Workbook

Sheet FTE 정리
B1: 평균 FTE (6월 ~ 8월) | F1: 현재 인원수 | J1: FTE/인원수
A2: 팀 | B2: 전체 | C2: 책임 | D2: 선임 | E2: 사원 | F2: 전체 | G2: 책임 | H2: 선임 | I2: 사원 | J2: 전체 | K2: 책임 | L2: 선임 | M2: 사원
A3: SL생산기술팀 | B3: =AVERAGE('FTE 계산'!W3,'FTE 계산'!AI3,'FTE 계산'!AU3) -> 10.290324 | C3: =AVERAGE('FTE 계산'!X3,'FTE 계산'!AJ3,'FTE 계산'!AV3) -> 5.9911502 | D3: =AVERAGE('FTE 계산'!Y3,'FTE 계산'!AK3,'FTE 계산'!AW3) -> 2.0141762 | E3: =AVERAGE('FTE 계산'!Z3,'FTE 계산'!AL3,'FTE 계산'!AX3) -> 0.74734375 | F3: =_xlfn.XLOOKUP($A3,Sheet3!$A:$A,Sheet3!K:K) -> 11 | G3: =_xlfn.XLOOKUP($A3,Sheet3!$A:$A,Sheet3!L:L) -> 5 | H3: =_xlfn.XLOOKUP($A3,Sheet3!$A:$A,Sheet3!M:M) -> 2 | I3: =_xlfn.XLOOKUP($A3,Sheet3!$A:$A,Sheet3!N:N) -> 4 | J3: =B3/F3 -> 0.93548396 | K3: =C3/G3 -> 1.19823 | L3: =D3/H3 -> 1.0070881 | M3: =E3/I3 -> 0.18683594
A4: SL운영팀 | B4: =AVERAGE('FTE 계산'!W4,'FTE 계산'!AI4,'FTE 계산'!AU4) -> 9.43798 | C4: =AVERAGE('FTE 계산'!X4,'FTE 계산'!AJ4,'FTE 계산'!AV4) -> 4.6447768 | D4: =AVERAGE('FTE 계산'!Y4,'FTE 계산'!AK4,'FTE 계산'!AW4) -> 2.3962681 | E4: =AVERAGE('FTE 계산'!Z4,'FTE 계산'!AL4,'FTE 계산'!AX4) -> 2.379189 | F4: =_xlfn.XLOOKUP($A4,Sheet3!$A:$A,Sheet3!K:K) -> 8 | G4: =_xlfn.XLOOKUP($A4,Sheet3!$A:$A,Sheet3!L:L) -> 4 | H4: =_xlfn.XLOOKUP($A4,Sheet3!$A:$A,Sheet3!M:M) -> 2 | I4: =_xlfn.XLOOKUP($A4,Sheet3!$A:$A,Sheet3!N:N) -> 2 | J4: =B4/F4 -> 1.1797475 | K4: =C4/G4 -> 1.1611942 | L4: =D4/H4 -> 1.198134 | M4: =E4/I4 -> 1.1895945
A5: HR팀 | B5: =AVERAGE('FTE 계산'!W5,'FTE 계산'!AI5,'FTE 계산'!AU5) -> 6.0174103 | C5: =AVERAGE('FTE 계산'!X5,'FTE 계산'!AJ5,'FTE 계산'!AV5) -> 2.3470047 | D5: =AVERAGE('FTE 계산'!Y5,'FTE 계산'!AK5,'FTE 계산'!AW5) -> 1.1297743 | E5: =AVERAGE('FTE 계산'!Z5,'FTE 계산'!AL5,'FTE 계산'!AX5) -> 2.5465474 | F5: =_xlfn.XLOOKUP($A5,Sheet3!$A:$A,Sheet3!K:K) -> 5 | G5: =_xlfn.XLOOKUP($A5,Sheet3!$A:$A,Sheet3!L:L) -> 2 | H5: =_xlfn.XLOOKUP($A5,Sheet3!$A:$A,Sheet3!M:M) -> 1 | I5: =_xlfn.XLOOKUP($A5,Sheet3!$A:$A,Sheet3!N:N) -> 2 | J5: =B5/F5 -> 1.2034821 | K5: =C5/G5 -> 1.1735023 | L5: =D5/H5 -> 1.1297743 | M5: =E5/I5 -> 1.2732737
A6: 구매원가팀 | B6: =AVERAGE('FTE 계산'!W6,'FTE 계산'!AI6,'FTE 계산'!AU6) -> 7.6317259 | C6: =AVERAGE('FTE 계산'!X6,'FTE 계산'!AJ6,'FTE 계산'!AV6) -> 2.5589117 | D6: =AVERAGE('FTE 계산'!Y6,'FTE 계산'!AK6,'FTE 계산'!AW6) -> 2.5706889 | E6: =AVERAGE('FTE 계산'!Z6,'FTE 계산'!AL6,'FTE 계산'!AX6) -> 2.5036064 | F6: =_xlfn.XLOOKUP($A6,Sheet3!$A:$A,Sheet3!K:K) -> 6 | G6: =_xlfn.XLOOKUP($A6,Sheet3!$A:$A,Sheet3!L:L) -> 2 | H6: =_xlfn.XLOOKUP($A6,Sheet3!$A:$A,Sheet3!M:M) -> 2 | I6: =_xlfn.XLOOKUP($A6,Sheet3!$A:$A,Sheet3!N:N) -> 2 | J6: =B6/F6 -> 1.2719543 | K6: =C6/G6 -> 1.2794559 | L6: =D6/H6 -> 1.2853445 | M6: =E6/I6 -> 1.2518032
A7: SCM팀 | B7: =AVERAGE('FTE 계산'!W7,'FTE 계산'!AI7,'FTE 계산'!AU7) -> 16.216856 | C7: =AVERAGE('FTE 계산'!X7,'FTE 계산'!AJ7,'FTE 계산'!AV7) -> 4.8307175 | D7: =AVERAGE('FTE 계산'!Y7,'FTE 계산'!AK7,'FTE 계산'!AW7) -> 4.7317786 | E7: =AVERAGE('FTE 계산'!Z7,'FTE 계산'!AL7,'FTE 계산'!AX7) -> 4.7387856 | F7: =_xlfn.XLOOKUP($A7,Sheet3!$A:$A,Sheet3!K:K) -> 12 | G7: =_xlfn.XLOOKUP($A7,Sheet3!$A:$A,Sheet3!L:L) -> 4 | H7: =_xlfn.XLOOKUP($A7,Sheet3!$A:$A,Sheet3!M:M) -> 4 | I7: =_xlfn.XLOOKUP($A7,Sheet3!$A:$A,Sheet3!N:N) -> 4 | J7: =B7/F7 -> 1.3514047 | K7: =C7/G7 -> 1.2076794 | L7: =D7/H7 -> 1.1829447 | M7: =E7/I7 -> 1.1846964
A8: SL품질보증팀 | B8: =AVERAGE('FTE 계산'!W8,'FTE 계산'!AI8,'FTE 계산'!AU8) -> 14.796171 | C8: =AVERAGE('FTE 계산'!X8,'FTE 계산'!AJ8,'FTE 계산'!AV8) -> 3.3280902 | D8: =AVERAGE('FTE 계산'!Y8,'FTE 계산'!AK8,'FTE 계산'!AW8) -> 7.6721886 | E8: =AVERAGE('FTE 계산'!Z8,'FTE 계산'!AL8,'FTE 계산'!AX8) -> 3.2577988 | F8: =_xlfn.XLOOKUP($A8,Sheet3!$A:$A,Sheet3!K:K) -> 14 | G8: =_xlfn.XLOOKUP($A8,Sheet3!$A:$A,Sheet3!L:L) -> 3 | H8: =_xlfn.XLOOKUP($A8,Sheet3!$A:$A,Sheet3!M:M) -> 8 | I8: =_xlfn.XLOOKUP($A8,Sheet3!$A:$A,Sheet3!N:N) -> 2 | J8: =B8/F8 -> 1.0568693 | K8: =C8/G8 -> 1.1093634 | L8: =D8/H8 -> 0.95902357 | M8: =E8/I8 -> 1.6288994
A9: 열관리설계팀 | B9: =AVERAGE('FTE 계산'!W9,'FTE 계산'!AI9,'FTE 계산'!AU9) -> 19.944953 | C9: =AVERAGE('FTE 계산'!X9,'FTE 계산'!AJ9,'FTE 계산'!AV9) -> 11.274102 | D9: =AVERAGE('FTE 계산'!Y9,'FTE 계산'!AK9,'FTE 계산'!AW9) -> 4.6361366 | E9: =AVERAGE('FTE 계산'!Z9,'FTE 계산'!AL9,'FTE 계산'!AX9) -> 3.3208987 | F9: =_xlfn.XLOOKUP($A9,Sheet3!$A:$A,Sheet3!K:K) -> 13 | G9: =_xlfn.XLOOKUP($A9,Sheet3!$A:$A,Sheet3!L:L) -> 4 | H9: =_xlfn.XLOOKUP($A9,Sheet3!$A:$A,Sheet3!M:M) -> 5 | I9: =_xlfn.XLOOKUP($A9,Sheet3!$A:$A,Sheet3!N:N) -> 3 | J9: =B9/F9 -> 1.5342272 | K9: =C9/G9 -> 2.8185256 | L9: =D9/H9 -> 0.92722732 | M9: =E9/I9 -> 1.1069662
A10: FL생산기술팀 | B10: =AVERAGE('FTE 계산'!W10,'FTE 계산'!AI10,'FTE 계산'!AU10) -> 9.8287118 | C10: =AVERAGE('FTE 계산'!X10,'FTE 계산'!AJ10,'FTE 계산'!AV10) -> 2.4849873 | D10: =AVERAGE('FTE 계산'!Y10,'FTE 계산'!AK10,'FTE 계산'!AW10) -> 3.675594 | E10: =AVERAGE('FTE 계산'!Z10,'FTE 계산'!AL10,'FTE 계산'!AX10) -> 3.6642344 | F10: =_xlfn.XLOOKUP($A10,Sheet3!$A:$A,Sheet3!K:K) -> 10 | G10: =_xlfn.XLOOKUP($A10,Sheet3!$A:$A,Sheet3!L:L) -> 2 | H10: =_xlfn.XLOOKUP($A10,Sheet3!$A:$A,Sheet3!M:M) -> 5 | I10: =_xlfn.XLOOKUP($A10,Sheet3!$A:$A,Sheet3!N:N) -> 3 | J10: =B10/F10 -> 0.98287118 | K10: =C10/G10 -> 1.2424937 | L10: =D10/H10 -> 0.7351188 | M10: =E10/I10 -> 1.2214115
A11: FL개발팀 | B11: =AVERAGE('FTE 계산'!W11,'FTE 계산'!AI11,'FTE 계산'!AU11) -> 18.04339 | C11: =AVERAGE('FTE 계산'!X11,'FTE 계산'!AJ11,'FTE 계산'!AV11) -> 3.9853009 | D11: =AVERAGE('FTE 계산'!Y11,'FTE 계산'!AK11,'FTE 계산'!AW11) -> 8.289793 | E11: =AVERAGE('FTE 계산'!Z11,'FTE 계산'!AL11,'FTE 계산'!AX11) -> 4.3588348 | F11: =_xlfn.XLOOKUP($A11,Sheet3!$A:$A,Sheet3!K:K) -> 14 | G11: =_xlfn.XLOOKUP($A11,Sheet3!$A:$A,Sheet3!L:L) -> 3 | H11: =_xlfn.XLOOKUP($A11,Sheet3!$A:$A,Sheet3!M:M) -> 7 | I11: =_xlfn.XLOOKUP($A11,Sheet3!$A:$A,Sheet3!N:N) -> 3 | J11: =B11/F11 -> 1.2888136 | K11: =C11/G11 -> 1.3284336 | L11: =D11/H11 -> 1.1842561 | M11: =E11/I11 -> 1.4529449
A12: SL구매팀 | B12: =AVERAGE('FTE 계산'!W12,'FTE 계산'!AI12,'FTE 계산'!AU12) -> 10.780294 | C12: =AVERAGE('FTE 계산'!X12,'FTE 계산'!AJ12,'FTE 계산'!AV12) -> 5.8705952 | D12: =AVERAGE('FTE 계산'!Y12,'FTE 계산'!AK12,'FTE 계산'!AW12) -> 3.6930038 | E12: =AVERAGE('FTE 계산'!Z12,'FTE 계산'!AL12,'FTE 계산'!AX12) -> 1.2112723 | F12: =_xlfn.XLOOKUP($A12,Sheet3!$A:$A,Sheet3!K:K) -> 9 | G12: =_xlfn.XLOOKUP($A12,Sheet3!$A:$A,Sheet3!L:L) -> 5 | H12: =_xlfn.XLOOKUP($A12,Sheet3!$A:$A,Sheet3!M:M) -> 3 | I12: =_xlfn.XLOOKUP($A12,Sheet3!$A:$A,Sheet3!N:N) -> 1 | J12: =B12/F12 -> 1.1978105 | K12: =C12/G12 -> 1.174119 | L12: =D12/H12 -> 1.2310013 | M12: =E12/I12 -> 1.2112723
A13: 품질경영팀 | B13: =AVERAGE('FTE 계산'!W13,'FTE 계산'!AI13,'FTE 계산'!AU13) -> 14.789225 | C13: =AVERAGE('FTE 계산'!X13,'FTE 계산'!AJ13,'FTE 계산'!AV13) -> 4.5496892 | D13: =AVERAGE('FTE 계산'!Y13,'FTE 계산'!AK13,'FTE 계산'!AW13) -> 8.1785126 | E13: =AVERAGE('FTE 계산'!Z13,'FTE 계산'!AL13,'FTE 계산'!AX13) -> 1.1352056 | F13: =_xlfn.XLOOKUP($A13,Sheet3!$A:$A,Sheet3!K:K) -> 13 | G13: =_xlfn.XLOOKUP($A13,Sheet3!$A:$A,Sheet3!L:L) -> 4 | H13: =_xlfn.XLOOKUP($A13,Sheet3!$A:$A,Sheet3!M:M) -> 7 | I13: =_xlfn.XLOOKUP($A13,Sheet3!$A:$A,Sheet3!N:N) -> 2 | J13: =B13/F13 -> 1.1376327 | K13: =C13/G13 -> 1.1374223 | L13: =D13/H13 -> 1.1683589 | M13: =E13/I13 -> 0.56760281
A14: B/H사업팀 | B14: =AVERAGE('FTE 계산'!W14,'FTE 계산'!AI14,'FTE 계산'!AU14) -> 8.3166612 | C14: =AVERAGE('FTE 계산'!X14,'FTE 계산'!AJ14,'FTE 계산'!AV14) -> 2.4152769 | D14: =AVERAGE('FTE 계산'!Y14,'FTE 계산'!AK14,'FTE 계산'!AW14) -> 4.7317487 | E14: =AVERAGE('FTE 계산'!Z14,'FTE 계산'!AL14,'FTE 계산'!AX14) -> 1.1741365 | F14: =_xlfn.XLOOKUP($A14,Sheet3!$A:$A,Sheet3!K:K) -> 6 | G14: =_xlfn.XLOOKUP($A14,Sheet3!$A:$A,Sheet3!L:L) -> 2 | H14: =_xlfn.XLOOKUP($A14,Sheet3!$A:$A,Sheet3!M:M) -> 4 | I14: =_xlfn.XLOOKUP($A14,Sheet3!$A:$A,Sheet3!N:N) -> 0 | J14: =B14/F14 -> 1.3861102 | K14: =C14/G14 -> 1.2076385 | L14: =D14/H14 -> 1.1829372 | M14: =E14/I14 -> #DIV/0!
... A77: 기술전략화팀 | B77: =AVERAGE('FTE 계산'!W77,'FTE 계산'!AI77,'FTE 계산'!AU77) -> 4.6809889 | C77: =AVERAGE('FTE 계산'!X77,'FTE 계산'!AJ77,'FTE 계산'!AV77) -> 2.3659813 | D77: =AVERAGE('FTE 계산'!Y77,'FTE 계산'!AK77,'FTE 계산'!AW77) -> #DIV/0! | E77: =AVERAGE('FTE 계산'!Z77,'FTE 계산'!AL77,'FTE 계산'!AX77) -> 2.316951 | F77: =_xlfn.XLOOKUP($A77,Sheet3!$A:$A,Sheet3!K:K) -> 4 | G77: =_xlfn.XLOOKUP($A77,Sheet3!$A:$A,Sheet3!L:L) -> 2 | H77: =_xlfn.XLOOKUP($A77,Sheet3!$A:$A,Sheet3!M:M) -> 0 | I77: =_xlfn.XLOOKUP($A77,Sheet3!$A:$A,Sheet3!N:N) -> 2 | J77: =B77/F77 -> 1.1702472 | K77: =C77/G77 -> 1.1829906 | L77: =D77/H77 -> #DIV/0! | M77: =E77/I77 -> 1.1584755

Sheet monthly_work_hours
A1: 사번 | B1: 성명 | C1: 소속팀 | D1: 직위 | E1: 년 | F1: 월 | G1: 근무일수 | H1: 총근무시간_분 | I1: 초과근무시간_분 | J1: 주말근무일수 | K1: 총근무시간 | L1: 초과근무시간 | M1: 일평균근무시간 | N1: 예상정규근무시간 | O1: 근무시간차이
A2: 1199158 | B2: 윤상규 | C2: SL생산기술팀 | D2: 기능주임 | E2: 2025 | F2: 6 | G2: 30 | H2: 8053 | I2: 0 | J2: 9 | K2: 134.2 | L2: 0 | M2: 4.5 | N2: 168 | O2: -33.8
A3: 1199158 | B3: 윤상규 | C3: SL생산기술팀 | D3: 기능주임 | E3: 2025 | F3: 7 | G3: 31 | H3: 7095 | I3: 0 | J3: 8 | K3: 118.2 | L3: 0 | M3: 3.8 | N3: 184 | O3: -65.8
A4: 1199158 | B4: 윤상규 | C4: SL생산기술팀 | D4: 기능주임 | E4: 2025 | F4: 8 | G4: 22 | H4: 4949 | I4: 0 | J4: 5 | K4: 82.5 | L4: 0 | M4: 3.8 | N4: 136 | O4: -53.5
A5: 1202155 | B5: 추상민 | C5: SL운영팀 | D5: 책임 | E5: 2025 | F5: 6 | G5: 1 | H5: 207 | I5: 0 | J5: 0 | K5: 3.4 | L5: 0 | M5: 3.4 | N5: 8 | O5: -4.6
A6: 1202183 | B6: 안준철 | C6: HR팀 | D6: 책임 | E6: 2025 | F6: 6 | G6: 20 | H6: 10677 | I6: 0 | J6: 1 | K6: 178 | L6: 0 | M6: 8.9 | N6: 152 | O6: 26
A7: 1202183 | B7: 안준철 | C7: HR팀 | D7: 책임 | E7: 2025 | F7: 7 | G7: 20 | H7: 10409 | I7: 0 | J7: 0 | K7: 173.5 | L7: 0 | M7: 8.7 | N7: 160 | O7: 13.5
A8: 1202183 | B8: 안준철 | C8: HR팀 | D8: 책임 | E8: 2025 | F8: 8 | G8: 17 | H8: 8607 | I8: 0 | J8: 1 | K8: 143.4 | L8: 0 | M8: 8.4 | N8: 128 | O8: 15.400000000000006
A9: 1203036 | B9: 이범철 | C9: SL생산기술팀 | D9: 책임 | E9: 2025 | F9: 6 | G9: 18 | H9: 9663 | I9: 0 | J9: 0 | K9: 161 | L9: 0 | M9: 8.9 | N9: 144 | O9: 17
A10: 1203036 | B10: 이범철 | C10: SL생산기술팀 | D10: 책임 | E10: 2025 | F10: 7 | G10: 19 | H10: 10298 | I10: 0 | J10: 0 | K10: 171.6 | L10: 0 | M10: 9 | N10: 152 | O10: 19.599999999999994
A11: 1203036 | B11: 이범철 | C11: SL생산기술팀 | D11: 책임 | E11: 2025 | F11: 8 | G11: 14 | H11: 7532 | I11: 0 | J11: 0 | K11: 125.5 | L11: 0 | M11: 9 | N11: 112 | O11: 13.5
A12: 1203052 | B12: 제용화 | C12: 구매원가팀 | D12: 책임 | E12: 2025 | F12: 6 | G12: 17 | H12: 10472 | I12: 1160 | J12: 0 | K12: 174.5 | L12: 19.3 | M12: 10.3 | N12: 136 | O12: 38.5
A13: 1203052 | B13: 제용화 | C13: 구매원가팀 | D13: 책임 | E13: 2025 | F13: 7 | G13: 19 | H13: 11600 | I13: 1221 | J13: 0 | K13: 193.3 | L13: 20.4 | M13: 10.2 | N13: 152 | O13: 41.30000000000001
A14: 1203052 | B14: 제용화 | C14: 구매원가팀 | D14: 책임 | E14: 2025 | F14: 8 | G14: 16 | H14: 10220 | I14: 1240 | J14: 0 | K14: 170.3 | L14: 20.7 | M14: 10.6 | N14: 128 | O14: 42.30000000000001
A15: 1203053 | B15: 문은진 | C15: SCM팀 | D15: 책임 | E15: 2025 | F15: 6 | G15: 17 | H15: 10225 | I15: 753 | J15: 0 | K15: 170.4 | L15: 12.6 | M15: 10 | N15: 136 | O15: 34.400000000000006
A16: 1203053 | B16: 문은진 | C16: SCM팀 | D16: 책임 | E16: 2025 | F16: 7 | G16: 18 | H16: 9923 | I16: 191 | J16: 0 | K16: 165.4 | L16: 3.2 | M16: 9.2 | N16: 144 | O16: 21.400000000000006
A17: 1203053 | B17: 문은진 | C17: SCM팀 | D17: 책임 | E17: 2025 | F17: 8 | G17: 16 | H17: 8418 | I17: 124 | J17: 0 | K17: 140.3 | L17: 2.1 | M17: 8.8 | N17: 128 | O17: 12.300000000000011
A18: 1204003 | B18: 정용규 | C18: SL생산기술팀 | D18: 책임 | E18: 2025 | F18: 6 | G18: 17 | H18: 8872 | I18: 0 | J18: 0 | K18: 147.9 | L18: 0 | M18: 8.7 | N18: 136 | O18: 11.900000000000006
A19: 1204003 | B19: 정용규 | C19: SL생산기술팀 | D19: 책임 | E19: 2025 | F19: 7 | G19: 19 | H19: 11481 | I19: 0 | J19: 0 | K19: 191.4 | L19: 0 | M19: 10.1 | N19: 152 | O19: 39.400000000000006
A20: 1204003 | B20: 정용규 | C20: SL생산기술팀 | D20: 책임 | E20: 2025 | F20: 8 | G20: 16 | H20: 8970 | I20: 0 | J20: 0 | K20: 149.5 | L20: 0 | M20: 9.3 | N20: 128 | O20: 21.5
A21: 1204063 | B21: 김주호 | C21: SL품질보증팀 | D21: 책임 | E21: 2025 | F21: 6 | G21: 2 | H21: 417 | I21: 0 | J21: 0 | K21: 7 | L21: 0 | M21: 3.5 | N21: 16 | O21: -9
A22: 1204063 | B22: 김주호 | C22: SL품질보증팀 | D22: 책임 | E22: 2025 | F22: 7 | G22: 4 | H22: 27 | I22: 0 | J22: 0 | K22: 0.4 | L22: 0 | M22: 0.1 | N22: 32 | O22: -31.6
A23: 1204063 | B23: 김주호 | C23: SL품질보증팀 | D23: 책임 | E23: 2025 | F23: 8 | G23: 4 | H23: 1365 | I23: 0 | J23: 0 | K23: 22.8 | L23: 0 | M23: 5.7 | N23: 32 | O23: -9.2
A24: 1204106 | B24: 김영준 | C24: 열관리설계팀 | D24: 책임 | E24: 2025 | F24: 6 | G24: 19 | H24: 13135 | I24: 0 | J24: 5 | K24: 218.9 | L24: 0 | M24: 11.5 | N24: 112 | O24: 106.9
A25: 1204106 | B25: 김영준 | C25: 열관리설계팀 | D25: 책임 | E25: 2025 | F25: 7 | G25: 19 | H25: 9604 | I25: 0 | J25: 3 | K25: 160.1 | L25: 0 | M25: 8.4 | N25: 128 | O25: 32.099999999999994
A26: 1204106 | B26: 김영준 | C26: 열관리설계팀 | D26: 책임 | E26: 2025 | F26: 8 | G26: 16 | H26: 7980 | I26: 0 | J26: 1 | K26: 133 | L26: 0 | M26: 8.3 | N26: 120 | O26: 13
A27: 1204115 | B27: 이용재 | C27: FL생산기술팀 | D27: 책임 | E27: 2025 | F27: 6 | G27: 18 | H27: 10328 | I27: 0 | J27: 0 | K27: 172.1 | L27: 0 | M27: 9.6 | N27: 144 | O27: 28.099999999999994
A28: 1204115 | B28: 이용재 | C28: FL생산기술팀 | D28: 책임 | E28: 2025 | F28: 7 | G28: 18 | H28: 10438 | I28: 0 | J28: 0 | K28: 174 | L28: 0 | M28: 9.7 | N28: 144 | O28: 30
A29: 1204115 | B29: 이용재 | C29: FL생산기술팀 | D29: 책임 | E29: 2025 | F29: 8 | G29: 16 | H29: 8796 | I29: 0 | J29: 0 | K29: 146.6 | L29: 0 | M29: 9.2 | N29: 128 | O29: 18.599999999999994
A30: 1205081 | B30: 이호진 | C30: SCM팀 | D30: 기능주임 | E30: 2025 | F30: 7 | G30: 1 | H30: 0 | I30: 0 | J30: 0 | K30: 0 | L30: 0 | M30: 0 | N30: 8 | O30: -8
A31: 1205094 | B31: 강동현 | C31: FL개발팀 | D31: 책임 | E31: 2025 | F31: 6 | G31: 24 | H31: 17014 | I31: 507 | J31: 5 | K31: 283.6 | L31: 8.4 | M31: 11.8 | N31: 152 | O31: 131.60000000000002
A32: 1205094 | B32: 강동현 | C32: FL개발팀 | D32: 책임 | E32: 2025 | F32: 7 | G32: 16 | H32: 9952 | I32: 809 | J32: 0 | K32: 165.9 | L32: 13.5 | M32: 10.4 | N32: 128 | O32: 37.900000000000006
A33: 1205094 | B33: 강동현 | C33: FL개발팀 | D33: 책임 | E33: 2025 | F33: 8 | G33: 16 | H33: 9109 | I33: 300 | J33: 0 | K33: 151.8 | L33: 5 | M33: 9.5 | N33: 128 | O33: 23.80000000000001
A34: 1205105 | B34: 엄중호 | C34: SL품질보증팀 | D34: 기능주임 | E34: 2025 | F34: 6 | G34: 20 | H34: 6216 | I34: 0 | J34: 0 | K34: 103.6 | L34: 0 | M34: 5.2 | N34: 160 | O34: -56.4
A35: 1205105 | B35: 엄중호 | C35: SL품질보증팀 | D35: 기능주임 | E35: 2025 | F35: 7 | G35: 20 | H35: 5741 | I35: 0 | J35: 1 | K35: 95.7 | L35: 0 | M35: 4.8 | N35: 152 | O35: -56.3
A36: 1205105 | B36: 엄중호 | C36: SL품질보증팀 | D36: 기능주임 | E36: 2025 | F36: 8 | G36: 19 | H36: 5870 | I36: 0 | J36: 2 | K36: 97.8 | L36: 0 | M36: 5.1 | N36: 136 | O36: -38.2
A37: 1205115 | B37: 김욱진 | C37: SL생산기술팀 | D37: 책임 | E37: 2025 | F37: 6 | G37: 17 | H37: 9894 | I37: 0 | J37: 0 | K37: 164.9 | L37: 0 | M37: 9.7 | N37: 136 | O37: 28.900000000000006
A38: 1205115 | B38: 김욱진 | C38: SL생산기술팀 | D38: 책임 | E38: 2025 | F38: 7 | G38: 17 | H38: 9977 | I38: 0 | J38: 0 | K38: 166.3 | L38: 0 | M38: 9.8 | N38: 136 | O38: 30.30000000000001
A39: 1205115 | B39: 김욱진 | C39: SL생산기술팀 | D39: 책임 | E39: 2025 | F39: 8 | G39: 13 | H39: 7204 | I39: 0 | J39: 0 | K39: 120.1 | L39: 0 | M39: 9.2 | N39: 104 | O39: 16.099999999999994
A40: 1206003 | B40: 김동건 | C40: FL개발팀 | D40: 책임 | E40: 2025 | F40: 6 | G40: 21 | H40: 12328 | I40: 1716 | J40: 3 | K40: 205.5 | L40: 28.6 | M40: 9.8 | N40: 144 | O40: 61.5
...

Sheet FTE 계산
E1: 근무시간 | H1: 정규근무일수 | L1: 기준근무시간 | O1: 6월 총근무시간 | S1: 6월 평균근무일수 | W1: 6월 FTE | AA1: 7월 총근무시간 | AE1: 7월 평균근무일수 | AI1: 7월 FTE | AM1: 8월 총근무시간 | AQ1: 8월 평균근무일수 | AU1: 8월 FTE
A2: 사번 | B2: 이름 | C2: 팀 | D2: 직급 | E2: 6 | F2: 7 | G2: 8 | H2: 6 | I2: 7 | J2: 8 | L2: 8 | N2: 팀 | O2: 전체 | P2: 책임 | Q2: 선임 | R2: 사원 | S2: 전체 | T2: 책임 | U2: 선임 | V2: 사원 | W2: 전체 | X2: 책임 | Y2: 선임 | Z2: 사원 | AA2: 전체 | AB2: 책임 | AC2: 선임 | AD2: 사원 | AE2: 전체 | AF2: 책임 | AG2: 선임 | AH2: 사원 | AI2: 전체 | AJ2: 책임 | AK2: 선임 | AL2: 사원 | AM2: 전체 | AN2: 책임 | AO2: 선임 | AP2: 사원 | AQ2: 전체 | AR2: 책임 | AS2: 선임 | AT2: 사원 | AU2: 전체 | AV2: 책임 | AW2: 선임 | AX2: 사원
A3: {=_xlfn.UNIQUE(monthly_work_hours!A2:A1447)} -> 1199158 | B3: =_xlfn.XLOOKUP(A3,monthly_work_hours!A:A,monthly_work_hours!B:B) -> 윤상규 | C3: =_xlfn.XLOOKUP(A3,monthly_work_hours!A:A,monthly_work_hours!C:C) -> SL생산기술팀 | D3: =_xlfn.XLOOKUP(A3,monthly_work_hours!A:A,monthly_work_hours!D:D) -> 기능주임 | E3: =SUMIFS(monthly_work_hours!$K:$K,monthly_work_hours!$A:$A,'FTE 계산'!$A3,monthly_work_hours!$F:$F,'FTE 계산'!E$2) -> 134.2 | F3: =SUMIFS(monthly_work_hours!$K:$K,monthly_work_hours!$A:$A,'FTE 계산'!$A3,monthly_work_hours!$F:$F,'FTE 계산'!F$2) -> 118.2 | G3: =SUMIFS(monthly_work_hours!$K:$K,monthly_work_hours!$A:$A,'FTE 계산'!$A3,monthly_work_hours!$F:$F,'FTE 계산'!G$2) -> 82.5 | H3: =(SUMIFS(monthly_work_hours!$G:$G,monthly_work_hours!$A:$A,'FTE 계산'!$A3,monthly_work_hours!$F:$F,'FTE 계산'!H$2)) - (SUMIFS(monthly_work_hours!$J:$J,monthly_work_hours!$A:$A,'FTE 계산'!$A3,monthly_work_hours!$F:$F,'FTE 계산'!H$2)) -> 21 | I3: =(SUMIFS(monthly_work_hours!$G:$G,monthly_work_hours!$A:$A,'FTE 계산'!$A3,monthly_work_hours!$F:$F,'FTE 계산'!I$2)) - (SUMIFS(monthly_work_hours!$J:$J,monthly_work_hours!$A:$A,'FTE 계산'!$A3,monthly_work_hours!$F:$F,'FTE 계산'!I$2)) -> 23 | J3: =(SUMIFS(monthly_work_hours!$G:$G,monthly_work_hours!$A:$A,'FTE 계산'!$A3,monthly_work_hours!$F:$F,'FTE 계산'!J$2)) - (SUMIFS(monthly_work_hours!$J:$J,monthly_work_hours!$A:$A,'FTE 계산'!$A3,monthly_work_hours!$F:$F,'FTE 계산'!J$2)) -> 17 | N3: {=_xlfn.UNIQUE(C3:C503)} -> SL생산기술팀 | O3: =SUMIFS($E$3:$E$503,$C$3:$C$503,$N3) -> 1446.2 | P3: =SUMIFS($E$3:$E$503,$C$3:$C$503,$N3,$D$3:$D$503,P$2) -> 830.9 | Q3: =SUMIFS($E$3:$E$503,$C$3:$C$503,$N3,$D$3:$D$503,Q$2) -> 256 | R3: =SUMIFS($E$3:$E$503,$C$3:$C$503,$N3,$D$3:$D$503,R$2) -> 54.2 | S3: =AVERAGEIFS($H$3:$H$503,$C$3:$C$503,$N3) -> 16.6 | T3: =AVERAGEIFS($H$3:$H$503,$C$3:$C$503,$N3,$D$3:$D$503,P$2) -> 16.8 | U3: =AVERAGEIFS($H$3:$H$503,$C$3:$C$503,$N3,$D$3:$D$503,Q$2) -> 16 | V3: =AVERAGEIFS($H$3:$H$503,$C$3:$C$503,$N3,$D$3:$D$503,R$2) -> 10 | W3: =IFERROR(O3/(S3*$L$2),"-") -> 10.89006 | X3: =IFERROR(P3/(T3*$L$2),"-") -> 6.1822917 | Y3: =IFERROR(Q3/(U3*$L$2),"-") -> 2 | Z3: =IFERROR(R3/(V3*$L$2),"-") -> 0.6775 | AA3: =SUMIFS($F$3:$F$503,$C$3:$C$503,$N3) -> 1440.8 | AB3: =SUMIFS($F$3:$F$503,$C$3:$C$503,$N3,$D$3:$D$503,P$2) -> 875.9 | AC3: =SUMIFS($F$3:$F$503,$C$3:$C$503,$N3,$D$3:$D$503,Q$2) -> 286.8 | AD3: =SUMIFS($F$3:$F$503,$C$3:$C$503,$N3,$D$3:$D$503,R$2) -> 52.3 | AE3: =AVERAGEIFS($I$3:$I$503,$C$3:$C$503,$N3) -> 17.7 | AF3: =AVERAGEIFS($I$3:$I$503,$C$3:$C$503,$N3,$D$3:$D$503,P$2) -> 18.2 | AG3: =AVERAGEIFS($I$3:$I$503,$C$3:$C$503,$N3,$D$3:$D$503,Q$2) -> 18 | AH3: =AVERAGEIFS($I$3:$I$503,$C$3:$C$503,$N3,$D$3:$D$503,R$2) -> 8 | AI3: =IFERROR(AA3/(AE3*$L$2),"-") -> 10.175141 | AJ3: =IFERROR(AB3/(AF3*$L$2),"-") -> 6.0157967 | AK3: =IFERROR(AC3/(AG3*$L$2),"-") -> 1.9916667 | AL3: =IFERROR(AD3/(AH3*$L$2),"-") -> 0.8171875 | AM3: =SUMIFS($G$3:$G$503,$C$3:$C$503,$N3) -> 1019.8 | AN3: =SUMIFS($G$3:$G$503,$C$3:$C$503,$N3,$D$3:$D$503,P$2) -> 637.6 | AO3: =SUMIFS($G$3:$G$503,$C$3:$C$503,$N3,$D$3:$D$503,Q$2) -> 237.9 | AP3: =SUMIFS($G$3:$G$503,$C$3:$C$503,$N3,$D$3:$D$503,R$2) -> 0 | AQ3: =AVERAGEIFS($J$3:$J$503,$C$3:$C$503,$N3) -> 13 | AR3: =AVERAGEIFS($J$3:$J$503,$C$3:$C$503,$N3,$D$3:$D$503,P$2) -> 13.8 | AS3: =AVERAGEIFS($J$3:$J$503,$C$3:$C$503,$N3,$D$3:$D$503,Q$2) -> 14.5 | AT3: =AVERAGEIFS($J$3:$J$503,$C$3:$C$503,$N3,$D$3:$D$503,R$2) -> 0 | AU3: =IFERROR(AM3/(AQ3*$L$2),"-") -> 9.8057692 | AV3: =IFERROR(AN3/(AR3*$L$2),"-") -> 5.7753623 | AW3: =IFERROR(AO3/(AS3*$L$2),"-") -> 2.0508621 | AX3: =IFERROR(AP3/(AT3*$L$2),"-") -> -
A4: 1202155 | B4: =_xlfn.XLOOKUP(A4,monthly_work_hours!A:A,monthly_work_hours!B:B) -> 추상민 | C4: =_xlfn.XLOOKUP(A4,monthly_work_hours!A:A,monthly_work_hours!C:C) -> SL운영팀 | D4: =_xlfn.XLOOKUP(A4,monthly_work_hours!A:A,monthly_work_hours!D:D) -> 책임 | E4: =SUMIFS(monthly_work_hours!$K:$K,monthly_work_hours!$A:$A,'FTE 계산'!$A4,monthly_work_hours!$F:$F,'FTE 계산'!E$2) -> 3.4 | F4: =SUMIFS(monthly_work_hours!$K:$K,monthly_work_hours!$A:$A,'FTE 계산'!$A4,monthly_work_hours!$F:$F,'FTE 계산'!F$2) -> 0 | G4: =SUMIFS(monthly_work_hours!$K:$K,monthly_work_hours!$A:$A,'FTE 계산'!$A4,monthly_work_hours!$F:$F,'FTE 계산'!G$2) -> 0 | H4: =(SUMIFS(monthly_work_hours!$G:$G,monthly_work_hours!$A:$A,'FTE 계산'!$A4,monthly_work_hours!$F:$F,'FTE 계산'!H$2)) - (SUMIFS(monthly_work_hours!$J:$J,monthly_work_hours!$A:$A,'FTE 계산'!$A4,monthly_work_hours!$F:$F,'FTE 계산'!H$2)) -> 1 | I4: =(SUMIFS(monthly_work_hours!$G:$G,monthly_work_hours!$A:$A,'FTE 계산'!$A4,monthly_work_hours!$F:$F,'FTE 계산'!I$2)) - (SUMIFS(monthly_work_hours!$J:$J,monthly_work_hours!$A:$A,'FTE 계산'!$A4,monthly_work_hours!$F:$F,'FTE 계산'!I$2)) -> 0 | J4: =(SUMIFS(monthly_work_hours!$G:$G,monthly_work_hours!$A:$A,'FTE 계산'!$A4,monthly_work_hours!$F:$F,'FTE 계산'!J$2)) - (SUMIFS(monthly_work_hours!$J:$J,monthly_work_hours!$A:$A,'FTE 계산'!$A4,monthly_work_hours!$F:$F,'FTE 계산'!J$2)) -> 0 | N4: SL운영팀 | O4: =SUMIFS($E$3:$E$503,$C$3:$C$503,$N4) -> 1174.5 | P4: =SUMIFS($E$3:$E$503,$C$3:$C$503,$N4,$D$3:$D$503,P$2) -> 516.5 | Q4: =SUMIFS($E$3:$E$503,$C$3:$C$503,$N4,$D$3:$D$503,Q$2) -> 379.6 | R4: =SUMIFS($E$3:$E$503,$C$3:$C$503,$N4,$D$3:$D$503,R$2) -> 278.4 | S4: =AVERAGEIFS($H$3:$H$503,$C$3:$C$503,$N4) -> 14.875 | T4: =AVERAGEIFS($H$3:$H$503,$C$3:$C$503,$N4,$D$3:$D$503,P$2) -> 13.5 | U4: =AVERAGEIFS($H$3:$H$503,$C$3:$C$503,$N4,$D$3:$D$503,Q$2) -> 18.5 | V4: =AVERAGEIFS($H$3:$H$503,$C$3:$C$503,$N4,$D$3:$D$503,R$2) -> 14 | W4: =IFERROR(O4/(S4*$L$2),"-") -> 9.8697479 | X4: =IFERROR(P4/(T4*$L$2),"-") -> 4.7824074 | Y4: =IFERROR(Q4/(U4*$L$2),"-") -> 2.5648649 | Z4: =IFERROR(R4/(V4*$L$2),"-") -> 2.4857143 | AA4: =SUMIFS($F$3:$F$503,$C$3:$C$503,$N4) -> 1162.3 | AB4: =SUMIFS($F$3:$F$503,$C$3:$C$503,$N4,$D$3:$D$503,P$2) -> 486.4 | AC4: =SUMIFS($F$3:$F$503,$C$3:$C$503,$N4,$D$3:$D$503,Q$2) -> 321.5 | AD4: =SUMIFS($F$3:$F$503,$C$3:$C$503,$N4,$D$3:$D$503,R$2) -> 354.4 | AE4: =AVERAGEIFS($I$3:$I$503,$C$3:$C$503,$N4) -> 15.25 | AF4: =AVERAGEIFS($I$3:$I$503,$C$3:$C$503,$N4,$D$3:$D$503,P$2) -> 13 | AG4: =AVERAGEIFS($I$3:$I$503,$C$3:$C$503,$N4,$D$3:$D$503,Q$2) -> 16.5 | AH4: =AVERAGEIFS($I$3:$I$503,$C$3:$C$503,$N4,$D$3:$D$503,R$2) -> 18.5 | AI4: =IFERROR(AA4/(AE4*$L$2),"-") -> 9.5270492 | AJ4: =IFERROR(AB4/(AF4*$L$2),"-") -> 4.6769231 | AK4: =IFERROR(AC4/(AG4*$L$2),"-") -> 2.4356061 | AL4: =IFERROR(AD4/(AH4*$L$2),"-") -> 2.3945946 | AM4: =SUMIFS($G$3:$G$503,$C$3:$C$503,$N4) -> 936.3 | AN4: =SUMIFS($G$3:$G$503,$C$3:$C$503,$N4,$D$3:$D$503,P$2) -> 393.8 | AO4: =SUMIFS($G$3:$G$503,$C$3:$C$503,$N4,$D$3:$D$503,Q$2) -> 262.6 | AP4: =SUMIFS($G$3:$G$503,$C$3:$C$503,$N4,$D$3:$D$503,R$2) -> 279.9 | AQ4: =AVERAGEIFS($J$3:$J$503,$C$3:$C$503,$N4) -> 13.125 | AR4: =AVERAGEIFS($J$3:$J$503,$C$3:$C$503,$N4,$D$3:$D$503,P$2) -> 11 | AS4: =AVERAGEIFS($J$3:$J$503,$C$3:$C$503,$N4,$D$3:$D$503,Q$2) -> 15 | AT4: =AVERAGEIFS($J$3:$J$503,$C$3:$C$503,$N4,$D$3:$D$503,R$2) -> 15.5 | AU4: =IFERROR(AM4/(AQ4*$L$2),"-") -> 8.9171429 | AV4: =IFERROR(AN4/(AR4*$L$2),"-") -> 4.475 | AW4: =IFERROR(AO4/(AS4*$L$2),"-") -> 2.1883333 | AX4: =IFERROR(AP4/(AT4*$L$2),"-") -> 2.2572581
A5: 1202183 | B5: =_xlfn.XLOOKUP(A5,monthly_work_hours!A:A,monthly_work_hours!B:B) -> 안준철 | C5: =_xlfn.XLOOKUP(A5,monthly_work_hours!A:A,monthly_work_hours!C:C) -> HR팀 | D5: =_xlfn.XLOOKUP(A5,monthly_work_hours!A:A,monthly_work_hours!D:D) -> 책임 | E5: =SUMIFS(monthly_work_hours!$K:$K,monthly_work_hours!$A:$A,'FTE 계산'!$A5,monthly_work_hours!$F:$F,'FTE 계산'!E$2) -> 178 | F5: =SUMIFS(monthly_work_hours!$K:$K,monthly_work_hours!$A:$A,'FTE 계산'!$A5,monthly_work_hours!$F:$F,'FTE 계산'!F$2) -> 173.5 | G5: =SUMIFS(monthly_work_hours!$K:$K,monthly_work_hours!$A:$A,'FTE 계산'!$A5,monthly_work_hours!$F:$F,'FTE 계산'!G$2) -> 143.4 | H5: =(SUMIFS(monthly_work_hours!$G:$G,monthly_work_hours!$A:$A,'FTE 계산'!$A5,monthly_work_hours!$F:$F,'FTE 계산'!H$2)) - (SUMIFS(monthly_work_hours!$J:$J,monthly_work_hours!$A:$A,'FTE 계산'!$A5,monthly_work_hours!$F:$F,'FTE 계산'!H$2)) -> 19 | I5: =(SUMIFS(monthly_work_hours!$G:$G,monthly_work_hours!$A:$A,'FTE 계산'!$A5,monthly_work_hours!$F:$F,'FTE 계산'!I$2)) - (SUMIFS(monthly_work_hours!$J:$J,monthly_work_hours!$A:$A,'FTE 계산'!$A5,monthly_work_hours!$F:$F,'FTE 계산'!I$2)) -> 20 | J5: =(SUMIFS(monthly_work_hours!$G:$G,monthly_work_hours!$A:$A,'FTE 계산'!$A5,monthly_work_hours!$F:$F,'FTE 계산'!J$2)) - (SUMIFS(monthly_work_hours!$J:$J,monthly_work_hours!$A:$A,'FTE 계산'!$A5,monthly_work_hours!$F:$F,'FTE 계산'!J$2)) -> 16 | N5: HR팀 | O5: =SUMIFS($E$3:$E$503,$C$3:$C$503,$N5) -> 879 | P5: =SUMIFS($E$3:$E$503,$C$3:$C$503,$N5,$D$3:$D$503,P$2) -> 367.1 | Q5: =SUMIFS($E$3:$E$503,$C$3:$C$503,$N5,$D$3:$D$503,Q$2) -> 169 | R5: =SUMIFS($E$3:$E$503,$C$3:$C$503,$N5,$D$3:$D$503,R$2) -> 342.9 | S5: =AVERAGEIFS($H$3:$H$503,$C$3:$C$503,$N5) -> 18.4 | T5: =AVERAGEIFS($H$3:$H$503,$C$3:$C$503,$N5,$D$3:$D$503,P$2) -> 18.5 | U5: =AVERAGEIFS($H$3:$H$503,$C$3:$C$503,$N5,$D$3:$D$503,Q$2) -> 18 | V5: =AVERAGEIFS($H$3:$H$503,$C$3:$C$503,$N5,$D$3:$D$503,R$2) -> 18.5 | W5: =IFERROR(O5/(S5*$L$2),"-") -> 5.9714674 | X5: =IFERROR(P5/(T5*$L$2),"-") -> 2.4804054 | Y5: =IFERROR(Q5/(U5*$L$2),"-") -> 1.1736111 | Z5: =IFERROR(R5/(V5*$L$2),"-") -> 2.3168919 | AA5: =SUMIFS($F$3:$F$503,$C$3:$C$503,$N5) -> 866 | AB5: =SUMIFS($F$3:$F$503,$C$3:$C$503,$N5,$D$3:$D$503,P$2) -> 350.5 | AC5: =SUMIFS($F$3:$F$503,$C$3:$C$503,$N5,$D$3:$D$503,Q$2) -> 170.9 | AD5: =SUMIFS($F$3:$F$503,$C$3:$C$503,$N5,$D$3:$D$503,R$2) -> 344.6 | AE5: =AVERAGEIFS($I$3:$I$503,$C$3:$C$503,$N5) -> 18.8 | AF5: =AVERAGEIFS($I$3:$I$503,$C$3:$C$503,$N5,$D$3:$D$503,P$2) -> 19 | AG5: =AVERAGEIFS($I$3:$I$503,$C$3:$C$503,$N5,$D$3:$D$503,Q$2) -> 18 | AH5: =AVERAGEIFS($I$3:$I$503,$C$3:$C$503,$N5,$D$3:$D$503,R$2) -> 19 | AI5: =IFERROR(AA5/(AE5*$L$2),"-") -> 5.7579787 | AJ5: =IFERROR(AB5/(AF5*$L$2),"-") -> 2.3059211 | AK5: =IFERROR(AC5/(AG5*$L$2),"-") -> 1.1868056 | AL5: =IFERROR(AD5/(AH5*$L$2),"-") -> 2.2671053 | AM5: =SUMIFS($G$3:$G$503,$C$3:$C$503,$N5) -> 799.2 | AN5: =SUMIFS($G$3:$G$503,$C$3:$C$503,$N5,$D$3:$D$503,P$2) -> 288.6 | AO5: =SUMIFS($G$3:$G$503,$C$3:$C$503,$N5,$D$3:$D$503,Q$2) -> 131.7 | AP5: =SUMIFS($G$3:$G$503,$C$3:$C$503,$N5,$D$3:$D$503,R$2) -> 378.9 | AQ5: =AVERAGEIFS($J$3:$J$503,$C$3:$C$503,$N5) -> 15.8 | AR5: =AVERAGEIFS($J$3:$J$503,$C$3:$C$503,$N5,$D$3:$D$503,P$2) -> 16 | AS5: =AVERAGEIFS($J$3:$J$503,$C$3:$C$503,$N5,$D$3:$D$503,Q$2) -> 16 | AT5: =AVERAGEIFS($J$3:$J$503,$C$3:$C$503,$N5,$D$3:$D$503,R$2) -> 15.5 | AU5: =IFERROR(AM5/(AQ5*$L$2),"-") -> 6.3227848 | AV5: =IFERROR(AN5/(AR5*$L$2),"-") -> 2.2546875 | AW5: =IFERROR(AO5/(AS5*$L$2),"-") -> 1.0289062 | AX5: =IFERROR(AP5/(AT5*$L$2),"-") -> 3.0556452
A6: 1203036 | B6: =_xlfn.XLOOKUP(A6,monthly_work_hours!A:A,monthly_work_hours!B:B) -> 이범철 | C6: =_xlfn.XLOOKUP(A6,monthly_work_hours!A:A,monthly_work_hours!C:C) -> SL생산기술팀 | D6: =_xlfn.XLOOKUP(A6,monthly_work_hours!A:A,monthly_work_hours!D:D) -> 책임 | E6: =SUMIFS(monthly_work_hours!$K:$K,monthly_work_hours!$A:$A,'FTE 계산'!$A6,monthly_work_hours!$F:$F,'FTE 계산'!E$2) -> 161 | F6: =SUMIFS(monthly_work_hours!$K:$K,monthly_work_hours!$A:$A,'FTE 계산'!$A6,monthly_work_hours!$F:$F,'FTE 계산'!F$2) -> 171.6 | G6: =SUMIFS(monthly_work_hours!$K:$K,monthly_work_hours!$A:$A,'FTE 계산'!$A6,monthly_work_hours!$F:$F,'FTE 계산'!G$2) -> 125.5 | H6: =(SUMIFS(monthly_work_hours!$G:$G,monthly_work_hours!$A:$A,'FTE 계산'!$A6,monthly_work_hours!$F:$F,'FTE 계산'!H$2)) - (SUMIFS(monthly_work_hours!$J:$J,monthly_work_hours!$A:$A,'FTE 계산'!$A6,monthly_work_hours!$F:$F,'FTE 계산'!H$2)) -> 18 | I6: =(SUMIFS(monthly_work_hours!$G:$G,monthly_work_hours!$A:$A,'FTE 계산'!$A6,monthly_work_hours!$F:$F,'FTE 계산'!I$2)) - (SUMIFS(monthly_work_hours!$J:$J,monthly_work_hours!$A:$A,'FTE 계산'!$A6,monthly_work_hours!$F:$F,'FTE 계산'!I$2)) -> 19 | J6: =(SUMIFS(monthly_work_hours!$G:$G,monthly_work_hours!$A:$A,'FTE 계산'!$A6,monthly_work_hours!$F:$F,'FTE 계산'!J$2)) - (SUMIFS(monthly_work_hours!$J:$J,monthly_work_hours!$A:$A,'FTE 계산'!$A6,monthly_work_hours!$F:$F,'FTE 계산'!J$2)) -> 14 | N6: 구매원가팀 | O6: =SUMIFS($E$3:$E$503,$C$3:$C$503,$N6) -> 1078.5 | P6: =SUMIFS($E$3:$E$503,$C$3:$C$503,$N6,$D$3:$D$503,P$2) -> 361.9 | Q6: =SUMIFS($E$3:$E$503,$C$3:$C$503,$N6,$D$3:$D$503,Q$2) -> 358.7 | R6: =SUMIFS($E$3:$E$503,$C$3:$C$503,$N6,$D$3:$D$503,R$2) -> 357.9 | S6: =AVERAGEIFS($H$3:$H$503,$C$3:$C$503,$N6) -> 17.5 | T6: =AVERAGEIFS($H$3:$H$503,$C$3:$C$503,$N6,$D$3:$D$503,P$2) -> 17.5 | U6: =AVERAGEIFS($H$3:$H$503,$C$3:$C$503,$N6,$D$3:$D$503,Q$2) -> 17.5 | V6: =AVERAGEIFS($H$3:$H$503,$C$3:$C$503,$N6,$D$3:$D$503,R$2) -> 17.5 | W6: =IFERROR(O6/(S6*$L$2),"-") -> 7.7035714 | X6: =IFERROR(P6/(T6*$L$2),"-") -> 2.585 | Y6: =IFERROR(Q6/(U6*$L$2),"-") -> 2.5621429 | Z6: =IFERROR(R6/(V6*$L$2),"-") -> 2.5564286 | AA6: =SUMIFS($F$3:$F$503,$C$3:$C$503,$N6) -> 1090.1 | AB6: =SUMIFS($F$3:$F$503,$C$3:$C$503,$N6,$D$3:$D$503,P$2) -> 381 | AC6: =SUMIFS($F$3:$F$503,$C$3:$C$503,$N6,$D$3:$D$503,Q$2) -> 352.3 | AD6: =SUMIFS($F$3:$F$503,$C$3:$C$503,$N6,$D$3:$D$503,R$2) -> 356.8 | AE6: =AVERAGEIFS($I$3:$I$503,$C$3:$C$503,$N6) -> 18 | AF6: =AVERAGEIFS($I$3:$I$503,$C$3:$C$503,$N6,$D$3:$D$503,P$2) -> 19 | AG6: =AVERAGEIFS($I$3:$I$503,$C$3:$C$503,$N6,$D$3:$D$503,Q$2) -> 17 | AH6: =AVERAGEIFS($I$3:$I$503,$C$3:$C$503,$N6,$D$3:$D$503,R$2) -> 18 | AI6: =IFERROR(AA6/(AE6*$L$2),"-") -> 7.5701389 | AJ6: =IFERROR(AB6/(AF6*$L$2),"-") -> 2.5065789 | AK6: =IFERROR(AC6/(AG6*$L$2),"-") -> 2.5904412 | AL6: =IFERROR(AD6/(AH6*$L$2),"-") -> 2.4777778 | AM6: =SUMIFS($G$3:$G$503,$C$3:$C$503,$N6) -> 934.9 | AN6: =SUMIFS($G$3:$G$503,$C$3:$C$503,$N6,$D$3:$D$503,P$2) -> 330.9 | AO6: =SUMIFS($G$3:$G$503,$C$3:$C$503,$N6,$D$3:$D$503,Q$2) -> 296.9 | AP6: =SUMIFS($G$3:$G$503,$C$3:$C$503,$N6,$D$3:$D$503,R$2) -> 307.1 | AQ6: =AVERAGEIFS($J$3:$J$503,$C$3:$C$503,$N6) -> 15.333333 | AR6: =AVERAGEIFS($J$3:$J$503,$C$3:$C$503,$N6,$D$3:$D$503,P$2) -> 16 | AS6: =AVERAGEIFS($J$3:$J$503,$C$3:$C$503,$N6,$D$3:$D$503,Q$2) -> 14.5 | AT6: =AVERAGEIFS($J$3:$J$503,$C$3:$C$503,$N6,$D$3:$D$503,R$2) -> 15.5 | AU6: =IFERROR(AM6/(AQ6*$L$2),"-") -> 7.6214674 | AV6: =IFERROR(AN6/(AR6*$L$2),"-") -> 2.5851562 | AW6: =IFERROR(AO6/(AS6*$L$2),"-") -> 2.5594828 | AX6: =IFERROR(AP6/(AT6*$L$2),"-") -> 2.4766129
A7: 1203052 | B7: =_xlfn.XLOOKUP(A7,monthly_work_hours!A:A,monthly_work_hours!B:B) -> 제용화 | C7: =_xlfn.XLOOKUP(A7,monthly_work_hours!A:A,monthly_work_hours!C:C) -> 구매원가팀 | D7: =_xlfn.XLOOKUP(A7,monthly_work_hours!A:A,monthly_work_hours!D:D) -> 책임 | E7: =SUMIFS(monthly_work_hours!$K:$K,monthly_work_hours!$A:$A,'FTE 계산'!$A7,monthly_work_hours!$F:$F,'FTE 계산'!E$2) -> 174.5 | F7: =SUMIFS(monthly_work_hours!$K:$K,monthly_work_hours!$A:$A,'FTE 계산'!$A7,monthly_work_hours!$F:$F,'FTE 계산'!F$2) -> 193.3 | G7: =SUMIFS(monthly_work_hours!$K:$K,monthly_work_hours!$A:$A,'FTE 계산'!$A7,monthly_work_hours!$F:$F,'FTE 계산'!G$2) -> 170.3 | H7: =(SUMIFS(monthly_work_hours!$G:$G,monthly_work_hours!$A:$A,'FTE 계산'!$A7,monthly_work_hours!$F:$F,'FTE 계산'!H$2)) - (SUMIFS(monthly_work_hours!$J:$J,monthly_work_hours!$A:$A,'FTE 계산'!$A7,monthly_work_hours!$F:$F,'FTE 계산'!H$2)) -> 17 | I7: =(SUMIFS(monthly_work_hours!$G:$G,monthly_work_hours!$A:$A,'FTE 계산'!$A7,monthly_work_hours!$F:$F,'FTE 계산'!I$2)) - (SUMIFS(monthly_work_hours!$J:$J,monthly_work_hours!$A:$A,'FTE 계산'!$A7,monthly_work_hours!$F:$F,'FTE 계산'!I$2)) -> 19 | J7: =(SUMIFS(monthly_work_hours!$G:$G,monthly_work_hours!$A:$A,'FTE 계산'!$A7,monthly_work_hours!$F:$F,'FTE 계산'!J$2)) - (SUMIFS(monthly_work_hours!$J:$J,monthly_work_hours!$A:$A,'FTE 계산'!$A7,monthly_work_hours!$F:$F,'FTE 계산'!J$2)) -> 16 | N7: SCM팀 | O7: =SUMIFS($E$3:$E$503,$C$3:$C$503,$N7) -> 2211.4 | P7: =SUMIFS($E$3:$E$503,$C$3:$C$503,$N7,$D$3:$D$503,P$2) -> 699.8 | Q7: =SUMIFS($E$3:$E$503,$C$3:$C$503,$N7,$D$3:$D$503,Q$2) -> 687.8 | R7: =SUMIFS($E$3:$E$503,$C$3:$C$503,$N7,$D$3:$D$503,R$2) -> 686.3 | S7: =AVERAGEIFS($H$3:$H$503,$C$3:$C$503,$N7) -> 16.428571 | T7: =AVERAGEIFS($H$3:$H$503,$C$3:$C$503,$N7,$D$3:$D$503,P$2) -> 17.5 | U7: =AVERAGEIFS($H$3:$H$503,$C$3:$C$503,$N7,$D$3:$D$503,Q$2) -> 16.75 | V7: =AVERAGEIFS($H$3:$H$503,$C$3:$C$503,$N7,$D$3:$D$503,R$2) -> 18 | W7: =IFERROR(O7/(S7*$L$2),"-") -> 16.82587 | X7: =IFERROR(P7/(T7*$L$2),"-") -> 4.9985714 | Y7: =IFERROR(Q7/(U7*$L$2),"-") -> 5.1328358 | Z7: =IFERROR(R7/(V7*$L$2),"-") -> 4.7659722 | AA7: =SUMIFS($F$3:$F$503,$C$3:$C$503,$N7) -> 2161.5 | AB7: =SUMIFS($F$3:$F$503,$C$3:$C$503,$N7,$D$3:$D$503,P$2) -> 715 | AC7: =SUMIFS($F$3:$F$503,$C$3:$C$503,$N7,$D$3:$D$503,Q$2) -> 548.7 | AD7: =SUMIFS($F$3:$F$503,$C$3:$C$503,$N7,$D$3:$D$503,R$2) -> 764.1 | AE7: =AVERAGEIFS($I$3:$I$503,$C$3:$C$503,$N7) -> 16.642857 | AF7: =AVERAGEIFS($I$3:$I$503,$C$3:$C$503,$N7,$D$3:$D$503,P$2) -> 18.5 | AG7: =AVERAGEIFS($I$3:$I$503,$C$3:$C$503,$N7,$D$3:$D$503,Q$2) -> 15.5 | AH7: =AVERAGEIFS($I$3:$I$503,$C$3:$C$503,$N7,$D$3:$D$503,R$2) -> 19.5 | AI7: =IFERROR(AA7/(AE7*$L$2),"-") -> 16.234442 | AJ7: =IFERROR(AB7/(AF7*$L$2),"-") -> 4.8310811 | AK7: =IFERROR(AC7/(AG7*$L$2),"-") -> 4.425 | AL7: =IFERROR(AD7/(AH7*$L$2),"-") -> 4.8980769 | AM7: =SUMIFS($G$3:$G$503,$C$3:$C$503,$N7) -> 1737.2 | AN7: =SUMIFS($G$3:$G$503,$C$3:$C$503,$N7,$D$3:$D$503,P$2) -> 596.8 | AO7: =SUMIFS($G$3:$G$503,$C$3:$C$503,$N7,$D$3:$D$503,Q$2) -> 445.2 | AP7: =SUMIFS($G$3:$G$503,$C$3:$C$503,$N7,$D$3:$D$503,R$2) -> 591.8 | AQ7: =AVERAGEIFS($J$3:$J$503,$C$3:$C$503,$N7) -> 13.928571 | AR7: =AVERAGEIFS($J$3:$J$503,$C$3:$C$503,$N7,$D$3:$D$503,P$2) -> 16 | AS7: =AVERAGEIFS($J$3:$J$503,$C$3:$C$503,$N7,$D$3:$D$503,Q$2) -> 12 | AT7: =AVERAGEIFS($J$3:$J$503,$C$3:$C$503,$N7,$D$3:$D$503,R$2) -> 16.25 | AU7: =IFERROR(AM7/(AQ7*$L$2),"-") -> 15.590256 | AV7: =IFERROR(AN7/(AR7*$L$2),"-") -> 4.6625 | AW7: =IFERROR(AO7/(AS7*$L$2),"-") -> 4.6375 | AX7: =IFERROR(AP7/(AT7*$L$2),"-") -> 4.5523077
A8: 1203053 | B8: =_xlfn.XLOOKUP(A8,monthly_work_hours!A:A,monthly_work_hours!B:B) -> 문은진 | C8: =_xlfn.XLOOKUP(A8,monthly_work_hours!A:A,monthly_work_hours!C:C) -> SCM팀 | D8: =_xlfn.XLOOKUP(A8,monthly_work_hours!A:A,monthly_work_hours!D:D) -> 책임 | E8: =SUMIFS(monthly_work_hours!$K:$K,monthly_work_hours!$A:$A,'FTE 계산'!$A8,monthly_work_hours!$F:$F,'FTE 계산'!E$2) -> 170.4 | F8: =SUMIFS(monthly_work_hours!$K:$K,monthly_work_hours!$A:$A,'FTE 계산'!$A8,monthly_work_hours!$F:$F,'FTE 계산'!F$2) -> 165.4 | G8: =SUMIFS(monthly_work_hours!$K:$K,monthly_work_hours!$A:$A,'FTE 계산'!$A8,monthly_work_hours!$F:$F,'FTE 계산'!G$2) -> 140.3 | H8: =(SUMIFS(monthly_work_hours!$G:$G,monthly_work_hours!$A:$A,'FTE 계산'!$A8,monthly_work_hours!$F:$F,'FTE 계산'!H$2)) - (SUMIFS(monthly_work_hours!$J:$J,monthly_work_hours!$A:$A,'FTE 계산'!$A8,monthly_work_hours!$F:$F,'FTE 계산'!H$2)) -> 17 | I8: =(SUMIFS(monthly_work_hours!$G:$G,monthly_work_hours!$A:$A,'FTE 계산'!$A8,monthly_work_hours!$F:$F,'FTE 계산'!I$2)) - (SUMIFS(monthly_work_hours!$J:$J,monthly_work_hours!$A:$A,'FTE 계산'!$A8,monthly_work_hours!$F:$F,'FTE 계산'!I$2)) -> 18 | J8: =(SUMIFS(monthly_work_hours!$G:$G,monthly_work_hours!$A:$A,'FTE 계산'!$A8,monthly_work_hours!$F:$F,'FTE 계산'!J$2)) - (SUMIFS(monthly_work_hours!$J:$J,monthly_work_hours!$A:$A,'FTE 계산'!$A8,monthly_work_hours!$F:$F,'FTE 계산'!J$2)) -> 16 | N8: SL품질보증팀 | O8: =SUMIFS($E$3:$E$503,$C$3:$C$503,$N8) -> 1599.7 | P8: =SUMIFS($E$3:$E$503,$C$3:$C$503,$N8,$D$3:$D$503,P$2) -> 322 | Q8: =SUMIFS($E$3:$E$503,$C$3:$C$503,$N8,$D$3:$D$503,Q$2) -> 833.1 | R8: =SUMIFS($E$3:$E$503,$C$3:$C$503,$N8,$D$3:$D$503,R$2) -> 341 | S8: =AVERAGEIFS($H$3:$H$503,$C$3:$C$503,$N8) -> 13.2 | T8: =AVERAGEIFS($H$3:$H$503,$C$3:$C$503,$N8,$D$3:$D$503,P$2) -> 11.666667 | U8: =AVERAGEIFS($H$3:$H$503,$C$3:$C$503,$N8,$D$3:$D$503,Q$2) -> 12.875 | V8: =AVERAGEIFS($H$3:$H$503,$C$3:$C$503,$N8,$D$3:$D$503,R$2) -> 13.333333 | W8: =IFERROR(O8/(S8*$L$2),"-") -> 15.148674 | X8: =IFERROR(P8/(T8*$L$2),"-") -> 3.45 | Y8: =IFERROR(Q8/(U8*$L$2),"-") -> 8.0883495 | Z8: =IFERROR(R8/(V8*$L$2),"-") -> 3.196875 | AA8: =SUMIFS($F$3:$F$503,$C$3:$C$503,$N8) -> 1658.5 | AB8: =SUMIFS($F$3:$F$503,$C$3:$C$503,$N8,$D$3:$D$503,P$2) -> 321.4 | AC8: =SUMIFS($F$3:$F$503,$C$3:$C$503,$N8,$D$3:$D$503,Q$2) -> 802.3 | AD8: =SUMIFS($F$3:$F$503,$C$3:$C$503,$N8,$D$3:$D$503,R$2) -> 439.1 | AE8: =AVERAGEIFS($I$3:$I$503,$C$3:$C$503,$N8) -> 13.866667 | AF8: =AVERAGEIFS($I$3:$I$503,$C$3:$C$503,$N8,$D$3:$D$503,P$2) -> 12.333333 | AG8: =AVERAGEIFS($I$3:$I$503,$C$3:$C$503,$N8,$D$3:$D$503,Q$2) -> 13 | AH8: =AVERAGEIFS($I$3:$I$503,$C$3:$C$503,$N8,$D$3:$D$503,R$2) -> 16 | AI8: =IFERROR(AA8/(AE8*$L$2),"-") -> 14.950421 | AJ8: =IFERROR(AB8/(AF8*$L$2),"-") -> 3.2574324 | AK8: =IFERROR(AC8/(AG8*$L$2),"-") -> 7.7144231 | AL8: =IFERROR(AD8/(AH8*$L$2),"-") -> 3.4304688 | AM8: =SUMIFS($G$3:$G$503,$C$3:$C$503,$N8) -> 1341.3 | AN8: =SUMIFS($G$3:$G$503,$C$3:$C$503,$N8,$D$3:$D$503,P$2) -> 297.1 | AO8: =SUMIFS($G$3:$G$503,$C$3:$C$503,$N8,$D$3:$D$503,Q$2) -> 627.6 | AP8: =SUMIFS($G$3:$G$503,$C$3:$C$503,$N8,$D$3:$D$503,R$2) -> 318.8 | AQ8: =AVERAGEIFS($J$3:$J$503,$C$3:$C$503,$N8) -> 11.733333 | AR8: =AVERAGEIFS($J$3:$J$503,$C$3:$C$503,$N8,$D$3:$D$503,P$2) -> 11.333333 | AS8: =AVERAGEIFS($J$3:$J$503,$C$3:$C$503,$N8,$D$3:$D$503,Q$2) -> 10.875 | AT8: =AVERAGEIFS($J$3:$J$503,$C$3:$C$503,$N8,$D$3:$D$503,R$2) -> 12.666667 | AU8: =IFERROR(AM8/(AQ8*$L$2),"-") -> 14.289418 | AV8: =IFERROR(AN8/(AR8*$L$2),"-") -> 3.2768382 | AW8: =IFERROR(AO8/(AS8*$L$2),"-") -> 7.2137931 | AX8: =IFERROR(AP8/(AT8*$L$2),"-") -> 3.1460526
A9: 1204003 | B9: =_xlfn.XLOOKUP(A9,monthly_work_hours!A:A,monthly_work_hours!B:B) -> 정용규 | C9: =_xlfn.XLOOKUP(A9,monthly_work_hours!A:A,monthly_work_hours!C:C) -> SL생산기술팀 | D9: =_xlfn.XLOOKUP(A9,monthly_work_hours!A:A,monthly_work_hours!D:D) -> 책임 | E9: =SUMIFS(monthly_work_hours!$K:$K,monthly_work_hours!$A:$A,'FTE 계산'!$A9,monthly_work_hours!$F:$F,'FTE 계산'!E$2) -> 147.9 | F9: =SUMIFS(monthly_work_hours!$K:$K,monthly_work_hours!$A:$A,'FTE 계산'!$A9,monthly_work_hours!$F:$F,'FTE 계산'!F$2) -> 191.4 | G9: =SUMIFS(monthly_work_hours!$K:$K,monthly_work_hours!$A:$A,'FTE 계산'!$A9,monthly_work_hours!$F:$F,'FTE 계산'!G$2) -> 149.5 | H9: =(SUMIFS(monthly_work_hours!$G:$G,monthly_work_hours!$A:$A,'FTE 계산'!$A9,monthly_work_hours!$F:$F,'FTE 계산'!H$2)) - (SUMIFS(monthly_work_hours!$J:$J,monthly_work_hours!$A:$A,'FTE 계산'!$A9,monthly_work_hours!$F:$F,'FTE 계산'!H$2)) -> 17 | I9: =(SUMIFS(monthly_work_hours!$G:$G,monthly_work_hours!$A:$A,'FTE 계산'!$A9,monthly_work_hours!$F:$F,'FTE 계산'!I$2)) - (SUMIFS(monthly_work_hours!$J:$J,monthly_work_hours!$A:$A,'FTE 계산'!$A9,monthly_work_hours!$F:$F,'FTE 계산'!I$2)) -> 19 | J9: =(SUMIFS(monthly_work_hours!$G:$G,monthly_work_hours!$A:$A,'FTE 계산'!$A9,monthly_work_hours!$F:$F,'FTE 계산'!J$2)) - (SUMIFS(monthly_work_hours!$J:$J,monthly_work_hours!$A:$A,'FTE 계산'!$A9,monthly_work_hours!$F:$F,'FTE 계산'!J$2)) -> 16 | N9: 열관리설계팀 | O9: =SUMIFS($E$3:$E$503,$C$3:$C$503,$N9) -> 2526.8 | P9: =SUMIFS($E$3:$E$503,$C$3:$C$503,$N9,$D$3:$D$503,P$2) -> 1582.1 | Q9: =SUMIFS($E$3:$E$503,$C$3:$C$503,$N9,$D$3:$D$503,Q$2) -> 626.9 | R9: =SUMIFS($E$3:$E$503,$C$3:$C$503,$N9,$D$3:$D$503,R$2) -> 317.8 | S9: =AVERAGEIFS($H$3:$H$503,$C$3:$C$503,$N9) -> 14.363636 | T9: =AVERAGEIFS($H$3:$H$503,$C$3:$C$503,$N9,$D$3:$D$503,P$2) -> 14 | U9: =AVERAGEIFS($H$3:$H$503,$C$3:$C$503,$N9,$D$3:$D$503,Q$2) -> 16.5 | V9: =AVERAGEIFS($H$3:$H$503,$C$3:$C$503,$N9,$D$3:$D$503,R$2) -> 12 | W9: =IFERROR(O9/(S9*$L$2),"-") -> 21.989557 | X9: =IFERROR(P9/(T9*$L$2),"-") -> 14.125893 | Y9: =IFERROR(Q9/(U9*$L$2),"-") -> 4.7492424 | Z9: =IFERROR(R9/(V9*$L$2),"-") -> 3.3104167 | AA9: =SUMIFS($F$3:$F$503,$C$3:$C$503,$N9) -> 2422.2 | AB9: =SUMIFS($F$3:$F$503,$C$3:$C$503,$N9,$D$3:$D$503,P$2) -> 1577.7 | AC9: =SUMIFS($F$3:$F$503,$C$3:$C$503,$N9,$D$3:$D$503,Q$2) -> 527.4 | AD9: =SUMIFS($F$3:$F$503,$C$3:$C$503,$N9,$D$3:$D$503,R$2) -> 317.1 | AE9: =AVERAGEIFS($I$3:$I$503,$C$3:$C$503,$N9) -> 14.545455 | AF9: =AVERAGEIFS($I$3:$I$503,$C$3:$C$503,$N9,$D$3:$D$503,P$2) -> 18 | AG9: =AVERAGEIFS($I$3:$I$503,$C$3:$C$503,$N9,$D$3:$D$503,Q$2) -> 13.25 | AH9: =AVERAGEIFS($I$3:$I$503,$C$3:$C$503,$N9,$D$3:$D$503,R$2) -> 11.666667 | AI9: =IFERROR(AA9/(AE9*$L$2),"-") -> 20.815781 | AJ9: =IFERROR(AB9/(AF9*$L$2),"-") -> 10.95625 | AK9: =IFERROR(AC9/(AG9*$L$2),"-") -> 4.9754717 | AL9: =IFERROR(AD9/(AH9*$L$2),"-") -> 3.3975 | AM9: =SUMIFS($G$3:$G$503,$C$3:$C$503,$N9) -> 1746.3 | AN9: =SUMIFS($G$3:$G$503,$C$3:$C$503,$N9,$D$3:$D$503,P$2) -> 1066.3 | AO9: =SUMIFS($G$3:$G$503,$C$3:$C$503,$N9,$D$3:$D$503,Q$2) -> 384.9 | AP9: =SUMIFS($G$3:$G$503,$C$3:$C$503,$N9,$D$3:$D$503,R$2) -> 295.1 | AQ9: =AVERAGEIFS($J$3:$J$503,$C$3:$C$503,$N9) -> 12.818182 | AR9: =AVERAGEIFS($J$3:$J$503,$C$3:$C$503,$N9,$D$3:$D$503,P$2) -> 15.25 | AS9: =AVERAGEIFS($J$3:$J$503,$C$3:$C$503,$N9,$D$3:$D$503,Q$2) -> 11.5 | AT9: =AVERAGEIFS($J$3:$J$503,$C$3:$C$503,$N9,$D$3:$D$503,R$2) -> 11.333333 | AU9: =IFERROR(AM9/(AQ9*$L$2),"-") -> 17.029521 | AV9: =IFERROR(AN9/(AR9*$L$2),"-") -> 8.7401639 | AW9: =IFERROR(AO9/(AS9*$L$2),"-") -> 4.1836957 | AX9: =IFERROR(AP9/(AT9*$L$2),"-") -> 3.2547794
A10: 1204063 | B10: =_xlfn.XLOOKUP(A10,monthly_work_hours!A:A,monthly_work_hours!B:B) -> 김주호 | C10: =_xlfn.XLOOKUP(A10,monthly_work_hours!A:A,monthly_work_hours!C:C) -> SL품질보증팀 | D10: =_xlfn.XLOOKUP(A10,monthly_work_hours!A:A,monthly_work_hours!D:D) -> 책임 | E10: =SUMIFS(monthly_work_hours!$K:$K,monthly_work_hours!$A:$A,'FTE 계산'!$A10,monthly_work_hours!$F:$F,'FTE 계산'!E$2) -> 7 | F10: =SUMIFS(monthly_work_hours!$K:$K,monthly_work_hours!$A:$A,'FTE 계산'!$A10,monthly_work_hours!$F:$F,'FTE 계산'!F$2) -> 0.4 | G10: =SUMIFS(monthly_work_hours!$K:$K,monthly_work_hours!$A:$A,'FTE 계산'!$A10,monthly_work_hours!$F:$F,'FTE 계산'!G$2) -> 22.8 | H10: =(SUMIFS(monthly_work_hours!$G:$G,monthly_work_hours!$A:$A,'FTE 계산'!$A10,monthly_work_hours!$F:$F,'FTE 계산'!H$2)) - (SUMIFS(monthly_work_hours!$J:$J,monthly_work_hours!$A:$A,'FTE 계산'!$A10,monthly_work_hours!$F:$F,'FTE 계산'!H$2)) -> 2 | I10: =(SUMIFS(monthly_work_hours!$G:$G,monthly_work_hours!$A:$A,'FTE 계산'!$A10,monthly_work_hours!$F:$F,'FTE 계산'!I$2)) - (SUMIFS(monthly_work_hours!$J:$J,monthly_work_hours!$A:$A,'FTE 계산'!$A10,monthly_work_hours!$F:$F,'FTE 계산'!I$2)) -> 4 | J10: =(SUMIFS(monthly_work_hours!$G:$G,monthly_work_hours!$A:$A,'FTE 계산'!$A10,monthly_work_hours!$F:$F,'FTE 계산'!J$2)) - (SUMIFS(monthly_work_hours!$J:$J,monthly_work_hours!$A:$A,'FTE 계산'!$A10,monthly_work_hours!$F:$F,'FTE 계산'!J$2)) -> 4 | N10: FL생산기술팀 | O10: =SUMIFS($E$3:$E$503,$C$3:$C$503,$N10) -> 1315.9 | P10: =SUMIFS($E$3:$E$503,$C$3:$C$503,$N10,$D$3:$D$503,P$2) -> 371.9 | Q10: =SUMIFS($E$3:$E$503,$C$3:$C$503,$N10,$D$3:$D$503,Q$2) -> 429.8 | R10: =SUMIFS($E$3:$E$503,$C$3:$C$503,$N10,$D$3:$D$503,R$2) -> 514.2 | S10: =AVERAGEIFS($H$3:$H$503,$C$3:$C$503,$N10) -> 17 | T10: =AVERAGEIFS($H$3:$H$503,$C$3:$C$503,$N10,$D$3:$D$503,P$2) -> 18.5 | U10: =AVERAGEIFS($H$3:$H$503,$C$3:$C$503,$N10,$D$3:$D$503,Q$2) -> 15.666667 | V10: =AVERAGEIFS($H$3:$H$503,$C$3:$C$503,$N10,$D$3:$D$503,R$2) -> 17.333333 | W10: =IFERROR(O10/(S10*$L$2),"-") -> 9.6757353 | X10: =IFERROR(P10/(T10*$L$2),"-") -> 2.5128378 | Y10: =IFERROR(Q10/(U10*$L$2),"-") -> 3.4292553 | Z10: =IFERROR(R10/(V10*$L$2),"-") -> 3.7081731 | AA10: =SUMIFS($F$3:$F$503,$C$3:$C$503,$N10) -> 1478.4 | AB10: =SUMIFS($F$3:$F$503,$C$3:$C$503,$N10,$D$3:$D$503,P$2) -> 378.2 | AC10: =SUMIFS($F$3:$F$503,$C$3:$C$503,$N10,$D$3:$D$503,Q$2) -> 534.7 | AD10: =SUMIFS($F$3:$F$503,$C$3:$C$503,$N10,$D$3:$D$503,R$2) -> 565.5 | AE10: =AVERAGEIFS($I$3:$I$503,$C$3:$C$503,$N10) -> 17.5 | AF10: =AVERAGEIFS($I$3:$I$503,$C$3:$C$503,$N10,$D$3:$D$503,P$2) -> 18.5 | AG10: =AVERAGEIFS($I$3:$I$503,$C$3:$C$503,$N10,$D$3:$D$503,Q$2) -> 16.333333 | AH10: =AVERAGEIFS($I$3:$I$503,$C$3:$C$503,$N10,$D$3:$D$503,R$2) -> 18 | AI10: =IFERROR(AA10/(AE10*$L$2),"-") -> 10.56 | AJ10: =IFERROR(AB10/(AF10*$L$2),"-") -> 2.5554054 | AK10: =IFERROR(AC10/(AG10*$L$2),"-") -> 4.0920918 | AL10: =IFERROR(AD10/(AH10*$L$2),"-") -> 3.9270833 | AM10: =SUMIFS($G$3:$G$503,$C$3:$C$503,$N10) -> 1156.3 | AN10: =SUMIFS($G$3:$G$503,$C$3:$C$503,$N10,$D$3:$D$503,P$2) -> 305.5 | AO10: =SUMIFS($G$3:$G$503,$C$3:$C$503,$N10,$D$3:$D$503,Q$2) -> 430 | AP10: =SUMIFS($G$3:$G$503,$C$3:$C$503,$N10,$D$3:$D$503,R$2) -> 420.8 | AQ10: =AVERAGEIFS($J$3:$J$503,$C$3:$C$503,$N10) -> 15.625 | AR10: =AVERAGEIFS($J$3:$J$503,$C$3:$C$503,$N10,$D$3:$D$503,P$2) -> 16 | AS10: =AVERAGEIFS($J$3:$J$503,$C$3:$C$503,$N10,$D$3:$D$503,Q$2) -> 15.333333 | AT10: =AVERAGEIFS($J$3:$J$503,$C$3:$C$503,$N10,$D$3:$D$503,R$2) -> 15.666667 | AU10: =IFERROR(AM10/(AQ10*$L$2),"-") -> 9.2504 | AV10: =IFERROR(AN10/(AR10*$L$2),"-") -> 2.3867188 | AW10: =IFERROR(AO10/(AS10*$L$2),"-") -> 3.5054348 | AX10: =IFERROR(AP10/(AT10*$L$2),"-") -> 3.3574468
A11: 1204106 | B11: =_xlfn.XLOOKUP(A11,monthly_work_hours!A:A,monthly_work_hours!B:B) -> 김영준 | C11: =_xlfn.XLOOKUP(A11,monthly_work_hours!A:A,monthly_work_hours!C:C) -> 열관리설계팀 | D11: =_xlfn.XLOOKUP(A11,monthly_work_hours!A:A,monthly_work_hours!D:D) -> 책임 | E11: =SUMIFS(monthly_work_hours!$K:$K,monthly_work_hours!$A:$A,'FTE 계산'!$A11,monthly_work_hours!$F:$F,'FTE 계산'!E$2) -> 218.9 | F11: =SUMIFS(monthly_work_hours!$K:$K,monthly_work_hours!$A:$A,'FTE 계산'!$A11,monthly_work_hours!$F:$F,'FTE 계산'!F$2) -> 160.1 | G11: =SUMIFS(monthly_work_hours!$K:$K,monthly_work_hours!$A:$A,'FTE 계산'!$A11,monthly_work_hours!$F:$F,'FTE 계산'!G$2) -> 133 | H11: =(SUMIFS(monthly_work_hours!$G:$G,monthly_work_hours!$A:$A,'FTE 계산'!$A11,monthly_work_hours!$F:$F,'FTE 계산'!H$2)) - (SUMIFS(monthly_work_hours!$J:$J,monthly_work_hours!$A:$A,'FTE 계산'!$A11,monthly_work_hours!$F:$F,'FTE 계산'!H$2)) -> 14 | I11: =(SUMIFS(monthly_work_hours!$G:$G,monthly_work_hours!$A:$A,'FTE 계산'!$A11,monthly_work_hours!$F:$F,'FTE 계산'!I$2)) - (SUMIFS(monthly_work_hours!$J:$J,monthly_work_hours!$A:$A,'FTE 계산'!$A11,monthly_work_hours!$F:$F,'FTE 계산'!I$2)) -> 16 | J11: =(SUMIFS(monthly_work_hours!$G:$G,monthly_work_hours!$A:$A,'FTE 계산'!$A11,monthly_work_hours!$F:$F,'FTE 계산'!J$2)) - (SUMIFS(monthly_work_hours!$J:$J,monthly_work_hours!$A:$A,'FTE 계산'!$A11,monthly_work_hours!$F:$F,'FTE 계산'!J$2)) -> 15 | N11: FL개발팀 | O11: =SUMIFS($E$3:$E$503,$C$3:$C$503,$N11) -> 2346.1 | P11: =SUMIFS($E$3:$E$503,$C$3:$C$503,$N11,$D$3:$D$503,P$2) -> 664.6 | Q11: =SUMIFS($E$3:$E$503,$C$3:$C$503,$N11,$D$3:$D$503,Q$2) -> 1097.9 | R11: =SUMIFS($E$3:$E$503,$C$3:$C$503,$N11,$D$3:$D$503,R$2) -> 385.8 | S11: =AVERAGEIFS($H$3:$H$503,$C$3:$C$503,$N11) -> 15.266667 | T11: =AVERAGEIFS($H$3:$H$503,$C$3:$C$503,$N11,$D$3:$D$503,P$2) -> 18 | U11: =AVERAGEIFS($H$3:$H$503,$C$3:$C$503,$N11,$D$3:$D$503,Q$2) -> 16.428571 | V11: =AVERAGEIFS($H$3:$H$503,$C$3:$C$503,$N11,$D$3:$D$503,R$2) -> 10.5 | W11: =IFERROR(O11/(S11*$L$2),"-") -> 19.209334 | X11: =IFERROR(P11/(T11*$L$2),"-") -> 4.6152778 | Y11: =IFERROR(Q11/(U11*$L$2),"-") -> 8.353587 | Z11: =IFERROR(R11/(V11*$L$2),"-") -> 4.5928571 | AA11: =SUMIFS($F$3:$F$503,$C$3:$C$503,$N11) -> 2459.9 | AB11: =SUMIFS($F$3:$F$503,$C$3:$C$503,$N11,$D$3:$D$503,P$2) -> 540 | AC11: =SUMIFS($F$3:$F$503,$C$3:$C$503,$N11,$D$3:$D$503,Q$2) -> 1144.8 | AD11: =SUMIFS($F$3:$F$503,$C$3:$C$503,$N11,$D$3:$D$503,R$2) -> 524.7 | AE11: =AVERAGEIFS($I$3:$I$503,$C$3:$C$503,$N11) -> 16.333333 | AF11: =AVERAGEIFS($I$3:$I$503,$C$3:$C$503,$N11,$D$3:$D$503,P$2) -> 18 | AG11: =AVERAGEIFS($I$3:$I$503,$C$3:$C$503,$N11,$D$3:$D$503,Q$2) -> 16.428571 | AH11: =AVERAGEIFS($I$3:$I$503,$C$3:$C$503,$N11,$D$3:$D$503,R$2) -> 14.75 | AI11: =IFERROR(AA11/(AE11*$L$2),"-") -> 18.825765 | AJ11: =IFERROR(AB11/(AF11*$L$2),"-") -> 3.75 | AK11: =IFERROR(AC11/(AG11*$L$2),"-") -> 8.7104348 | AL11: =IFERROR(AD11/(AH11*$L$2),"-") -> 4.4466102 | AM11: =SUMIFS($G$3:$G$503,$C$3:$C$503,$N11) -> 1828.4 | AN11: =SUMIFS($G$3:$G$503,$C$3:$C$503,$N11,$D$3:$D$503,P$2) -> 459.6 | AO11: =SUMIFS($G$3:$G$503,$C$3:$C$503,$N11,$D$3:$D$503,Q$2) -> 874.2 | AP11: =SUMIFS($G$3:$G$503,$C$3:$C$503,$N11,$D$3:$D$503,R$2) -> 436 | AQ11: =AVERAGEIFS($J$3:$J$503,$C$3:$C$503,$N11) -> 14.2 | AR11: =AVERAGEIFS($J$3:$J$503,$C$3:$C$503,$N11,$D$3:$D$503,P$2) -> 16 | AS11: =AVERAGEIFS($J$3:$J$503,$C$3:$C$503,$N11,$D$3:$D$503,Q$2) -> 14 | AT11: =AVERAGEIFS($J$3:$J$503,$C$3:$C$503,$N11,$D$3:$D$503,R$2) -> 13.5 | AU11: =IFERROR(AM11/(AQ11*$L$2),"-") -> 16.09507 | AV11: =IFERROR(AN11/(AR11*$L$2),"-") -> 3.590625 | AW11: =IFERROR(AO11/(AS11*$L$2),"-") -> 7.8053571 | AX11: =IFERROR(AP11/(AT11*$L$2),"-") -> 4.037037
A12: 1204115 | B12: =_xlfn.XLOOKUP(A12,monthly_work_hours!A:A,monthly_work_hours!B:B) -> 이용재 | C12: =_xlfn.XLOOKUP(A12,monthly_work_hours!A:A,monthly_work_hours!C:C) -> FL생산기술팀 | D12: =_xlfn.XLOOKUP(A12,monthly_work_hours!A:A,monthly_work_hours!D:D) -> 책임 | E12: =SUMIFS(monthly_work_hours!$K:$K,monthly_work_hours!$A:$A,'FTE 계산'!$A12,monthly_work_hours!$F:$F,'FTE 계산'!E$2) -> 172.1 | F12: =SUMIFS(monthly_work_hours!$K:$K,monthly_work_hours!$A:$A,'FTE 계산'!$A12,monthly_work_hours!$F:$F,'FTE 계산'!F$2) -> 174 | G12: =SUMIFS(monthly_work_hours!$K:$K,monthly_work_hours!$A:$A,'FTE 계산'!$A12,monthly_work_hours!$F:$F,'FTE 계산'!G$2) -> 146.6 | H12: =(SUMIFS(monthly_work_hours!$G:$G,monthly_work_hours!$A:$A,'FTE 계산'!$A12,monthly_work_hours!$F:$F,'FTE 계산'!H$2)) - (SUMIFS(monthly_work_hours!$J:$J,monthly_work_hours!$A:$A,'FTE 계산'!$A12,monthly_work_hours!$F:$F,'FTE 계산'!H$2)) -> 18 | I12: =(SUMIFS(monthly_work_hours!$G:$G,monthly_work_hours!$A:$A,'FTE 계산'!$A12,monthly_work_hours!$F:$F,'FTE 계산'!I$2)) - (SUMIFS(monthly_work_hours!$J:$J,monthly_work_hours!$A:$A,'FTE 계산'!$A12,monthly_work_hours!$F:$F,'FTE 계산'!I$2)) -> 18 | J12: =(SUMIFS(monthly_work_hours!$G:$G,monthly_work_hours!$A:$A,'FTE 계산'!$A12,monthly_work_hours!$F:$F,'FTE 계산'!J$2)) - (SUMIFS(monthly_work_hours!$J:$J,monthly_work_hours!$A:$A,'FTE 계산'!$A12,monthly_work_hours!$F:$F,'FTE 계산'!J$2)) -> 16 | N12: SL구매팀 | O12: =SUMIFS($E$3:$E$503,$C$3:$C$503,$N12) -> 1619.7 | P12: =SUMIFS($E$3:$E$503,$C$3:$C$503,$N12,$D$3:$D$503,P$2) -> 939.7 | Q12: =SUMIFS($E$3:$E$503,$C$3:$C$503,$N12,$D$3:$D$503,Q$2) -> 520.7 | R12: =SUMIFS($E$3:$E$503,$C$3:$C$503,$N12,$D$3:$D$503,R$2) -> 159.3 | S12: =AVERAGEIFS($H$3:$H$503,$C$3:$C$503,$N12) -> 17.5 | T12: =AVERAGEIFS($H$3:$H$503,$C$3:$C$503,$N12,$D$3:$D$503,P$2) -> 17.5 | U12: =AVERAGEIFS($H$3:$H$503,$C$3:$C$503,$N12,$D$3:$D$503,Q$2) -> 18 | V12: =AVERAGEIFS($H$3:$H$503,$C$3:$C$503,$N12,$D$3:$D$503,R$2) -> 16 | W12: =IFERROR(O12/(S12*$L$2),"-") -> 11.569286 | X12: =IFERROR(P12/(T12*$L$2),"-") -> 6.7121429 | Y12: =IFERROR(Q12/(U12*$L$2),"-") -> 3.6159722 | Z12: =IFERROR(R12/(V12*$L$2),"-") -> 1.2445313 | AA12: =SUMIFS($F$3:$F$503,$C$3:$C$503,$N12) -> 1387.8 | AB12: =SUMIFS($F$3:$F$503,$C$3:$C$503,$N12,$D$3:$D$503,P$2) -> 737.4 | AC12: =SUMIFS($F$3:$F$503,$C$3:$C$503,$N12,$D$3:$D$503,Q$2) -> 508.6 | AD12: =SUMIFS($F$3:$F$503,$C$3:$C$503,$N12,$D$3:$D$503,R$2) -> 141.8 | AE12: =AVERAGEIFS($I$3:$I$503,$C$3:$C$503,$N12) -> 16.875 | AF12: =AVERAGEIFS($I$3:$I$503,$C$3:$C$503,$N12,$D$3:$D$503,P$2) -> 17.5 | AG12: =AVERAGEIFS($I$3:$I$503,$C$3:$C$503,$N12,$D$3:$D$503,Q$2) -> 17 | AH12: =AVERAGEIFS($I$3:$I$503,$C$3:$C$503,$N12,$D$3:$D$503,R$2) -> 14 | AI12: =IFERROR(AA12/(AE12*$L$2),"-") -> 10.28 | AJ12: =IFERROR(AB12/(AF12*$L$2),"-") -> 5.2671429 | AK12: =IFERROR(AC12/(AG12*$L$2),"-") -> 3.7397059 | AL12: =IFERROR(AD12/(AH12*$L$2),"-") -> 1.2660714 | AM12: =SUMIFS($G$3:$G$503,$C$3:$C$503,$N12) -> 1248.5 | AN12: =SUMIFS($G$3:$G$503,$C$3:$C$503,$N12,$D$3:$D$503,P$2) -> 675.9 | AO12: =SUMIFS($G$3:$G$503,$C$3:$C$503,$N12,$D$3:$D$503,Q$2) -> 446.8 | AP12: =SUMIFS($G$3:$G$503,$C$3:$C$503,$N12,$D$3:$D$503,R$2) -> 125.8 | AQ12: =AVERAGEIFS($J$3:$J$503,$C$3:$C$503,$N12) -> 14.875 | AR12: =AVERAGEIFS($J$3:$J$503,$C$3:$C$503,$N12,$D$3:$D$503,P$2) -> 15 | AS12: =AVERAGEIFS($J$3:$J$503,$C$3:$C$503,$N12,$D$3:$D$503,Q$2) -> 15 | AT12: =AVERAGEIFS($J$3:$J$503,$C$3:$C$503,$N12,$D$3:$D$503,R$2) -> 14 | AU12: =IFERROR(AM12/(AQ12*$L$2),"-") -> 10.491597 | AV12: =IFERROR(AN12/(AR12*$L$2),"-") -> 5.6325 | AW12: =IFERROR(AO12/(AS12*$L$2),"-") -> 3.7233333 | AX12: =IFERROR(AP12/(AT12*$L$2),"-") -> 1.1232143
A13: 1205081 | B13: =_xlfn.XLOOKUP(A13,monthly_work_hours!A:A,monthly_work_hours!B:B) -> 이호진 | C13: =_xlfn.XLOOKUP(A13,monthly_work_hours!A:A,monthly_work_hours!C:C) -> SCM팀 | D13: =_xlfn.XLOOKUP(A13,monthly_work_hours!A:A,monthly_work_hours!D:D) -> 기능주임 | E13: =SUMIFS(monthly_work_hours!$K:$K,monthly_work_hours!$A:$A,'FTE 계산'!$A13,monthly_work_hours!$F:$F,'FTE 계산'!E$2) -> 0 | F13: =SUMIFS(monthly_work_hours!$K:$K,monthly_work_hours!$A:$A,'FTE 계산'!$A13,monthly_work_hours!$F:$F,'FTE 계산'!F$2) -> 0 | G13: =SUMIFS(monthly_work_hours!$K:$K,monthly_work_hours!$A:$A,'FTE 계산'!$A13,monthly_work_hours!$F:$F,'FTE 계산'!G$2) -> 0 | H13: =(SUMIFS(monthly_work_hours!$G:$G,monthly_work_hours!$A:$A,'FTE 계산'!$A13,monthly_work_hours!$F:$F,'FTE 계산'!H$2)) - (SUMIFS(monthly_work_hours!$J:$J,monthly_work_hours!$A:$A,'FTE 계산'!$A13,monthly_work_hours!$F:$F,'FTE 계산'!H$2)) -> 0 | I13: =(SUMIFS(monthly_work_hours!$G:$G,monthly_work_hours!$A:$A,'FTE 계산'!$A13,monthly_work_hours!$F:$F,'FTE 계산'!I$2)) - (SUMIFS(monthly_work_hours!$J:$J,monthly_work_hours!$A:$A,'FTE 계산'!$A13,monthly_work_hours!$F:$F,'FTE 계산'!I$2)) -> 1 | J13: =(SUMIFS(monthly_work_hours!$G:$G,monthly_work_hours!$A:$A,'FTE 계산'!$A13,monthly_work_hours!$F:$F,'FTE 계산'!J$2)) - (SUMIFS(monthly_work_hours!$J:$J,monthly_work_hours!$A:$A,'FTE 계산'!$A13,monthly_work_hours!$F:$F,'FTE 계산'!J$2)) -> 0 | N13: 품질경영팀 | O13: =SUMIFS($E$3:$E$503,$C$3:$C$503,$N13) -> 1969.5 | P13: =SUMIFS($E$3:$E$503,$C$3:$C$503,$N13,$D$3:$D$503,P$2) -> 637.3 | Q13: =SUMIFS($E$3:$E$503,$C$3:$C$503,$N13,$D$3:$D$503,Q$2) -> 1163.7 | R13: =SUMIFS($E$3:$E$503,$C$3:$C$503,$N13,$D$3:$D$503,R$2) -> 168.5 | S13: =AVERAGEIFS($H$3:$H$503,$C$3:$C$503,$N13) -> 16.230769 | T13: =AVERAGEIFS($H$3:$H$503,$C$3:$C$503,$N13,$D$3:$D$503,P$2) -> 17.5 | U13: =AVERAGEIFS($H$3:$H$503,$C$3:$C$503,$N13,$D$3:$D$503,Q$2) -> 17.285714 | V13: =AVERAGEIFS($H$3:$H$503,$C$3:$C$503,$N13,$D$3:$D$503,R$2) -> 18 | W13: =IFERROR(O13/(S13*$L$2),"-") -> 15.16795 | X13: =IFERROR(P13/(T13*$L$2),"-") -> 4.5521429 | Y13: =IFERROR(Q13/(U13*$L$2),"-") -> 8.415186 | Z13: =IFERROR(R13/(V13*$L$2),"-") -> 1.1701389 | AA13: =SUMIFS($F$3:$F$503,$C$3:$C$503,$N13) -> 2014.4 | AB13: =SUMIFS($F$3:$F$503,$C$3:$C$503,$N13,$D$3:$D$503,P$2) -> 674.3 | AC13: =SUMIFS($F$3:$F$503,$C$3:$C$503,$N13,$D$3:$D$503,Q$2) -> 1183 | AD13: =SUMIFS($F$3:$F$503,$C$3:$C$503,$N13,$D$3:$D$503,R$2) -> 155.7 | AE13: =AVERAGEIFS($I$3:$I$503,$C$3:$C$503,$N13) -> 17.076923 | AF13: =AVERAGEIFS($I$3:$I$503,$C$3:$C$503,$N13,$D$3:$D$503,P$2) -> 18 | AG13: =AVERAGEIFS($I$3:$I$503,$C$3:$C$503,$N13,$D$3:$D$503,Q$2) -> 17.857143 | AH13: =AVERAGEIFS($I$3:$I$503,$C$3:$C$503,$N13,$D$3:$D$503,R$2) -> 17 | AI13: =IFERROR(AA13/(AE13*$L$2),"-") -> 14.745045 | AJ13: =IFERROR(AB13/(AF13*$L$2),"-") -> 4.6826389 | AK13: =IFERROR(AC13/(AG13*$L$2),"-") -> 8.281 | AL13: =IFERROR(AD13/(AH13*$L$2),"-") -> 1.1448529 | AM13: =SUMIFS($G$3:$G$503,$C$3:$C$503,$N13) -> 1663.4 | AN13: =SUMIFS($G$3:$G$503,$C$3:$C$503,$N13,$D$3:$D$503,P$2) -> 556.2 | AO13: =SUMIFS($G$3:$G$503,$C$3:$C$503,$N13,$D$3:$D$503,Q$2) -> 967.6 | AP13: =SUMIFS($G$3:$G$503,$C$3:$C$503,$N13,$D$3:$D$503,R$2) -> 139.6 | AQ13: =AVERAGEIFS($J$3:$J$503,$C$3:$C$503,$N13) -> 14.384615 | AR13: =AVERAGEIFS($J$3:$J$503,$C$3:$C$503,$N13,$D$3:$D$503,P$2) -> 15.75 | AS13: =AVERAGEIFS($J$3:$J$503,$C$3:$C$503,$N13,$D$3:$D$503,Q$2) -> 15.428571 | AT13: =AVERAGEIFS($J$3:$J$503,$C$3:$C$503,$N13,$D$3:$D$503,R$2) -> 16 | AU13: =IFERROR(AM13/(AQ13*$L$2),"-") -> 14.454679 | AV13: =IFERROR(AN13/(AR13*$L$2),"-") -> 4.4142857 | AW13: =IFERROR(AO13/(AS13*$L$2),"-") -> 7.8393519 | AX13: =IFERROR(AP13/(AT13*$L$2),"-") -> 1.090625
A14: 1205094 | B14: =_xlfn.XLOOKUP(A14,monthly_work_hours!A:A,monthly_work_hours!B:B) -> 강동현 | C14: =_xlfn.XLOOKUP(A14,monthly_work_hours!A:A,monthly_work_hours!C:C) -> FL개발팀 | D14: =_xlfn.XLOOKUP(A14,monthly_work_hours!A:A,monthly_work_hours!D:D) -> 책임 | E14: =SUMIFS(monthly_work_hours!$K:$K,monthly_work_hours!$A:$A,'FTE 계산'!$A14,monthly_work_hours!$F:$F,'FTE 계산'!E$2) -> 283.6 | F14: =SUMIFS(monthly_work_hours!$K:$K,monthly_work_hours!$A:$A,'FTE 계산'!$A14,monthly_work_hours!$F:$F,'FTE 계산'!F$2) -> 165.9 | G14: =SUMIFS(monthly_work_hours!$K:$K,monthly_work_hours!$A:$A,'FTE 계산'!$A14,monthly_work_hours!$F:$F,'FTE 계산'!G$2) -> 151.8 | H14: =(SUMIFS(monthly_work_hours!$G:$G,monthly_work_hours!$A:$A,'FTE 계산'!$A14,monthly_work_hours!$F:$F,'FTE 계산'!H$2)) - (SUMIFS(monthly_work_hours!$J:$J,monthly_work_hours!$A:$A,'FTE 계산'!$A14,monthly_work_hours!$F:$F,'FTE 계산'!H$2)) -> 19 | I14: =(SUMIFS(monthly_work_hours!$G:$G,monthly_work_hours!$A:$A,'FTE 계산'!$A14,monthly_work_hours!$F:$F,'FTE 계산'!I$2)) - (SUMIFS(monthly_work_hours!$J:$J,monthly_work_hours!$A:$A,'FTE 계산'!$A14,monthly_work_hours!$F:$F,'FTE 계산'!I$2)) -> 16 | J14: =(SUMIFS(monthly_work_hours!$G:$G,monthly_work_hours!$A:$A,'FTE 계산'!$A14,monthly_work_hours!$F:$F,'FTE 계산'!J$2)) - (SUMIFS(monthly_work_hours!$J:$J,monthly_work_hours!$A:$A,'FTE 계산'!$A14,monthly_work_hours!$F:$F,'FTE 계산'!J$2)) -> 16 | N14: B/H사업팀 | O14: =SUMIFS($E$3:$E$503,$C$3:$C$503,$N14) -> 1191.8 | P14: =SUMIFS($E$3:$E$503,$C$3:$C$503,$N14,$D$3:$D$503,P$2) -> 329.2 | Q14: =SUMIFS($E$3:$E$503,$C$3:$C$503,$N14,$D$3:$D$503,Q$2) -> 678.7 | R14: =SUMIFS($E$3:$E$503,$C$3:$C$503,$N14,$D$3:$D$503,R$2) -> 183.9 | S14: =AVERAGEIFS($H$3:$H$503,$C$3:$C$503,$N14) -> 17.857143 | T14: =AVERAGEIFS($H$3:$H$503,$C$3:$C$503,$N14,$D$3:$D$503,P$2) -> 16.5 | U14: =AVERAGEIFS($H$3:$H$503,$C$3:$C$503,$N14,$D$3:$D$503,Q$2) -> 18.25 | V14: =AVERAGEIFS($H$3:$H$503,$C$3:$C$503,$N14,$D$3:$D$503,R$2) -> 19 | W14: =IFERROR(O14/(S14*$L$2),"-") -> 8.3426 | X14: =IFERROR(P14/(T14*$L$2),"-") -> 2.4939394 | Y14: =IFERROR(Q14/(U14*$L$2),"-") -> 4.6486301 | Z14: =IFERROR(R14/(V14*$L$2),"-") -> 1.2098684 | AA14: =SUMIFS($F$3:$F$503,$C$3:$C$503,$N14) -> 1211.4 | AB14: =SUMIFS($F$3:$F$503,$C$3:$C$503,$N14,$D$3:$D$503,P$2) -> 362 | AC14: =SUMIFS($F$3:$F$503,$C$3:$C$503,$N14,$D$3:$D$503,Q$2) -> 672.1 | AD14: =SUMIFS($F$3:$F$503,$C$3:$C$503,$N14,$D$3:$D$503,R$2) -> 177.3 | AE14: =AVERAGEIFS($I$3:$I$503,$C$3:$C$503,$N14) -> 18.142857 | AF14: =AVERAGEIFS($I$3:$I$503,$C$3:$C$503,$N14,$D$3:$D$503,P$2) -> 19 | AG14: =AVERAGEIFS($I$3:$I$503,$C$3:$C$503,$N14,$D$3:$D$503,Q$2) -> 17.5 | AH14: =AVERAGEIFS($I$3:$I$503,$C$3:$C$503,$N14,$D$3:$D$503,R$2) -> 19 | AI14: =IFERROR(AA14/(AE14*$L$2),"-") -> 8.3462598 | AJ14: =IFERROR(AB14/(AF14*$L$2),"-") -> 2.3815789 | AK14: =IFERROR(AC14/(AG14*$L$2),"-") -> 4.8007143 | AL14: =IFERROR(AD14/(AH14*$L$2),"-") -> 1.1664474 | AM14: =SUMIFS($G$3:$G$503,$C$3:$C$503,$N14) -> 1029.1 | AN14: =SUMIFS($G$3:$G$503,$C$3:$C$503,$N14,$D$3:$D$503,P$2) -> 303.4 | AO14: =SUMIFS($G$3:$G$503,$C$3:$C$503,$N14,$D$3:$D$503,Q$2) -> 579 | AP14: =SUMIFS($G$3:$G$503,$C$3:$C$503,$N14,$D$3:$D$503,R$2) -> 146.7 | AQ14: =AVERAGEIFS($J$3:$J$503,$C$3:$C$503,$N14) -> 15.571429 | AR14: =AVERAGEIFS($J$3:$J$503,$C$3:$C$503,$N14,$D$3:$D$503,P$2) -> 16 | AS14: =AVERAGEIFS($J$3:$J$503,$C$3:$C$503,$N14,$D$3:$D$503,Q$2) -> 15.25 | AT14: =AVERAGEIFS($J$3:$J$503,$C$3:$C$503,$N14,$D$3:$D$503,R$2) -> 16 | AU14: =IFERROR(AM14/(AQ14*$L$2),"-") -> 8.2611239 | AV14: =IFERROR(AN14/(AR14*$L$2),"-") -> 2.3703125 | AW14: =IFERROR(AO14/(AS14*$L$2),"-") -> 4.7459016 | AX14: =IFERROR(AP14/(AT14*$L$2),"-") -> 1.1460937
