Workbook

Sheet monthly_work_hours
A1: 사번 | B1: 성명 | C1: 소속팀 | D1: 신본부 | E1: 신조직 | F1: 직위 | G1: 년 | H1: 월 | I1: 근무일수 | J1: 총근무시간_분 | K1: 초과근무시간_분 | L1: 주말근무일수 | M1: 총근무시간 | N1: 초과근무시간 | O1: 일평균근무시간 | P1: 예상정규근무시간 | Q1: 근무시간차이
A2: 1199158 | B2: 윤상규 | C2: SL생산기술팀 (R&A) | D2: #N/A | E2: #N/A | F2: 기능주임 | G2: 2025 | H2: 6 | I2: 30 | J2: 8053 | K2: 0 | L2: 9 | M2: 134.2 | N2: 0 | O2: 4.5 | P2: 168 | Q2: -33.8
A3: 1199158 | B3: 윤상규 | C3: SL생산기술팀 (R&A) | D3: #N/A | E3: #N/A | F3: 기능주임 | G3: 2025 | H3: 7 | I3: 31 | J3: 7095 | K3: 0 | L3: 8 | M3: 118.2 | N3: 0 | O3: 3.8 | P3: 184 | Q3: -65.8
A4: 1199158 | B4: 윤상규 | C4: SL생산기술팀 (R&A) | D4: #N/A | E4: #N/A | F4: 기능주임 | G4: 2025 | H4: 8 | I4: 22 | J4: 4949 | K4: 0 | L4: 5 | M4: 82.5 | N4: 0 | O4: 3.8 | P4: 136 | Q4: -53.5
A5: 1202155 | B5: 추상민 | C5: SL운영팀 (R&A) | D5: SL사업본부 | E5: SL구매팀 | F5: 책임 | G5: 2025 | H5: 6 | I5: 1 | J5: 207 | K5: 0 | L5: 0 | M5: 3.4 | N5: 0 | O5: 3.4 | P5: 8 | Q5: -4.6
A6: 1202183 | B6: 안준철 | C6: HR팀 (R&A) | D6: HR/안전담당 | E6: HR/안전담당 | F6: 책임 | G6: 2025 | H6: 6 | I6: 20 | J6: 10677 | K6: 0 | L6: 1 | M6: 178 | N6: 0 | O6: 8.9 | P6: 152 | Q6: 26
A7: 1202183 | B7: 안준철 | C7: HR팀 (R&A) | D7: HR/안전담당 | E7: HR/안전담당 | F7: 책임 | G7: 2025 | H7: 7 | I7: 20 | J7: 10409 | K7: 0 | L7: 0 | M7: 173.5 | N7: 0 | O7: 8.7 | P7: 160 | Q7: 13.5
A8: 1202183 | B8: 안준철 | C8: HR팀 (R&A) | D8: HR/안전담당 | E8: HR/안전담당 | F8: 책임 | G8: 2025 | H8: 8 | I8: 17 | J8: 8607 | K8: 0 | L8: 1 | M8: 143.4 | N8: 0 | O8: 8.4 | P8: 128 | Q8: 15.400000000000006
A9: 1203036 | B9: 이범철 | C9: SL생산기술팀 (R&A) | D9: 기술연구본부 | E9: SL생산기술팀 | F9: 책임 | G9: 2025 | H9: 6 | I9: 18 | J9: 9663 | K9: 0 | L9: 0 | M9: 161 | N9: 0 | O9: 8.9 | P9: 144 | Q9: 17
A10: 1203036 | B10: 이범철 | C10: SL생산기술팀 (R&A) | D10: 기술연구본부 | E10: SL생산기술팀 | F10: 책임 | G10: 2025 | H10: 7 | I10: 19 | J10: 10298 | K10: 0 | L10: 0 | M10: 171.6 | N10: 0 | O10: 9 | P10: 152 | Q10: 19.599999999999994
A11: 1203036 | B11: 이범철 | C11: SL생산기술팀 (R&A) | D11: 기술연구본부 | E11: SL생산기술팀 | F11: 책임 | G11: 2025 | H11: 8 | I11: 14 | J11: 7532 | K11: 0 | L11: 0 | M11: 125.5 | N11: 0 | O11: 9 | P11: 112 | Q11: 13.5
A12: 1203052 | B12: 제용화 | C12: 구매원가팀 (R&A) | D12: 저압사업단 | E12: 구매원가팀 | F12: 책임 | G12: 2025 | H12: 6 | I12: 17 | J12: 10472 | K12: 1160 | L12: 0 | M12: 174.5 | N12: 19.3 | O12: 10.3 | P12: 136 | Q12: 38.5
A13: 1203052 | B13: 제용화 | C13: 구매원가팀 (R&A) | D13: 저압사업단 | E13: 구매원가팀 | F13: 책임 | G13: 2025 | H13: 7 | I13: 19 | J13: 11600 | K13: 1221 | L13: 0 | M13: 193.3 | N13: 20.4 | O13: 10.2 | P13: 152 | Q13: 41.30000000000001
A14: 1203052 | B14: 제용화 | C14: 구매원가팀 (R&A) | D14: 저압사업단 | E14: 구매원가팀 | F14: 책임 | G14: 2025 | H14: 8 | I14: 16 | J14: 10220 | K14: 1240 | L14: 0 | M14: 170.3 | N14: 20.7 | O14: 10.6 | P14: 128 | Q14: 42.30000000000001
A15: 1203053 | B15: 문은진 | C15: SCM팀 (R&A) | D15: SCM담당 | E15: SCM팀 | F15: 책임 | G15: 2025 | H15: 6 | I15: 17 | J15: 10225 | K15: 753 | L15: 0 | M15: 170.4 | N15: 12.6 | O15: 10 | P15: 136 | Q15: 34.400000000000006
A16: 1203053 | B16: 문은진 | C16: SCM팀 (R&A) | D16: SCM담당 | E16: SCM팀 | F16: 책임 | G16: 2025 | H16: 7 | I16: 18 | J16: 9923 | K16: 191 | L16: 0 | M16: 165.4 | N16: 3.2 | O16: 9.2 | P16: 144 | Q16: 21.400000000000006
A17: 1203053 | B17: 문은진 | C17: SCM팀 (R&A) | D17: SCM담당 | E17: SCM팀 | F17: 책임 | G17: 2025 | H17: 8 | I17: 16 | J17: 8418 | K17: 124 | L17: 0 | M17: 140.3 | N17: 2.1 | O17: 8.8 | P17: 128 | Q17: 12.300000000000011
A18: 1204003 | B18: 정용규 | C18: SL생산기술팀 (R&A) | D18: 기술연구본부 | E18: SL생산기술팀 | F18: 책임 | G18: 2025 | H18: 6 | I18: 17 | J18: 8872 | K18: 0 | L18: 0 | M18: 147.9 | N18: 0 | O18: 8.7 | P18: 136 | Q18: 11.900000000000006
A19: 1204003 | B19: 정용규 | C19: SL생산기술팀 (R&A) | D19: 기술연구본부 | E19: SL생산기술팀 | F19: 책임 | G19: 2025 | H19: 7 | I19: 19 | J19: 11481 | K19: 0 | L19: 0 | M19: 191.4 | N19: 0 | O19: 10.1 | P19: 152 | Q19: 39.400000000000006
A20: 1204003 | B20: 정용규 | C20: SL생산기술팀 (R&A) | D20: 기술연구본부 | E20: SL생산기술팀 | F20: 책임 | G20: 2025 | H20: 8 | I20: 16 | J20: 8970 | K20: 0 | L20: 0 | M20: 149.5 | N20: 0 | O20: 9.3 | P20: 128 | Q20: 21.5
A21: 1204063 | B21: 김주호 | C21: SL품질보증팀 (R&A) | D21: SL사업본부 | E21: SL품질보증팀 | F21: 책임 | G21: 2025 | H21: 6 | I21: 2 | J21: 417 | K21: 0 | L21: 0 | M21: 7 | N21: 0 | O21: 3.5 | P21: 16 | Q21: -9
A22: 1204063 | B22: 김주호 | C22: SL품질보증팀 (R&A) | D22: SL사업본부 | E22: SL품질보증팀 | F22: 책임 | G22: 2025 | H22: 7 | I22: 4 | J22: 27 | K22: 0 | L22: 0 | M22: 0.4 | N22: 0 | O22: 0.1 | P22: 32 | Q22: -31.6
A23: 1204063 | B23: 김주호 | C23: SL품질보증팀 (R&A) | D23: SL사업본부 | E23: SL품질보증팀 | F23: 책임 | G23: 2025 | H23: 8 | I23: 4 | J23: 1365 | K23: 0 | L23: 0 | M23: 22.8 | N23: 0 | O23: 5.7 | P23: 32 | Q23: -9.2
A24: 1204106 | B24: 김영준 | C24: 열관리설계팀 (R&A) | D24: 기술연구본부 | E24: 선행개발실 | F24: 책임 | G24: 2025 | H24: 6 | I24: 19 | J24: 13135 | K24: 0 | L24: 5 | M24: 218.9 | N24: 0 | O24: 11.5 | P24: 112 | Q24: 106.9
A25: 1204106 | B25: 김영준 | C25: 열관리설계팀 (R&A) | D25: 기술연구본부 | E25: 선행개발실 | F25: 책임 | G25: 2025 | H25: 7 | I25: 19 | J25: 9604 | K25: 0 | L25: 3 | M25: 160.1 | N25: 0 | O25: 8.4 | P25: 128 | Q25: 32.099999999999994
A26: 1204106 | B26: 김영준 | C26: 열관리설계팀 (R&A) | D26: 기술연구본부 | E26: 선행개발실 | F26: 책임 | G26: 2025 | H26: 8 | I26: 16 | J26: 7980 | K26: 0 | L26: 1 | M26: 133 | N26: 0 | O26: 8.3 | P26: 120 | Q26: 13
A27: 1204115 | B27: 이용재 | C27: FL생산기술팀 (R&A) | D27: 기술연구본부 | E27: FL생산기술팀 | F27: 책임 | G27: 2025 | H27: 6 | I27: 18 | J27: 10328 | K27: 0 | L27: 0 | M27: 172.1 | N27: 0 | O27: 9.6 | P27: 144 | Q27: 28.099999999999994
A28: 1204115 | B28: 이용재 | C28: FL생산기술팀 (R&A) | D28: 기술연구본부 | E28: FL생산기술팀 | F28: 책임 | G28: 2025 | H28: 7 | I28: 18 | J28: 10438 | K28: 0 | L28: 0 | M28: 174 | N28: 0 | O28: 9.7 | P28: 144 | Q28: 30
A29: 1204115 | B29: 이용재 | C29: FL생산기술팀 (R&A) | D29: 기술연구본부 | E29: FL생산기술팀 | F29: 책임 | G29: 2025 | H29: 8 | I29: 16 | J29: 8796 | K29: 0 | L29: 0 | M29: 146.6 | N29: 0 | O29: 9.2 | P29: 128 | Q29: 18.599999999999994
A30: 1205081 | B30: 이호진 | C30: SCM팀 (R&A) | D30: #N/A | E30: #N/A | F30: 기능주임 | G30: 2025 | H30: 7 | I30: 1 | J30: 0 | K30: 0 | L30: 0 | M30: 0 | N30: 0 | O30: 0 | P30: 8 | Q30: -8
A31: 1205094 | B31: 강동현 | C31: FL개발팀 (R&A) | D31: FL사업지원담당 | E31: FL개발팀 | F31: 책임 | G31: 2025 | H31: 6 | I31: 24 | J31: 17014 | K31: 507 | L31: 5 | M31: 283.6 | N31: 8.4 | O31: 11.8 | P31: 152 | Q31: 131.60000000000002
A32: 1205094 | B32: 강동현 | C32: FL개발팀 (R&A) | D32: FL사업지원담당 | E32: FL개발팀 | F32: 책임 | G32: 2025 | H32: 7 | I32: 16 | J32: 9952 | K32: 809 | L32: 0 | M32: 165.9 | N32: 13.5 | O32: 10.4 | P32: 128 | Q32: 37.900000000000006
A33: 1205094 | B33: 강동현 | C33: FL개발팀 (R&A) | D33: FL사업지원담당 | E33: FL개발팀 | F33: 책임 | G33: 2025 | H33: 8 | I33: 16 | J33: 9109 | K33: 300 | L33: 0 | M33: 151.8 | N33: 5 | O33: 9.5 | P33: 128 | Q33: 23.80000000000001
A34: 1205105 | B34: 엄중호 | C34: SL품질보증팀 (R&A) | D34: #N/A | E34: #N/A | F34: 기능주임 | G34: 2025 | H34: 6 | I34: 20 | J34: 6216 | K34: 0 | L34: 0 | M34: 103.6 | N34: 0 | O34: 5.2 | P34: 160 | Q34: -56.4
A35: 1205105 | B35: 엄중호 | C35: SL품질보증팀 (R&A) | D35: #N/A | E35: #N/A | F35: 기능주임 | G35: 2025 | H35: 7 | I35: 20 | J35: 5741 | K35: 0 | L35: 1 | M35: 95.7 | N35: 0 | O35: 4.8 | P35: 152 | Q35: -56.3
A36: 1205105 | B36: 엄중호 | C36: SL품질보증팀 (R&A) | D36: #N/A | E36: #N/A | F36: 기능주임 | G36: 2025 | H36: 8 | I36: 19 | J36: 5870 | K36: 0 | L36: 2 | M36: 97.8 | N36: 0 | O36: 5.1 | P36: 136 | Q36: -38.2
A37: 1205115 | B37: 김욱진 | C37: SL생산기술팀 (R&A) | D37: 기술연구본부 | E37: SL생산기술팀 | F37: 책임 | G37: 2025 | H37: 6 | I37: 17 | J37: 9894 | K37: 0 | L37: 0 | M37: 164.9 | N37: 0 | O37: 9.7 | P37: 136 | Q37: 28.900000000000006
A38: 1205115 | B38: 김욱진 | C38: SL생산기술팀 (R&A) | D38: 기술연구본부 | E38: SL생산기술팀 | F38: 책임 | G38: 2025 | H38: 7 | I38: 17 | J38: 9977 | K38: 0 | L38: 0 | M38: 166.3 | N38: 0 | O38: 9.8 | P38: 136 | Q38: 30.30000000000001
A39: 1205115 | B39: 김욱진 | C39: SL생산기술팀 (R&A) | D39: 기술연구본부 | E39: SL생산기술팀 | F39: 책임 | G39: 2025 | H39: 8 | I39: 13 | J39: 7204 | K39: 0 | L39: 0 | M39: 120.1 | N39: 0 | O39: 9.2 | P39: 104 | Q39: 16.099999999999994
A40: 1206003 | B40: 김동건 | C40: FL개발팀 (R&A) | D40: FL사업지원담당 | E40: FL개발팀 | F40: 책임 | G40: 2025 | H40: 6 | I40: 21 | J40: 12328 | K40: 1716 | L40: 3 | M40: 205.5 | N40: 28.6 | O40: 9.8 | P40: 144 | Q40: 61.5
...

Sheet FTE 정리
B1: 평균 FTE (6월 ~ 8월) | F1: 현재 인원수 | J1: FTE/인원수
A2: 팀 | B2: 전체 | C2: 책임 | D2: 선임 | E2: 사원 | F2: 전체 | G2: 책임 | H2: 선임 | I2: 사원 | J2: 전체 | K2: 책임 | L2: 선임 | M2: 사원
A3: SL구매팀 | B3: =AVERAGE('FTE 계산'!W3,'FTE 계산'!AI3,'FTE 계산'!AU3) -> 15.654036 | C3: =AVERAGE('FTE 계산'!X3,'FTE 계산'!AJ3,'FTE 계산'!AV3) -> 7.3088301 | D3: =AVERAGE('FTE 계산'!Y3,'FTE 계산'!AK3,'FTE 계산'!AW3) -> 6.0979965 | E3: =AVERAGE('FTE 계산'!Z3,'FTE 계산'!AL3,'FTE 계산'!AX3) -> 2.3836806 | F3: =_xlfn.XLOOKUP($A3,'실제 인원'!$A:$A,'실제 인원'!B:B) -> 12 | G3: =_xlfn.XLOOKUP($A3,'실제 인원'!$A:$A,'실제 인원'!C:C) -> 5 | H3: =_xlfn.XLOOKUP($A3,'실제 인원'!$A:$A,'실제 인원'!D:D) -> 5 | I3: =_xlfn.XLOOKUP($A3,'실제 인원'!$A:$A,'실제 인원'!E:E) -> 2 | J3: =B3/F3 -> 1.304503 | K3: =C3/G3 -> 1.461766 | L3: =D3/H3 -> 1.2195993 | M3: =E3/I3 -> 1.1918403
A4: SL생산기술팀 | B4: =AVERAGE('FTE 계산'!W4,'FTE 계산'!AI4,'FTE 계산'!AU4) -> 8.8760626 | C4: =AVERAGE('FTE 계산'!X4,'FTE 계산'!AJ4,'FTE 계산'!AV4) -> 5.8714239 | D4: =AVERAGE('FTE 계산'!Y4,'FTE 계산'!AK4,'FTE 계산'!AW4) -> 2.0141762 | E4: =AVERAGE('FTE 계산'!Z4,'FTE 계산'!AL4,'FTE 계산'!AX4) -> 0.74734375 | F4: =_xlfn.XLOOKUP($A4,'실제 인원'!$A:$A,'실제 인원'!B:B) -> 10 | G4: =_xlfn.XLOOKUP($A4,'실제 인원'!$A:$A,'실제 인원'!C:C) -> 5 | H4: =_xlfn.XLOOKUP($A4,'실제 인원'!$A:$A,'실제 인원'!D:D) -> 2 | I4: =_xlfn.XLOOKUP($A4,'실제 인원'!$A:$A,'실제 인원'!E:E) -> 3 | J4: =B4/F4 -> 0.88760626 | K4: =C4/G4 -> 1.1742848 | L4: =D4/H4 -> 1.0070881 | M4: =E4/I4 -> 0.24911458
A5: 구매원가팀 | B5: =AVERAGE('FTE 계산'!W5,'FTE 계산'!AI5,'FTE 계산'!AU5) -> 7.6317259 | C5: =AVERAGE('FTE 계산'!X5,'FTE 계산'!AJ5,'FTE 계산'!AV5) -> 2.5589117 | D5: =AVERAGE('FTE 계산'!Y5,'FTE 계산'!AK5,'FTE 계산'!AW5) -> 2.5706889 | E5: =AVERAGE('FTE 계산'!Z5,'FTE 계산'!AL5,'FTE 계산'!AX5) -> 2.5036064 | F5: =_xlfn.XLOOKUP($A5,'실제 인원'!$A:$A,'실제 인원'!B:B) -> 6 | G5: =_xlfn.XLOOKUP($A5,'실제 인원'!$A:$A,'실제 인원'!C:C) -> 2 | H5: =_xlfn.XLOOKUP($A5,'실제 인원'!$A:$A,'실제 인원'!D:D) -> 2 | I5: =_xlfn.XLOOKUP($A5,'실제 인원'!$A:$A,'실제 인원'!E:E) -> 2 | J5: =B5/F5 -> 1.2719543 | K5: =C5/G5 -> 1.2794559 | L5: =D5/H5 -> 1.2853445 | M5: =E5/I5 -> 1.2518032
A6: SCM팀 | B6: =AVERAGE('FTE 계산'!W6,'FTE 계산'!AI6,'FTE 계산'!AU6) -> 14.314588 | C6: =AVERAGE('FTE 계산'!X6,'FTE 계산'!AJ6,'FTE 계산'!AV6) -> 4.8307175 | D6: =AVERAGE('FTE 계산'!Y6,'FTE 계산'!AK6,'FTE 계산'!AW6) -> 4.7317786 | E6: =AVERAGE('FTE 계산'!Z6,'FTE 계산'!AL6,'FTE 계산'!AX6) -> 4.7387856 | F6: =_xlfn.XLOOKUP($A6,'실제 인원'!$A:$A,'실제 인원'!B:B) -> 12 | G6: =_xlfn.XLOOKUP($A6,'실제 인원'!$A:$A,'실제 인원'!C:C) -> 4 | H6: =_xlfn.XLOOKUP($A6,'실제 인원'!$A:$A,'실제 인원'!D:D) -> 4 | I6: =_xlfn.XLOOKUP($A6,'실제 인원'!$A:$A,'실제 인원'!E:E) -> 4 | J6: =B6/F6 -> 1.1928823 | K6: =C6/G6 -> 1.2076794 | L6: =D6/H6 -> 1.1829447 | M6: =E6/I6 -> 1.1846964
A7: SL품질보증팀 | B7: =AVERAGE('FTE 계산'!W7,'FTE 계산'!AI7,'FTE 계산'!AU7) -> 14.288513 | C7: =AVERAGE('FTE 계산'!X7,'FTE 계산'!AJ7,'FTE 계산'!AV7) -> 3.3280902 | D7: =AVERAGE('FTE 계산'!Y7,'FTE 계산'!AK7,'FTE 계산'!AW7) -> 7.6721886 | E7: =AVERAGE('FTE 계산'!Z7,'FTE 계산'!AL7,'FTE 계산'!AX7) -> 3.2577988 | F7: =_xlfn.XLOOKUP($A7,'실제 인원'!$A:$A,'실제 인원'!B:B) -> 14 | G7: =_xlfn.XLOOKUP($A7,'실제 인원'!$A:$A,'실제 인원'!C:C) -> 3 | H7: =_xlfn.XLOOKUP($A7,'실제 인원'!$A:$A,'실제 인원'!D:D) -> 8 | I7: =_xlfn.XLOOKUP($A7,'실제 인원'!$A:$A,'실제 인원'!E:E) -> 2 | J7: =B7/F7 -> 1.0206081 | K7: =C7/G7 -> 1.1093634 | L7: =D7/H7 -> 0.95902357 | M7: =E7/I7 -> 1.6288994
A8: FL생산기술팀 | B8: =AVERAGE('FTE 계산'!W8,'FTE 계산'!AI8,'FTE 계산'!AU8) -> 3.7295446 | C8: =AVERAGE('FTE 계산'!X8,'FTE 계산'!AJ8,'FTE 계산'!AV8) -> 1.1829282 | D8: =AVERAGE('FTE 계산'!Y8,'FTE 계산'!AK8,'FTE 계산'!AW8) -> #DIV/0! | E8: =AVERAGE('FTE 계산'!Z8,'FTE 계산'!AL8,'FTE 계산'!AX8) -> 2.5462753 | F8: =_xlfn.XLOOKUP($A8,'실제 인원'!$A:$A,'실제 인원'!B:B) -> 5 | G8: =_xlfn.XLOOKUP($A8,'실제 인원'!$A:$A,'실제 인원'!C:C) -> 1 | H8: =_xlfn.XLOOKUP($A8,'실제 인원'!$A:$A,'실제 인원'!D:D) -> 2 | I8: =_xlfn.XLOOKUP($A8,'실제 인원'!$A:$A,'실제 인원'!E:E) -> 2 | J8: =B8/F8 -> 0.74590892 | K8: =C8/G8 -> 1.1829282 | L8: =D8/H8 -> #DIV/0! | M8: =E8/I8 -> 1.2731376
A9: FL개발팀 | B9: =AVERAGE('FTE 계산'!W9,'FTE 계산'!AI9,'FTE 계산'!AU9) -> 16.754095 | C9: =AVERAGE('FTE 계산'!X9,'FTE 계산'!AJ9,'FTE 계산'!AV9) -> 3.9853009 | D9: =AVERAGE('FTE 계산'!Y9,'FTE 계산'!AK9,'FTE 계산'!AW9) -> 8.289793 | E9: =AVERAGE('FTE 계산'!Z9,'FTE 계산'!AL9,'FTE 계산'!AX9) -> 4.3588348 | F9: =_xlfn.XLOOKUP($A9,'실제 인원'!$A:$A,'실제 인원'!B:B) -> 14 | G9: =_xlfn.XLOOKUP($A9,'실제 인원'!$A:$A,'실제 인원'!C:C) -> 3 | H9: =_xlfn.XLOOKUP($A9,'실제 인원'!$A:$A,'실제 인원'!D:D) -> 7 | I9: =_xlfn.XLOOKUP($A9,'실제 인원'!$A:$A,'실제 인원'!E:E) -> 3 | J9: =B9/F9 -> 1.1967211 | K9: =C9/G9 -> 1.3284336 | L9: =D9/H9 -> 1.1842561 | M9: =E9/I9 -> 1.4529449
A10: 선행개발팀 | B10: =AVERAGE('FTE 계산'!W10,'FTE 계산'!AI10,'FTE 계산'!AU10) -> 7.911807 | C10: =AVERAGE('FTE 계산'!X10,'FTE 계산'!AJ10,'FTE 계산'!AV10) -> 2.1366356 | D10: =AVERAGE('FTE 계산'!Y10,'FTE 계산'!AK10,'FTE 계산'!AW10) -> 4.7495001 | E10: =AVERAGE('FTE 계산'!Z10,'FTE 계산'!AL10,'FTE 계산'!AX10) -> 1.0725797 | F10: =_xlfn.XLOOKUP($A10,'실제 인원'!$A:$A,'실제 인원'!B:B) -> 8 | G10: =_xlfn.XLOOKUP($A10,'실제 인원'!$A:$A,'실제 인원'!C:C) -> 2 | H10: =_xlfn.XLOOKUP($A10,'실제 인원'!$A:$A,'실제 인원'!D:D) -> 4 | I10: =_xlfn.XLOOKUP($A10,'실제 인원'!$A:$A,'실제 인원'!E:E) -> 2 | J10: =B10/F10 -> 0.98897587 | K10: =C10/G10 -> 1.0683178 | L10: =D10/H10 -> 1.187375 | M10: =E10/I10 -> 0.53628983
A11: FL설계팀 | B11: =AVERAGE('FTE 계산'!W11,'FTE 계산'!AI11,'FTE 계산'!AU11) -> 22.162766 | C11: =AVERAGE('FTE 계산'!X11,'FTE 계산'!AJ11,'FTE 계산'!AV11) -> 3.2168949 | D11: =AVERAGE('FTE 계산'!Y11,'FTE 계산'!AK11,'FTE 계산'!AW11) -> 5.54711 | E11: =AVERAGE('FTE 계산'!Z11,'FTE 계산'!AL11,'FTE 계산'!AX11) -> 12.940137 | F11: =_xlfn.XLOOKUP($A11,'실제 인원'!$A:$A,'실제 인원'!B:B) -> 14 | G11: =_xlfn.XLOOKUP($A11,'실제 인원'!$A:$A,'실제 인원'!C:C) -> 2 | H11: =_xlfn.XLOOKUP($A11,'실제 인원'!$A:$A,'실제 인원'!D:D) -> 4 | I11: =_xlfn.XLOOKUP($A11,'실제 인원'!$A:$A,'실제 인원'!E:E) -> 6 | J11: =B11/F11 -> 1.5830547 | K11: =C11/G11 -> 1.6084474 | L11: =D11/H11 -> 1.3867775 | M11: =E11/I11 -> 2.1566895
A12: 품질경영팀 | B12: =AVERAGE('FTE 계산'!W12,'FTE 계산'!AI12,'FTE 계산'!AU12) -> 7.8791181 | C12: =AVERAGE('FTE 계산'!X12,'FTE 계산'!AJ12,'FTE 계산'!AV12) -> 2.2866304 | D12: =AVERAGE('FTE 계산'!Y12,'FTE 계산'!AK12,'FTE 계산'!AW12) -> 4.4584874 | E12: =AVERAGE('FTE 계산'!Z12,'FTE 계산'!AL12,'FTE 계산'!AX12) -> 1.1352056 | F12: =_xlfn.XLOOKUP($A12,'실제 인원'!$A:$A,'실제 인원'!B:B) -> 7 | G12: =_xlfn.XLOOKUP($A12,'실제 인원'!$A:$A,'실제 인원'!C:C) -> 2 | H12: =_xlfn.XLOOKUP($A12,'실제 인원'!$A:$A,'실제 인원'!D:D) -> 4 | I12: =_xlfn.XLOOKUP($A12,'실제 인원'!$A:$A,'실제 인원'!E:E) -> 1 | J12: =B12/F12 -> 1.1255883 | K12: =C12/G12 -> 1.1433152 | L12: =D12/H12 -> 1.1146218 | M12: =E12/I12 -> 1.1352056
A13: B/H사업팀 | B13: =AVERAGE('FTE 계산'!W13,'FTE 계산'!AI13,'FTE 계산'!AU13) -> 8.3166612 | C13: =AVERAGE('FTE 계산'!X13,'FTE 계산'!AJ13,'FTE 계산'!AV13) -> 2.4152769 | D13: =AVERAGE('FTE 계산'!Y13,'FTE 계산'!AK13,'FTE 계산'!AW13) -> 4.7317487 | E13: =AVERAGE('FTE 계산'!Z13,'FTE 계산'!AL13,'FTE 계산'!AX13) -> 1.1741365 | F13: =_xlfn.XLOOKUP($A13,'실제 인원'!$A:$A,'실제 인원'!B:B) -> 6 | G13: =_xlfn.XLOOKUP($A13,'실제 인원'!$A:$A,'실제 인원'!C:C) -> 2 | H13: =_xlfn.XLOOKUP($A13,'실제 인원'!$A:$A,'실제 인원'!D:D) -> 4 | I13: =_xlfn.XLOOKUP($A13,'실제 인원'!$A:$A,'실제 인원'!E:E) -> 0 | J13: =B13/F13 -> 1.3861102 | K13: =C13/G13 -> 1.2076385 | L13: =D13/H13 -> 1.1829372 | M13: =E13/I13 -> #DIV/0!
A14: 관체사업팀 | B14: =AVERAGE('FTE 계산'!W14,'FTE 계산'!AI14,'FTE 계산'!AU14) -> 15.676961 | C14: =AVERAGE('FTE 계산'!X14,'FTE 계산'!AJ14,'FTE 계산'!AV14) -> 5.1937983 | D14: =AVERAGE('FTE 계산'!Y14,'FTE 계산'!AK14,'FTE 계산'!AW14) -> 9.358411 | E14: =AVERAGE('FTE 계산'!Z14,'FTE 계산'!AL14,'FTE 계산'!AX14) -> 1.1277665 | F14: =_xlfn.XLOOKUP($A14,'실제 인원'!$A:$A,'실제 인원'!B:B) -> 11 | G14: =_xlfn.XLOOKUP($A14,'실제 인원'!$A:$A,'실제 인원'!C:C) -> 4 | H14: =_xlfn.XLOOKUP($A14,'실제 인원'!$A:$A,'실제 인원'!D:D) -> 6 | I14: =_xlfn.XLOOKUP($A14,'실제 인원'!$A:$A,'실제 인원'!E:E) -> 1 | J14: =B14/F14 -> 1.4251782 | K14: =C14/G14 -> 1.2984496 | L14: =D14/H14 -> 1.5597352 | M14: =E14/I14 -> 1.1277665
... A33: SL상생협력팀 | B33: =AVERAGE('FTE 계산'!W33,'FTE 계산'!AI33,'FTE 계산'!AU33) -> 1.1381587 | C33: =AVERAGE('FTE 계산'!X33,'FTE 계산'!AJ33,'FTE 계산'!AV33) -> #DIV/0! | D33: =AVERAGE('FTE 계산'!Y33,'FTE 계산'!AK33,'FTE 계산'!AW33) -> #DIV/0! | E33: =AVERAGE('FTE 계산'!Z33,'FTE 계산'!AL33,'FTE 계산'!AX33) -> 1.1381587 | F33: =_xlfn.XLOOKUP($A33,'실제 인원'!$A:$A,'실제 인원'!B:B) -> 0 | G33: =_xlfn.XLOOKUP($A33,'실제 인원'!$A:$A,'실제 인원'!C:C) -> 0 | H33: =_xlfn.XLOOKUP($A33,'실제 인원'!$A:$A,'실제 인원'!D:D) -> 0 | I33: =_xlfn.XLOOKUP($A33,'실제 인원'!$A:$A,'실제 인원'!E:E) -> 0 | J33: =B33/F33 -> #DIV/0! | K33: =C33/G33 -> #DIV/0! | L33: =D33/H33 -> #DIV/0! | M33: =E33/I33 -> #DIV/0!

Sheet FTE 계산
E1: 근무시간 | H1: 정규근무일수 | L1: 기준근무시간 | O1: 6월 총근무시간 | S1: 6월 평균근무일수 | W1: 6월 FTE | AA1: 7월 총근무시간 | AE1: 7월 평균근무일수 | AI1: 7월 FTE | AM1: 8월 총근무시간 | AQ1: 8월 평균근무일수 | AU1: 8월 FTE
A2: 사번 | B2: 이름 | C2: 팀 | D2: 직급 | E2: 6 | F2: 7 | G2: 8 | H2: 6 | I2: 7 | J2: 8 | L2: 8 | N2: 팀 | O2: 전체 | P2: 책임 | Q2: 선임 | R2: 사원 | S2: 전체 | T2: 책임 | U2: 선임 | V2: 사원 | W2: 전체 | X2: 책임 | Y2: 선임 | Z2: 사원 | AA2: 전체 | AB2: 책임 | AC2: 선임 | AD2: 사원 | AE2: 전체 | AF2: 책임 | AG2: 선임 | AH2: 사원 | AI2: 전체 | AJ2: 책임 | AK2: 선임 | AL2: 사원 | AM2: 전체 | AN2: 책임 | AO2: 선임 | AP2: 사원 | AQ2: 전체 | AR2: 책임 | AS2: 선임 | AT2: 사원 | AU2: 전체 | AV2: 책임 | AW2: 선임 | AX2: 사원
A3: {=_xlfn.UNIQUE(monthly_work_hours!A2:A726)} -> 1199158 | B3: =_xlfn.XLOOKUP(A3,monthly_work_hours!A:A,monthly_work_hours!B:B) -> 윤상규 | C3: =_xlfn.XLOOKUP(A3,monthly_work_hours!A:A,monthly_work_hours!E:E) -> #N/A | D3: =_xlfn.XLOOKUP(A3,monthly_work_hours!A:A,monthly_work_hours!F:F) -> 기능주임 | E3: =SUMIFS(monthly_work_hours!$M:$M,monthly_work_hours!$A:$A,'FTE 계산'!$A3,monthly_work_hours!$H:$H,'FTE 계산'!E$2) -> 134.2 | F3: =SUMIFS(monthly_work_hours!$M:$M,monthly_work_hours!$A:$A,'FTE 계산'!$A3,monthly_work_hours!$H:$H,'FTE 계산'!F$2) -> 118.2 | G3: =SUMIFS(monthly_work_hours!$M:$M,monthly_work_hours!$A:$A,'FTE 계산'!$A3,monthly_work_hours!$H:$H,'FTE 계산'!G$2) -> 82.5 | H3: =(SUMIFS(monthly_work_hours!$I:$I,monthly_work_hours!$A:$A,'FTE 계산'!$A3,monthly_work_hours!$H:$H,'FTE 계산'!H$2)) - (SUMIFS(monthly_work_hours!$L:$L,monthly_work_hours!$A:$A,'FTE 계산'!$A3,monthly_work_hours!$H:$H,'FTE 계산'!H$2)) -> 21 | I3: =(SUMIFS(monthly_work_hours!$I:$I,monthly_work_hours!$A:$A,'FTE 계산'!$A3,monthly_work_hours!$H:$H,'FTE 계산'!I$2)) - (SUMIFS(monthly_work_hours!$L:$L,monthly_work_hours!$A:$A,'FTE 계산'!$A3,monthly_work_hours!$H:$H,'FTE 계산'!I$2)) -> 23 | J3: =(SUMIFS(monthly_work_hours!$I:$I,monthly_work_hours!$A:$A,'FTE 계산'!$A3,monthly_work_hours!$H:$H,'FTE 계산'!J$2)) - (SUMIFS(monthly_work_hours!$L:$L,monthly_work_hours!$A:$A,'FTE 계산'!$A3,monthly_work_hours!$H:$H,'FTE 계산'!J$2)) -> 17 | N3: SL구매팀 | O3: =SUMIFS($E$3:$E$253,$C$3:$C$253,$N3) -> 2136.7 | P3: =SUMIFS($E$3:$E$253,$C$3:$C$253,$N3,$D$3:$D$253,P$2) -> 943.1 | Q3: =SUMIFS($E$3:$E$253,$C$3:$C$253,$N3,$D$3:$D$253,Q$2) -> 853.6 | R3: =SUMIFS($E$3:$E$253,$C$3:$C$253,$N3,$D$3:$D$253,R$2) -> 340 | S3: =AVERAGEIFS($H$3:$H$253,$C$3:$C$253,$N3) -> 16 | T3: =AVERAGEIFS($H$3:$H$253,$C$3:$C$253,$N3,$D$3:$D$253,P$2) -> 14.2 | U3: =AVERAGEIFS($H$3:$H$253,$C$3:$C$253,$N3,$D$3:$D$253,Q$2) -> 17.4 | V3: =AVERAGEIFS($H$3:$H$253,$C$3:$C$253,$N3,$D$3:$D$253,R$2) -> 17 | W3: =IFERROR(O3/(S3*$L$2),"-") -> 16.692969 | X3: =IFERROR(P3/(T3*$L$2),"-") -> 8.3019366 | Y3: =IFERROR(Q3/(U3*$L$2),"-") -> 6.1321839 | Z3: =IFERROR(R3/(V3*$L$2),"-") -> 2.5 | AA3: =SUMIFS($F$3:$F$253,$C$3:$C$253,$N3) -> 1829.4 | AB3: =SUMIFS($F$3:$F$253,$C$3:$C$253,$N3,$D$3:$D$253,P$2) -> 737.4 | AC3: =SUMIFS($F$3:$F$253,$C$3:$C$253,$N3,$D$3:$D$253,Q$2) -> 783.6 | AD3: =SUMIFS($F$3:$F$253,$C$3:$C$253,$N3,$D$3:$D$253,R$2) -> 308.4 | AE3: =AVERAGEIFS($I$3:$I$253,$C$3:$C$253,$N3) -> 15.166667 | AF3: =AVERAGEIFS($I$3:$I$253,$C$3:$C$253,$N3,$D$3:$D$253,P$2) -> 14 | AG3: =AVERAGEIFS($I$3:$I$253,$C$3:$C$253,$N3,$D$3:$D$253,Q$2) -> 16 | AH3: =AVERAGEIFS($I$3:$I$253,$C$3:$C$253,$N3,$D$3:$D$253,R$2) -> 16 | AI3: =IFERROR(AA3/(AE3*$L$2),"-") -> 15.077473 | AJ3: =IFERROR(AB3/(AF3*$L$2),"-") -> 6.5839286 | AK3: =IFERROR(AC3/(AG3*$L$2),"-") -> 6.121875 | AL3: =IFERROR(AD3/(AH3*$L$2),"-") -> 2.409375 | AM3: =SUMIFS($G$3:$G$253,$C$3:$C$253,$N3) -> 1640.7 | AN3: =SUMIFS($G$3:$G$253,$C$3:$C$253,$N3,$D$3:$D$253,P$2) -> 675.9 | AO3: =SUMIFS($G$3:$G$253,$C$3:$C$253,$N3,$D$3:$D$253,Q$2) -> 695.8 | AP3: =SUMIFS($G$3:$G$253,$C$3:$C$253,$N3,$D$3:$D$253,R$2) -> 269 | AQ3: =AVERAGEIFS($J$3:$J$253,$C$3:$C$253,$N3) -> 13.5 | AR3: =AVERAGEIFS($J$3:$J$253,$C$3:$C$253,$N3,$D$3:$D$253,P$2) -> 12 | AS3: =AVERAGEIFS($J$3:$J$253,$C$3:$C$253,$N3,$D$3:$D$253,Q$2) -> 14.4 | AT3: =AVERAGEIFS($J$3:$J$253,$C$3:$C$253,$N3,$D$3:$D$253,R$2) -> 15 | AU3: =IFERROR(AM3/(AQ3*$L$2),"-") -> 15.191667 | AV3: =IFERROR(AN3/(AR3*$L$2),"-") -> 7.040625 | AW3: =IFERROR(AO3/(AS3*$L$2),"-") -> 6.0399306 | AX3: =IFERROR(AP3/(AT3*$L$2),"-") -> 2.2416667
A4: 1202155 | B4: =_xlfn.XLOOKUP(A4,monthly_work_hours!A:A,monthly_work_hours!B:B) -> 추상민 | C4: =_xlfn.XLOOKUP(A4,monthly_work_hours!A:A,monthly_work_hours!E:E) -> SL구매팀 | D4: =_xlfn.XLOOKUP(A4,monthly_work_hours!A:A,monthly_work_hours!F:F) -> 책임 | E4: =SUMIFS(monthly_work_hours!$M:$M,monthly_work_hours!$A:$A,'FTE 계산'!$A4,monthly_work_hours!$H:$H,'FTE 계산'!E$2) -> 3.4 | F4: =SUMIFS(monthly_work_hours!$M:$M,monthly_work_hours!$A:$A,'FTE 계산'!$A4,monthly_work_hours!$H:$H,'FTE 계산'!F$2) -> 0 | G4: =SUMIFS(monthly_work_hours!$M:$M,monthly_work_hours!$A:$A,'FTE 계산'!$A4,monthly_work_hours!$H:$H,'FTE 계산'!G$2) -> 0 | H4: =(SUMIFS(monthly_work_hours!$I:$I,monthly_work_hours!$A:$A,'FTE 계산'!$A4,monthly_work_hours!$H:$H,'FTE 계산'!H$2)) - (SUMIFS(monthly_work_hours!$L:$L,monthly_work_hours!$A:$A,'FTE 계산'!$A4,monthly_work_hours!$H:$H,'FTE 계산'!H$2)) -> 1 | I4: =(SUMIFS(monthly_work_hours!$I:$I,monthly_work_hours!$A:$A,'FTE 계산'!$A4,monthly_work_hours!$H:$H,'FTE 계산'!I$2)) - (SUMIFS(monthly_work_hours!$L:$L,monthly_work_hours!$A:$A,'FTE 계산'!$A4,monthly_work_hours!$H:$H,'FTE 계산'!I$2)) -> 0 | J4: =(SUMIFS(monthly_work_hours!$I:$I,monthly_work_hours!$A:$A,'FTE 계산'!$A4,monthly_work_hours!$H:$H,'FTE 계산'!J$2)) - (SUMIFS(monthly_work_hours!$L:$L,monthly_work_hours!$A:$A,'FTE 계산'!$A4,monthly_work_hours!$H:$H,'FTE 계산'!J$2)) -> 0 | N4: SL생산기술팀 | O4: =SUMIFS($E$3:$E$253,$C$3:$C$253,$N4) -> 1114.2 | P4: =SUMIFS($E$3:$E$253,$C$3:$C$253,$N4,$D$3:$D$253,P$2) -> 804 | Q4: =SUMIFS($E$3:$E$253,$C$3:$C$253,$N4,$D$3:$D$253,Q$2) -> 256 | R4: =SUMIFS($E$3:$E$253,$C$3:$C$253,$N4,$D$3:$D$253,R$2) -> 54.2 | S4: =AVERAGEIFS($H$3:$H$253,$C$3:$C$253,$N4) -> 16 | T4: =AVERAGEIFS($H$3:$H$253,$C$3:$C$253,$N4,$D$3:$D$253,P$2) -> 17.2 | U4: =AVERAGEIFS($H$3:$H$253,$C$3:$C$253,$N4,$D$3:$D$253,Q$2) -> 16 | V4: =AVERAGEIFS($H$3:$H$253,$C$3:$C$253,$N4,$D$3:$D$253,R$2) -> 10 | W4: =IFERROR(O4/(S4*$L$2),"-") -> 8.7046875 | X4: =IFERROR(P4/(T4*$L$2),"-") -> 5.8430233 | Y4: =IFERROR(Q4/(U4*$L$2),"-") -> 2 | Z4: =IFERROR(R4/(V4*$L$2),"-") -> 0.6775 | AA4: =SUMIFS($F$3:$F$253,$C$3:$C$253,$N4) -> 1227.6 | AB4: =SUMIFS($F$3:$F$253,$C$3:$C$253,$N4,$D$3:$D$253,P$2) -> 888.5 | AC4: =SUMIFS($F$3:$F$253,$C$3:$C$253,$N4,$D$3:$D$253,Q$2) -> 286.8 | AD4: =SUMIFS($F$3:$F$253,$C$3:$C$253,$N4,$D$3:$D$253,R$2) -> 52.3 | AE4: =AVERAGEIFS($I$3:$I$253,$C$3:$C$253,$N4) -> 17 | AF4: =AVERAGEIFS($I$3:$I$253,$C$3:$C$253,$N4,$D$3:$D$253,P$2) -> 18.4 | AG4: =AVERAGEIFS($I$3:$I$253,$C$3:$C$253,$N4,$D$3:$D$253,Q$2) -> 18 | AH4: =AVERAGEIFS($I$3:$I$253,$C$3:$C$253,$N4,$D$3:$D$253,R$2) -> 8 | AI4: =IFERROR(AA4/(AE4*$L$2),"-") -> 9.0264706 | AJ4: =IFERROR(AB4/(AF4*$L$2),"-") -> 6.0360054 | AK4: =IFERROR(AC4/(AG4*$L$2),"-") -> 1.9916667 | AL4: =IFERROR(AD4/(AH4*$L$2),"-") -> 0.8171875 | AM4: =SUMIFS($G$3:$G$253,$C$3:$C$253,$N4) -> 898.6 | AN4: =SUMIFS($G$3:$G$253,$C$3:$C$253,$N4,$D$3:$D$253,P$2) -> 660.7 | AO4: =SUMIFS($G$3:$G$253,$C$3:$C$253,$N4,$D$3:$D$253,Q$2) -> 237.9 | AP4: =SUMIFS($G$3:$G$253,$C$3:$C$253,$N4,$D$3:$D$253,R$2) -> 0 | AQ4: =AVERAGEIFS($J$3:$J$253,$C$3:$C$253,$N4) -> 12.625 | AR4: =AVERAGEIFS($J$3:$J$253,$C$3:$C$253,$N4,$D$3:$D$253,P$2) -> 14.4 | AS4: =AVERAGEIFS($J$3:$J$253,$C$3:$C$253,$N4,$D$3:$D$253,Q$2) -> 14.5 | AT4: =AVERAGEIFS($J$3:$J$253,$C$3:$C$253,$N4,$D$3:$D$253,R$2) -> 0 | AU4: =IFERROR(AM4/(AQ4*$L$2),"-") -> 8.8970297 | AV4: =IFERROR(AN4/(AR4*$L$2),"-") -> 5.7352431 | AW4: =IFERROR(AO4/(AS4*$L$2),"-") -> 2.0508621 | AX4: =IFERROR(AP4/(AT4*$L$2),"-") -> -
A5: 1202183 | B5: =_xlfn.XLOOKUP(A5,monthly_work_hours!A:A,monthly_work_hours!B:B) -> 안준철 | C5: =_xlfn.XLOOKUP(A5,monthly_work_hours!A:A,monthly_work_hours!E:E) -> HR/안전담당 | D5: =_xlfn.XLOOKUP(A5,monthly_work_hours!A:A,monthly_work_hours!F:F) -> 책임 | E5: =SUMIFS(monthly_work_hours!$M:$M,monthly_work_hours!$A:$A,'FTE 계산'!$A5,monthly_work_hours!$H:$H,'FTE 계산'!E$2) -> 178 | F5: =SUMIFS(monthly_work_hours!$M:$M,monthly_work_hours!$A:$A,'FTE 계산'!$A5,monthly_work_hours!$H:$H,'FTE 계산'!F$2) -> 173.5 | G5: =SUMIFS(monthly_work_hours!$M:$M,monthly_work_hours!$A:$A,'FTE 계산'!$A5,monthly_work_hours!$H:$H,'FTE 계산'!G$2) -> 143.4 | H5: =(SUMIFS(monthly_work_hours!$I:$I,monthly_work_hours!$A:$A,'FTE 계산'!$A5,monthly_work_hours!$H:$H,'FTE 계산'!H$2)) - (SUMIFS(monthly_work_hours!$L:$L,monthly_work_hours!$A:$A,'FTE 계산'!$A5,monthly_work_hours!$H:$H,'FTE 계산'!H$2)) -> 19 | I5: =(SUMIFS(monthly_work_hours!$I:$I,monthly_work_hours!$A:$A,'FTE 계산'!$A5,monthly_work_hours!$H:$H,'FTE 계산'!I$2)) - (SUMIFS(monthly_work_hours!$L:$L,monthly_work_hours!$A:$A,'FTE 계산'!$A5,monthly_work_hours!$H:$H,'FTE 계산'!I$2)) -> 20 | J5: =(SUMIFS(monthly_work_hours!$I:$I,monthly_work_hours!$A:$A,'FTE 계산'!$A5,monthly_work_hours!$H:$H,'FTE 계산'!J$2)) - (SUMIFS(monthly_work_hours!$L:$L,monthly_work_hours!$A:$A,'FTE 계산'!$A5,monthly_work_hours!$H:$H,'FTE 계산'!J$2)) -> 16 | N5: 구매원가팀 | O5: =SUMIFS($E$3:$E$253,$C$3:$C$253,$N5) -> 1078.5 | P5: =SUMIFS($E$3:$E$253,$C$3:$C$253,$N5,$D$3:$D$253,P$2) -> 361.9 | Q5: =SUMIFS($E$3:$E$253,$C$3:$C$253,$N5,$D$3:$D$253,Q$2) -> 358.7 | R5: =SUMIFS($E$3:$E$253,$C$3:$C$253,$N5,$D$3:$D$253,R$2) -> 357.9 | S5: =AVERAGEIFS($H$3:$H$253,$C$3:$C$253,$N5) -> 17.5 | T5: =AVERAGEIFS($H$3:$H$253,$C$3:$C$253,$N5,$D$3:$D$253,P$2) -> 17.5 | U5: =AVERAGEIFS($H$3:$H$253,$C$3:$C$253,$N5,$D$3:$D$253,Q$2) -> 17.5 | V5: =AVERAGEIFS($H$3:$H$253,$C$3:$C$253,$N5,$D$3:$D$253,R$2) -> 17.5 | W5: =IFERROR(O5/(S5*$L$2),"-") -> 7.7035714 | X5: =IFERROR(P5/(T5*$L$2),"-") -> 2.585 | Y5: =IFERROR(Q5/(U5*$L$2),"-") -> 2.5621429 | Z5: =IFERROR(R5/(V5*$L$2),"-") -> 2.5564286 | AA5: =SUMIFS($F$3:$F$253,$C$3:$C$253,$N5) -> 1090.1 | AB5: =SUMIFS($F$3:$F$253,$C$3:$C$253,$N5,$D$3:$D$253,P$2) -> 381 | AC5: =SUMIFS($F$3:$F$253,$C$3:$C$253,$N5,$D$3:$D$253,Q$2) -> 352.3 | AD5: =SUMIFS($F$3:$F$253,$C$3:$C$253,$N5,$D$3:$D$253,R$2) -> 356.8 | AE5: =AVERAGEIFS($I$3:$I$253,$C$3:$C$253,$N5) -> 18 | AF5: =AVERAGEIFS($I$3:$I$253,$C$3:$C$253,$N5,$D$3:$D$253,P$2) -> 19 | AG5: =AVERAGEIFS($I$3:$I$253,$C$3:$C$253,$N5,$D$3:$D$253,Q$2) -> 17 | AH5: =AVERAGEIFS($I$3:$I$253,$C$3:$C$253,$N5,$D$3:$D$253,R$2) -> 18 | AI5: =IFERROR(AA5/(AE5*$L$2),"-") -> 7.5701389 | AJ5: =IFERROR(AB5/(AF5*$L$2),"-") -> 2.5065789 | AK5: =IFERROR(AC5/(AG5*$L$2),"-") -> 2.5904412 | AL5: =IFERROR(AD5/(AH5*$L$2),"-") -> 2.4777778 | AM5: =SUMIFS($G$3:$G$253,$C$3:$C$253,$N5) -> 934.9 | AN5: =SUMIFS($G$3:$G$253,$C$3:$C$253,$N5,$D$3:$D$253,P$2) -> 330.9 | AO5: =SUMIFS($G$3:$G$253,$C$3:$C$253,$N5,$D$3:$D$253,Q$2) -> 296.9 | AP5: =SUMIFS($G$3:$G$253,$C$3:$C$253,$N5,$D$3:$D$253,R$2) -> 307.1 | AQ5: =AVERAGEIFS($J$3:$J$253,$C$3:$C$253,$N5) -> 15.333333 | AR5: =AVERAGEIFS($J$3:$J$253,$C$3:$C$253,$N5,$D$3:$D$253,P$2) -> 16 | AS5: =AVERAGEIFS($J$3:$J$253,$C$3:$C$253,$N5,$D$3:$D$253,Q$2) -> 14.5 | AT5: =AVERAGEIFS($J$3:$J$253,$C$3:$C$253,$N5,$D$3:$D$253,R$2) -> 15.5 | AU5: =IFERROR(AM5/(AQ5*$L$2),"-") -> 7.6214674 | AV5: =IFERROR(AN5/(AR5*$L$2),"-") -> 2.5851562 | AW5: =IFERROR(AO5/(AS5*$L$2),"-") -> 2.5594828 | AX5: =IFERROR(AP5/(AT5*$L$2),"-") -> 2.4766129
A6: 1203036 | B6: =_xlfn.XLOOKUP(A6,monthly_work_hours!A:A,monthly_work_hours!B:B) -> 이범철 | C6: =_xlfn.XLOOKUP(A6,monthly_work_hours!A:A,monthly_work_hours!E:E) -> SL생산기술팀 | D6: =_xlfn.XLOOKUP(A6,monthly_work_hours!A:A,monthly_work_hours!F:F) -> 책임 | E6: =SUMIFS(monthly_work_hours!$M:$M,monthly_work_hours!$A:$A,'FTE 계산'!$A6,monthly_work_hours!$H:$H,'FTE 계산'!E$2) -> 161 | F6: =SUMIFS(monthly_work_hours!$M:$M,monthly_work_hours!$A:$A,'FTE 계산'!$A6,monthly_work_hours!$H:$H,'FTE 계산'!F$2) -> 171.6 | G6: =SUMIFS(monthly_work_hours!$M:$M,monthly_work_hours!$A:$A,'FTE 계산'!$A6,monthly_work_hours!$H:$H,'FTE 계산'!G$2) -> 125.5 | H6: =(SUMIFS(monthly_work_hours!$I:$I,monthly_work_hours!$A:$A,'FTE 계산'!$A6,monthly_work_hours!$H:$H,'FTE 계산'!H$2)) - (SUMIFS(monthly_work_hours!$L:$L,monthly_work_hours!$A:$A,'FTE 계산'!$A6,monthly_work_hours!$H:$H,'FTE 계산'!H$2)) -> 18 | I6: =(SUMIFS(monthly_work_hours!$I:$I,monthly_work_hours!$A:$A,'FTE 계산'!$A6,monthly_work_hours!$H:$H,'FTE 계산'!I$2)) - (SUMIFS(monthly_work_hours!$L:$L,monthly_work_hours!$A:$A,'FTE 계산'!$A6,monthly_work_hours!$H:$H,'FTE 계산'!I$2)) -> 19 | J6: =(SUMIFS(monthly_work_hours!$I:$I,monthly_work_hours!$A:$A,'FTE 계산'!$A6,monthly_work_hours!$H:$H,'FTE 계산'!J$2)) - (SUMIFS(monthly_work_hours!$L:$L,monthly_work_hours!$A:$A,'FTE 계산'!$A6,monthly_work_hours!$H:$H,'FTE 계산'!J$2)) -> 14 | N6: SCM팀 | O6: =SUMIFS($E$3:$E$253,$C$3:$C$253,$N6) -> 2073.9 | P6: =SUMIFS($E$3:$E$253,$C$3:$C$253,$N6,$D$3:$D$253,P$2) -> 699.8 | Q6: =SUMIFS($E$3:$E$253,$C$3:$C$253,$N6,$D$3:$D$253,Q$2) -> 687.8 | R6: =SUMIFS($E$3:$E$253,$C$3:$C$253,$N6,$D$3:$D$253,R$2) -> 686.3 | S6: =AVERAGEIFS($H$3:$H$253,$C$3:$C$253,$N6) -> 17.416667 | T6: =AVERAGEIFS($H$3:$H$253,$C$3:$C$253,$N6,$D$3:$D$253,P$2) -> 17.5 | U6: =AVERAGEIFS($H$3:$H$253,$C$3:$C$253,$N6,$D$3:$D$253,Q$2) -> 16.75 | V6: =AVERAGEIFS($H$3:$H$253,$C$3:$C$253,$N6,$D$3:$D$253,R$2) -> 18 | W6: =IFERROR(O6/(S6*$L$2),"-") -> 14.88445 | X6: =IFERROR(P6/(T6*$L$2),"-") -> 4.9985714 | Y6: =IFERROR(Q6/(U6*$L$2),"-") -> 5.1328358 | Z6: =IFERROR(R6/(V6*$L$2),"-") -> 4.7659722 | AA6: =SUMIFS($F$3:$F$253,$C$3:$C$253,$N6) -> 2027.8 | AB6: =SUMIFS($F$3:$F$253,$C$3:$C$253,$N6,$D$3:$D$253,P$2) -> 715 | AC6: =SUMIFS($F$3:$F$253,$C$3:$C$253,$N6,$D$3:$D$253,Q$2) -> 548.7 | AD6: =SUMIFS($F$3:$F$253,$C$3:$C$253,$N6,$D$3:$D$253,R$2) -> 764.1 | AE6: =AVERAGEIFS($I$3:$I$253,$C$3:$C$253,$N6) -> 17.833333 | AF6: =AVERAGEIFS($I$3:$I$253,$C$3:$C$253,$N6,$D$3:$D$253,P$2) -> 18.5 | AG6: =AVERAGEIFS($I$3:$I$253,$C$3:$C$253,$N6,$D$3:$D$253,Q$2) -> 15.5 | AH6: =AVERAGEIFS($I$3:$I$253,$C$3:$C$253,$N6,$D$3:$D$253,R$2) -> 19.5 | AI6: =IFERROR(AA6/(AE6*$L$2),"-") -> 14.213551 | AJ6: =IFERROR(AB6/(AF6*$L$2),"-") -> 4.8310811 | AK6: =IFERROR(AC6/(AG6*$L$2),"-") -> 4.425 | AL6: =IFERROR(AD6/(AH6*$L$2),"-") -> 4.8980769 | AM6: =SUMIFS($G$3:$G$253,$C$3:$C$253,$N6) -> 1633.8 | AN6: =SUMIFS($G$3:$G$253,$C$3:$C$253,$N6,$D$3:$D$253,P$2) -> 596.8 | AO6: =SUMIFS($G$3:$G$253,$C$3:$C$253,$N6,$D$3:$D$253,Q$2) -> 445.2 | AP6: =SUMIFS($G$3:$G$253,$C$3:$C$253,$N6,$D$3:$D$253,R$2) -> 591.8 | AQ6: =AVERAGEIFS($J$3:$J$253,$C$3:$C$253,$N6) -> 14.75 | AR6: =AVERAGEIFS($J$3:$J$253,$C$3:$C$253,$N6,$D$3:$D$253,P$2) -> 16 | AS6: =AVERAGEIFS($J$3:$J$253,$C$3:$C$253,$N6,$D$3:$D$253,Q$2) -> 12 | AT6: =AVERAGEIFS($J$3:$J$253,$C$3:$C$253,$N6,$D$3:$D$253,R$2) -> 16.25 | AU6: =IFERROR(AM6/(AQ6*$L$2),"-") -> 13.845763 | AV6: =IFERROR(AN6/(AR6*$L$2),"-") -> 4.6625 | AW6: =IFERROR(AO6/(AS6*$L$2),"-") -> 4.6375 | AX6: =IFERROR(AP6/(AT6*$L$2),"-") -> 4.5523077
A7: 1203052 | B7: =_xlfn.XLOOKUP(A7,monthly_work_hours!A:A,monthly_work_hours!B:B) -> 제용화 | C7: =_xlfn.XLOOKUP(A7,monthly_work_hours!A:A,monthly_work_hours!E:E) -> 구매원가팀 | D7: =_xlfn.XLOOKUP(A7,monthly_work_hours!A:A,monthly_work_hours!F:F) -> 책임 | E7: =SUMIFS(monthly_work_hours!$M:$M,monthly_work_hours!$A:$A,'FTE 계산'!$A7,monthly_work_hours!$H:$H,'FTE 계산'!E$2) -> 174.5 | F7: =SUMIFS(monthly_work_hours!$M:$M,monthly_work_hours!$A:$A,'FTE 계산'!$A7,monthly_work_hours!$H:$H,'FTE 계산'!F$2) -> 193.3 | G7: =SUMIFS(monthly_work_hours!$M:$M,monthly_work_hours!$A:$A,'FTE 계산'!$A7,monthly_work_hours!$H:$H,'FTE 계산'!G$2) -> 170.3 | H7: =(SUMIFS(monthly_work_hours!$I:$I,monthly_work_hours!$A:$A,'FTE 계산'!$A7,monthly_work_hours!$H:$H,'FTE 계산'!H$2)) - (SUMIFS(monthly_work_hours!$L:$L,monthly_work_hours!$A:$A,'FTE 계산'!$A7,monthly_work_hours!$H:$H,'FTE 계산'!H$2)) -> 17 | I7: =(SUMIFS(monthly_work_hours!$I:$I,monthly_work_hours!$A:$A,'FTE 계산'!$A7,monthly_work_hours!$H:$H,'FTE 계산'!I$2)) - (SUMIFS(monthly_work_hours!$L:$L,monthly_work_hours!$A:$A,'FTE 계산'!$A7,monthly_work_hours!$H:$H,'FTE 계산'!I$2)) -> 19 | J7: =(SUMIFS(monthly_work_hours!$I:$I,monthly_work_hours!$A:$A,'FTE 계산'!$A7,monthly_work_hours!$H:$H,'FTE 계산'!J$2)) - (SUMIFS(monthly_work_hours!$L:$L,monthly_work_hours!$A:$A,'FTE 계산'!$A7,monthly_work_hours!$H:$H,'FTE 계산'!J$2)) -> 16 | N7: SL품질보증팀 | O7: =SUMIFS($E$3:$E$253,$C$3:$C$253,$N7) -> 1496.1 | P7: =SUMIFS($E$3:$E$253,$C$3:$C$253,$N7,$D$3:$D$253,P$2) -> 322 | Q7: =SUMIFS($E$3:$E$253,$C$3:$C$253,$N7,$D$3:$D$253,Q$2) -> 833.1 | R7: =SUMIFS($E$3:$E$253,$C$3:$C$253,$N7,$D$3:$D$253,R$2) -> 341 | S7: =AVERAGEIFS($H$3:$H$253,$C$3:$C$253,$N7) -> 12.714286 | T7: =AVERAGEIFS($H$3:$H$253,$C$3:$C$253,$N7,$D$3:$D$253,P$2) -> 11.666667 | U7: =AVERAGEIFS($H$3:$H$253,$C$3:$C$253,$N7,$D$3:$D$253,Q$2) -> 12.875 | V7: =AVERAGEIFS($H$3:$H$253,$C$3:$C$253,$N7,$D$3:$D$253,R$2) -> 13.333333 | W7: =IFERROR(O7/(S7*$L$2),"-") -> 14.708848 | X7: =IFERROR(P7/(T7*$L$2),"-") -> 3.45 | Y7: =IFERROR(Q7/(U7*$L$2),"-") -> 8.0883495 | Z7: =IFERROR(R7/(V7*$L$2),"-") -> 3.196875 | AA7: =SUMIFS($F$3:$F$253,$C$3:$C$253,$N7) -> 1562.8 | AB7: =SUMIFS($F$3:$F$253,$C$3:$C$253,$N7,$D$3:$D$253,P$2) -> 321.4 | AC7: =SUMIFS($F$3:$F$253,$C$3:$C$253,$N7,$D$3:$D$253,Q$2) -> 802.3 | AD7: =SUMIFS($F$3:$F$253,$C$3:$C$253,$N7,$D$3:$D$253,R$2) -> 439.1 | AE7: =AVERAGEIFS($I$3:$I$253,$C$3:$C$253,$N7) -> 13.5 | AF7: =AVERAGEIFS($I$3:$I$253,$C$3:$C$253,$N7,$D$3:$D$253,P$2) -> 12.333333 | AG7: =AVERAGEIFS($I$3:$I$253,$C$3:$C$253,$N7,$D$3:$D$253,Q$2) -> 13 | AH7: =AVERAGEIFS($I$3:$I$253,$C$3:$C$253,$N7,$D$3:$D$253,R$2) -> 16 | AI7: =IFERROR(AA7/(AE7*$L$2),"-") -> 14.47037 | AJ7: =IFERROR(AB7/(AF7*$L$2),"-") -> 3.2574324 | AK7: =IFERROR(AC7/(AG7*$L$2),"-") -> 7.7144231 | AL7: =IFERROR(AD7/(AH7*$L$2),"-") -> 3.4304688 | AM7: =SUMIFS($G$3:$G$253,$C$3:$C$253,$N7) -> 1243.5 | AN7: =SUMIFS($G$3:$G$253,$C$3:$C$253,$N7,$D$3:$D$253,P$2) -> 297.1 | AO7: =SUMIFS($G$3:$G$253,$C$3:$C$253,$N7,$D$3:$D$253,Q$2) -> 627.6 | AP7: =SUMIFS($G$3:$G$253,$C$3:$C$253,$N7,$D$3:$D$253,R$2) -> 318.8 | AQ7: =AVERAGEIFS($J$3:$J$253,$C$3:$C$253,$N7) -> 11.357143 | AR7: =AVERAGEIFS($J$3:$J$253,$C$3:$C$253,$N7,$D$3:$D$253,P$2) -> 11.333333 | AS7: =AVERAGEIFS($J$3:$J$253,$C$3:$C$253,$N7,$D$3:$D$253,Q$2) -> 10.875 | AT7: =AVERAGEIFS($J$3:$J$253,$C$3:$C$253,$N7,$D$3:$D$253,R$2) -> 12.666667 | AU7: =IFERROR(AM7/(AQ7*$L$2),"-") -> 13.686321 | AV7: =IFERROR(AN7/(AR7*$L$2),"-") -> 3.2768382 | AW7: =IFERROR(AO7/(AS7*$L$2),"-") -> 7.2137931 | AX7: =IFERROR(AP7/(AT7*$L$2),"-") -> 3.1460526
A8: 1203053 | B8: =_xlfn.XLOOKUP(A8,monthly_work_hours!A:A,monthly_work_hours!B:B) -> 문은진 | C8: =_xlfn.XLOOKUP(A8,monthly_work_hours!A:A,monthly_work_hours!E:E) -> SCM팀 | D8: =_xlfn.XLOOKUP(A8,monthly_work_hours!A:A,monthly_work_hours!F:F) -> 책임 | E8: =SUMIFS(monthly_work_hours!$M:$M,monthly_work_hours!$A:$A,'FTE 계산'!$A8,monthly_work_hours!$H:$H,'FTE 계산'!E$2) -> 170.4 | F8: =SUMIFS(monthly_work_hours!$M:$M,monthly_work_hours!$A:$A,'FTE 계산'!$A8,monthly_work_hours!$H:$H,'FTE 계산'!F$2) -> 165.4 | G8: =SUMIFS(monthly_work_hours!$M:$M,monthly_work_hours!$A:$A,'FTE 계산'!$A8,monthly_work_hours!$H:$H,'FTE 계산'!G$2) -> 140.3 | H8: =(SUMIFS(monthly_work_hours!$I:$I,monthly_work_hours!$A:$A,'FTE 계산'!$A8,monthly_work_hours!$H:$H,'FTE 계산'!H$2)) - (SUMIFS(monthly_work_hours!$L:$L,monthly_work_hours!$A:$A,'FTE 계산'!$A8,monthly_work_hours!$H:$H,'FTE 계산'!H$2)) -> 17 | I8: =(SUMIFS(monthly_work_hours!$I:$I,monthly_work_hours!$A:$A,'FTE 계산'!$A8,monthly_work_hours!$H:$H,'FTE 계산'!I$2)) - (SUMIFS(monthly_work_hours!$L:$L,monthly_work_hours!$A:$A,'FTE 계산'!$A8,monthly_work_hours!$H:$H,'FTE 계산'!I$2)) -> 18 | J8: =(SUMIFS(monthly_work_hours!$I:$I,monthly_work_hours!$A:$A,'FTE 계산'!$A8,monthly_work_hours!$H:$H,'FTE 계산'!J$2)) - (SUMIFS(monthly_work_hours!$L:$L,monthly_work_hours!$A:$A,'FTE 계산'!$A8,monthly_work_hours!$H:$H,'FTE 계산'!J$2)) -> 16 | N8: FL생산기술팀 | O8: =SUMIFS($E$3:$E$253,$C$3:$C$253,$N8) -> 535.9 | P8: =SUMIFS($E$3:$E$253,$C$3:$C$253,$N8,$D$3:$D$253,P$2) -> 172.1 | Q8: =SUMIFS($E$3:$E$253,$C$3:$C$253,$N8,$D$3:$D$253,Q$2) -> 0 | R8: =SUMIFS($E$3:$E$253,$C$3:$C$253,$N8,$D$3:$D$253,R$2) -> 363.8 | S8: =AVERAGEIFS($H$3:$H$253,$C$3:$C$253,$N8) -> 18 | T8: =AVERAGEIFS($H$3:$H$253,$C$3:$C$253,$N8,$D$3:$D$253,P$2) -> 18 | U8: =AVERAGEIFS($H$3:$H$253,$C$3:$C$253,$N8,$D$3:$D$253,Q$2) -> #DIV/0! | V8: =AVERAGEIFS($H$3:$H$253,$C$3:$C$253,$N8,$D$3:$D$253,R$2) -> 18 | W8: =IFERROR(O8/(S8*$L$2),"-") -> 3.7215278 | X8: =IFERROR(P8/(T8*$L$2),"-") -> 1.1951389 | Y8: =IFERROR(Q8/(U8*$L$2),"-") -> - | Z8: =IFERROR(R8/(V8*$L$2),"-") -> 2.5263889 | AA8: =SUMIFS($F$3:$F$253,$C$3:$C$253,$N8) -> 565.9 | AB8: =SUMIFS($F$3:$F$253,$C$3:$C$253,$N8,$D$3:$D$253,P$2) -> 174 | AC8: =SUMIFS($F$3:$F$253,$C$3:$C$253,$N8,$D$3:$D$253,Q$2) -> 0 | AD8: =SUMIFS($F$3:$F$253,$C$3:$C$253,$N8,$D$3:$D$253,R$2) -> 391.9 | AE8: =AVERAGEIFS($I$3:$I$253,$C$3:$C$253,$N8) -> 18 | AF8: =AVERAGEIFS($I$3:$I$253,$C$3:$C$253,$N8,$D$3:$D$253,P$2) -> 18 | AG8: =AVERAGEIFS($I$3:$I$253,$C$3:$C$253,$N8,$D$3:$D$253,Q$2) -> #DIV/0! | AH8: =AVERAGEIFS($I$3:$I$253,$C$3:$C$253,$N8,$D$3:$D$253,R$2) -> 18 | AI8: =IFERROR(AA8/(AE8*$L$2),"-") -> 3.9298611 | AJ8: =IFERROR(AB8/(AF8*$L$2),"-") -> 1.2083333 | AK8: =IFERROR(AC8/(AG8*$L$2),"-") -> - | AL8: =IFERROR(AD8/(AH8*$L$2),"-") -> 2.7215278 | AM8: =SUMIFS($G$3:$G$253,$C$3:$C$253,$N8) -> 462.2 | AN8: =SUMIFS($G$3:$G$253,$C$3:$C$253,$N8,$D$3:$D$253,P$2) -> 146.6 | AO8: =SUMIFS($G$3:$G$253,$C$3:$C$253,$N8,$D$3:$D$253,Q$2) -> 0 | AP8: =SUMIFS($G$3:$G$253,$C$3:$C$253,$N8,$D$3:$D$253,R$2) -> 315.6 | AQ8: =AVERAGEIFS($J$3:$J$253,$C$3:$C$253,$N8) -> 16.333333 | AR8: =AVERAGEIFS($J$3:$J$253,$C$3:$C$253,$N8,$D$3:$D$253,P$2) -> 16 | AS8: =AVERAGEIFS($J$3:$J$253,$C$3:$C$253,$N8,$D$3:$D$253,Q$2) -> #DIV/0! | AT8: =AVERAGEIFS($J$3:$J$253,$C$3:$C$253,$N8,$D$3:$D$253,R$2) -> 16.5 | AU8: =IFERROR(AM8/(AQ8*$L$2),"-") -> 3.5372449 | AV8: =IFERROR(AN8/(AR8*$L$2),"-") -> 1.1453125 | AW8: =IFERROR(AO8/(AS8*$L$2),"-") -> - | AX8: =IFERROR(AP8/(AT8*$L$2),"-") -> 2.3909091
A9: 1204003 | B9: =_xlfn.XLOOKUP(A9,monthly_work_hours!A:A,monthly_work_hours!B:B) -> 정용규 | C9: =_xlfn.XLOOKUP(A9,monthly_work_hours!A:A,monthly_work_hours!E:E) -> SL생산기술팀 | D9: =_xlfn.XLOOKUP(A9,monthly_work_hours!A:A,monthly_work_hours!F:F) -> 책임 | E9: =SUMIFS(monthly_work_hours!$M:$M,monthly_work_hours!$A:$A,'FTE 계산'!$A9,monthly_work_hours!$H:$H,'FTE 계산'!E$2) -> 147.9 | F9: =SUMIFS(monthly_work_hours!$M:$M,monthly_work_hours!$A:$A,'FTE 계산'!$A9,monthly_work_hours!$H:$H,'FTE 계산'!F$2) -> 191.4 | G9: =SUMIFS(monthly_work_hours!$M:$M,monthly_work_hours!$A:$A,'FTE 계산'!$A9,monthly_work_hours!$H:$H,'FTE 계산'!G$2) -> 149.5 | H9: =(SUMIFS(monthly_work_hours!$I:$I,monthly_work_hours!$A:$A,'FTE 계산'!$A9,monthly_work_hours!$H:$H,'FTE 계산'!H$2)) - (SUMIFS(monthly_work_hours!$L:$L,monthly_work_hours!$A:$A,'FTE 계산'!$A9,monthly_work_hours!$H:$H,'FTE 계산'!H$2)) -> 17 | I9: =(SUMIFS(monthly_work_hours!$I:$I,monthly_work_hours!$A:$A,'FTE 계산'!$A9,monthly_work_hours!$H:$H,'FTE 계산'!I$2)) - (SUMIFS(monthly_work_hours!$L:$L,monthly_work_hours!$A:$A,'FTE 계산'!$A9,monthly_work_hours!$H:$H,'FTE 계산'!I$2)) -> 19 | J9: =(SUMIFS(monthly_work_hours!$I:$I,monthly_work_hours!$A:$A,'FTE 계산'!$A9,monthly_work_hours!$H:$H,'FTE 계산'!J$2)) - (SUMIFS(monthly_work_hours!$L:$L,monthly_work_hours!$A:$A,'FTE 계산'!$A9,monthly_work_hours!$H:$H,'FTE 계산'!J$2)) -> 16 | N9: FL개발팀 | O9: =SUMIFS($E$3:$E$253,$C$3:$C$253,$N9) -> 2148.3 | P9: =SUMIFS($E$3:$E$253,$C$3:$C$253,$N9,$D$3:$D$253,P$2) -> 664.6 | Q9: =SUMIFS($E$3:$E$253,$C$3:$C$253,$N9,$D$3:$D$253,Q$2) -> 1097.9 | R9: =SUMIFS($E$3:$E$253,$C$3:$C$253,$N9,$D$3:$D$253,R$2) -> 385.8 | S9: =AVERAGEIFS($H$3:$H$253,$C$3:$C$253,$N9) -> 15.071429 | T9: =AVERAGEIFS($H$3:$H$253,$C$3:$C$253,$N9,$D$3:$D$253,P$2) -> 18 | U9: =AVERAGEIFS($H$3:$H$253,$C$3:$C$253,$N9,$D$3:$D$253,Q$2) -> 16.428571 | V9: =AVERAGEIFS($H$3:$H$253,$C$3:$C$253,$N9,$D$3:$D$253,R$2) -> 10.5 | W9: =IFERROR(O9/(S9*$L$2),"-") -> 17.817654 | X9: =IFERROR(P9/(T9*$L$2),"-") -> 4.6152778 | Y9: =IFERROR(Q9/(U9*$L$2),"-") -> 8.353587 | Z9: =IFERROR(R9/(V9*$L$2),"-") -> 4.5928571 | AA9: =SUMIFS($F$3:$F$253,$C$3:$C$253,$N9) -> 2209.5 | AB9: =SUMIFS($F$3:$F$253,$C$3:$C$253,$N9,$D$3:$D$253,P$2) -> 540 | AC9: =SUMIFS($F$3:$F$253,$C$3:$C$253,$N9,$D$3:$D$253,Q$2) -> 1144.8 | AD9: =SUMIFS($F$3:$F$253,$C$3:$C$253,$N9,$D$3:$D$253,R$2) -> 524.7 | AE9: =AVERAGEIFS($I$3:$I$253,$C$3:$C$253,$N9) -> 16.285714 | AF9: =AVERAGEIFS($I$3:$I$253,$C$3:$C$253,$N9,$D$3:$D$253,P$2) -> 18 | AG9: =AVERAGEIFS($I$3:$I$253,$C$3:$C$253,$N9,$D$3:$D$253,Q$2) -> 16.428571 | AH9: =AVERAGEIFS($I$3:$I$253,$C$3:$C$253,$N9,$D$3:$D$253,R$2) -> 14.75 | AI9: =IFERROR(AA9/(AE9*$L$2),"-") -> 16.958882 | AJ9: =IFERROR(AB9/(AF9*$L$2),"-") -> 3.75 | AK9: =IFERROR(AC9/(AG9*$L$2),"-") -> 8.7104348 | AL9: =IFERROR(AD9/(AH9*$L$2),"-") -> 4.4466102 | AM9: =SUMIFS($G$3:$G$253,$C$3:$C$253,$N9) -> 1769.8 | AN9: =SUMIFS($G$3:$G$253,$C$3:$C$253,$N9,$D$3:$D$253,P$2) -> 459.6 | AO9: =SUMIFS($G$3:$G$253,$C$3:$C$253,$N9,$D$3:$D$253,Q$2) -> 874.2 | AP9: =SUMIFS($G$3:$G$253,$C$3:$C$253,$N9,$D$3:$D$253,R$2) -> 436 | AQ9: =AVERAGEIFS($J$3:$J$253,$C$3:$C$253,$N9) -> 14.285714 | AR9: =AVERAGEIFS($J$3:$J$253,$C$3:$C$253,$N9,$D$3:$D$253,P$2) -> 16 | AS9: =AVERAGEIFS($J$3:$J$253,$C$3:$C$253,$N9,$D$3:$D$253,Q$2) -> 14 | AT9: =AVERAGEIFS($J$3:$J$253,$C$3:$C$253,$N9,$D$3:$D$253,R$2) -> 13.5 | AU9: =IFERROR(AM9/(AQ9*$L$2),"-") -> 15.48575 | AV9: =IFERROR(AN9/(AR9*$L$2),"-") -> 3.590625 | AW9: =IFERROR(AO9/(AS9*$L$2),"-") -> 7.8053571 | AX9: =IFERROR(AP9/(AT9*$L$2),"-") -> 4.037037
A10: 1204063 | B10: =_xlfn.XLOOKUP(A10,monthly_work_hours!A:A,monthly_work_hours!B:B) -> 김주호 | C10: =_xlfn.XLOOKUP(A10,monthly_work_hours!A:A,monthly_work_hours!E:E) -> SL품질보증팀 | D10: =_xlfn.XLOOKUP(A10,monthly_work_hours!A:A,monthly_work_hours!F:F) -> 책임 | E10: =SUMIFS(monthly_work_hours!$M:$M,monthly_work_hours!$A:$A,'FTE 계산'!$A10,monthly_work_hours!$H:$H,'FTE 계산'!E$2) -> 7 | F10: =SUMIFS(monthly_work_hours!$M:$M,monthly_work_hours!$A:$A,'FTE 계산'!$A10,monthly_work_hours!$H:$H,'FTE 계산'!F$2) -> 0.4 | G10: =SUMIFS(monthly_work_hours!$M:$M,monthly_work_hours!$A:$A,'FTE 계산'!$A10,monthly_work_hours!$H:$H,'FTE 계산'!G$2) -> 22.8 | H10: =(SUMIFS(monthly_work_hours!$I:$I,monthly_work_hours!$A:$A,'FTE 계산'!$A10,monthly_work_hours!$H:$H,'FTE 계산'!H$2)) - (SUMIFS(monthly_work_hours!$L:$L,monthly_work_hours!$A:$A,'FTE 계산'!$A10,monthly_work_hours!$H:$H,'FTE 계산'!H$2)) -> 2 | I10: =(SUMIFS(monthly_work_hours!$I:$I,monthly_work_hours!$A:$A,'FTE 계산'!$A10,monthly_work_hours!$H:$H,'FTE 계산'!I$2)) - (SUMIFS(monthly_work_hours!$L:$L,monthly_work_hours!$A:$A,'FTE 계산'!$A10,monthly_work_hours!$H:$H,'FTE 계산'!I$2)) -> 4 | J10: =(SUMIFS(monthly_work_hours!$I:$I,monthly_work_hours!$A:$A,'FTE 계산'!$A10,monthly_work_hours!$H:$H,'FTE 계산'!J$2)) - (SUMIFS(monthly_work_hours!$L:$L,monthly_work_hours!$A:$A,'FTE 계산'!$A10,monthly_work_hours!$H:$H,'FTE 계산'!J$2)) -> 4 | N10: 선행개발팀 | O10: =SUMIFS($E$3:$E$253,$C$3:$C$253,$N10) -> 1073.8 | P10: =SUMIFS($E$3:$E$253,$C$3:$C$253,$N10,$D$3:$D$253,P$2) -> 293.1 | Q10: =SUMIFS($E$3:$E$253,$C$3:$C$253,$N10,$D$3:$D$253,Q$2) -> 635.4 | R10: =SUMIFS($E$3:$E$253,$C$3:$C$253,$N10,$D$3:$D$253,R$2) -> 145.3 | S10: =AVERAGEIFS($H$3:$H$253,$C$3:$C$253,$N10) -> 16.571429 | T10: =AVERAGEIFS($H$3:$H$253,$C$3:$C$253,$N10,$D$3:$D$253,P$2) -> 16.5 | U10: =AVERAGEIFS($H$3:$H$253,$C$3:$C$253,$N10,$D$3:$D$253,Q$2) -> 16.5 | V10: =AVERAGEIFS($H$3:$H$253,$C$3:$C$253,$N10,$D$3:$D$253,R$2) -> 17 | W10: =IFERROR(O10/(S10*$L$2),"-") -> 8.0997845 | X10: =IFERROR(P10/(T10*$L$2),"-") -> 2.2204545 | Y10: =IFERROR(Q10/(U10*$L$2),"-") -> 4.8136364 | Z10: =IFERROR(R10/(V10*$L$2),"-") -> 1.0683824 | AA10: =SUMIFS($F$3:$F$253,$C$3:$C$253,$N10) -> 936.7 | AB10: =SUMIFS($F$3:$F$253,$C$3:$C$253,$N10,$D$3:$D$253,P$2) -> 291.2 | AC10: =SUMIFS($F$3:$F$253,$C$3:$C$253,$N10,$D$3:$D$253,Q$2) -> 499.6 | AD10: =SUMIFS($F$3:$F$253,$C$3:$C$253,$N10,$D$3:$D$253,R$2) -> 145.9 | AE10: =AVERAGEIFS($I$3:$I$253,$C$3:$C$253,$N10) -> 14.285714 | AF10: =AVERAGEIFS($I$3:$I$253,$C$3:$C$253,$N10,$D$3:$D$253,P$2) -> 17 | AG10: =AVERAGEIFS($I$3:$I$253,$C$3:$C$253,$N10,$D$3:$D$253,Q$2) -> 12.25 | AH10: =AVERAGEIFS($I$3:$I$253,$C$3:$C$253,$N10,$D$3:$D$253,R$2) -> 17 | AI10: =IFERROR(AA10/(AE10*$L$2),"-") -> 8.196125 | AJ10: =IFERROR(AB10/(AF10*$L$2),"-") -> 2.1411765 | AK10: =IFERROR(AC10/(AG10*$L$2),"-") -> 5.0979592 | AL10: =IFERROR(AD10/(AH10*$L$2),"-") -> 1.0727941 | AM10: =SUMIFS($G$3:$G$253,$C$3:$C$253,$N10) -> 739.7 | AN10: =SUMIFS($G$3:$G$253,$C$3:$C$253,$N10,$D$3:$D$253,P$2) -> 237.6 | AO10: =SUMIFS($G$3:$G$253,$C$3:$C$253,$N10,$D$3:$D$253,Q$2) -> 364.3 | AP10: =SUMIFS($G$3:$G$253,$C$3:$C$253,$N10,$D$3:$D$253,R$2) -> 137.8 | AQ10: =AVERAGEIFS($J$3:$J$253,$C$3:$C$253,$N10) -> 12.428571 | AR10: =AVERAGEIFS($J$3:$J$253,$C$3:$C$253,$N10,$D$3:$D$253,P$2) -> 14.5 | AS10: =AVERAGEIFS($J$3:$J$253,$C$3:$C$253,$N10,$D$3:$D$253,Q$2) -> 10.5 | AT10: =AVERAGEIFS($J$3:$J$253,$C$3:$C$253,$N10,$D$3:$D$253,R$2) -> 16 | AU10: =IFERROR(AM10/(AQ10*$L$2),"-") -> 7.4395115 | AV10: =IFERROR(AN10/(AR10*$L$2),"-") -> 2.0482759 | AW10: =IFERROR(AO10/(AS10*$L$2),"-") -> 4.3369048 | AX10: =IFERROR(AP10/(AT10*$L$2),"-") -> 1.0765625
A11: 1204106 | B11: =_xlfn.XLOOKUP(A11,monthly_work_hours!A:A,monthly_work_hours!B:B) -> 김영준 | C11: =_xlfn.XLOOKUP(A11,monthly_work_hours!A:A,monthly_work_hours!E:E) -> 선행개발실 | D11: =_xlfn.XLOOKUP(A11,monthly_work_hours!A:A,monthly_work_hours!F:F) -> 책임 | E11: =SUMIFS(monthly_work_hours!$M:$M,monthly_work_hours!$A:$A,'FTE 계산'!$A11,monthly_work_hours!$H:$H,'FTE 계산'!E$2) -> 218.9 | F11: =SUMIFS(monthly_work_hours!$M:$M,monthly_work_hours!$A:$A,'FTE 계산'!$A11,monthly_work_hours!$H:$H,'FTE 계산'!F$2) -> 160.1 | G11: =SUMIFS(monthly_work_hours!$M:$M,monthly_work_hours!$A:$A,'FTE 계산'!$A11,monthly_work_hours!$H:$H,'FTE 계산'!G$2) -> 133 | H11: =(SUMIFS(monthly_work_hours!$I:$I,monthly_work_hours!$A:$A,'FTE 계산'!$A11,monthly_work_hours!$H:$H,'FTE 계산'!H$2)) - (SUMIFS(monthly_work_hours!$L:$L,monthly_work_hours!$A:$A,'FTE 계산'!$A11,monthly_work_hours!$H:$H,'FTE 계산'!H$2)) -> 14 | I11: =(SUMIFS(monthly_work_hours!$I:$I,monthly_work_hours!$A:$A,'FTE 계산'!$A11,monthly_work_hours!$H:$H,'FTE 계산'!I$2)) - (SUMIFS(monthly_work_hours!$L:$L,monthly_work_hours!$A:$A,'FTE 계산'!$A11,monthly_work_hours!$H:$H,'FTE 계산'!I$2)) -> 16 | J11: =(SUMIFS(monthly_work_hours!$I:$I,monthly_work_hours!$A:$A,'FTE 계산'!$A11,monthly_work_hours!$H:$H,'FTE 계산'!J$2)) - (SUMIFS(monthly_work_hours!$L:$L,monthly_work_hours!$A:$A,'FTE 계산'!$A11,monthly_work_hours!$H:$H,'FTE 계산'!J$2)) -> 15 | N11: FL설계팀 | O11: =SUMIFS($E$3:$E$253,$C$3:$C$253,$N11) -> 2529.2 | P11: =SUMIFS($E$3:$E$253,$C$3:$C$253,$N11,$D$3:$D$253,P$2) -> 288.4 | Q11: =SUMIFS($E$3:$E$253,$C$3:$C$253,$N11,$D$3:$D$253,Q$2) -> 849.7 | R11: =SUMIFS($E$3:$E$253,$C$3:$C$253,$N11,$D$3:$D$253,R$2) -> 1391.1 | S11: =AVERAGEIFS($H$3:$H$253,$C$3:$C$253,$N11) -> 13.363636 | T11: =AVERAGEIFS($H$3:$H$253,$C$3:$C$253,$N11,$D$3:$D$253,P$2) -> 8.5 | U11: =AVERAGEIFS($H$3:$H$253,$C$3:$C$253,$N11,$D$3:$D$253,Q$2) -> 18.5 | V11: =AVERAGEIFS($H$3:$H$253,$C$3:$C$253,$N11,$D$3:$D$253,R$2) -> 13.285714 | W11: =IFERROR(O11/(S11*$L$2),"-") -> 23.657483 | X11: =IFERROR(P11/(T11*$L$2),"-") -> 4.2411765 | Y11: =IFERROR(Q11/(U11*$L$2),"-") -> 5.7412162 | Z11: =IFERROR(R11/(V11*$L$2),"-") -> 13.088306 | AA11: =SUMIFS($F$3:$F$253,$C$3:$C$253,$N11) -> 2628.3 | AB11: =SUMIFS($F$3:$F$253,$C$3:$C$253,$N11,$D$3:$D$253,P$2) -> 366.5 | AC11: =SUMIFS($F$3:$F$253,$C$3:$C$253,$N11,$D$3:$D$253,Q$2) -> 866.2 | AD11: =SUMIFS($F$3:$F$253,$C$3:$C$253,$N11,$D$3:$D$253,R$2) -> 1395.6 | AE11: =AVERAGEIFS($I$3:$I$253,$C$3:$C$253,$N11) -> 15.090909 | AF11: =AVERAGEIFS($I$3:$I$253,$C$3:$C$253,$N11,$D$3:$D$253,P$2) -> 17 | AG11: =AVERAGEIFS($I$3:$I$253,$C$3:$C$253,$N11,$D$3:$D$253,Q$2) -> 20 | AH11: =AVERAGEIFS($I$3:$I$253,$C$3:$C$253,$N11,$D$3:$D$253,R$2) -> 13.142857 | AI11: =IFERROR(AA11/(AE11*$L$2),"-") -> 21.770557 | AJ11: =IFERROR(AB11/(AF11*$L$2),"-") -> 2.6948529 | AK11: =IFERROR(AC11/(AG11*$L$2),"-") -> 5.41375 | AL11: =IFERROR(AD11/(AH11*$L$2),"-") -> 13.27337 | AM11: =SUMIFS($G$3:$G$253,$C$3:$C$253,$N11) -> 2220.9 | AN11: =SUMIFS($G$3:$G$253,$C$3:$C$253,$N11,$D$3:$D$253,P$2) -> 314.9 | AO11: =SUMIFS($G$3:$G$253,$C$3:$C$253,$N11,$D$3:$D$253,Q$2) -> 724.2 | AP11: =SUMIFS($G$3:$G$253,$C$3:$C$253,$N11,$D$3:$D$253,R$2) -> 1181.8 | AQ11: =AVERAGEIFS($J$3:$J$253,$C$3:$C$253,$N11) -> 13.181818 | AR11: =AVERAGEIFS($J$3:$J$253,$C$3:$C$253,$N11,$D$3:$D$253,P$2) -> 14.5 | AS11: =AVERAGEIFS($J$3:$J$253,$C$3:$C$253,$N11,$D$3:$D$253,Q$2) -> 16.5 | AT11: =AVERAGEIFS($J$3:$J$253,$C$3:$C$253,$N11,$D$3:$D$253,R$2) -> 11.857143 | AU11: =IFERROR(AM11/(AQ11*$L$2),"-") -> 21.060259 | AV11: =IFERROR(AN11/(AR11*$L$2),"-") -> 2.7146552 | AW11: =IFERROR(AO11/(AS11*$L$2),"-") -> 5.4863636 | AX11: =IFERROR(AP11/(AT11*$L$2),"-") -> 12.458735
A12: 1204115 | B12: =_xlfn.XLOOKUP(A12,monthly_work_hours!A:A,monthly_work_hours!B:B) -> 이용재 | C12: =_xlfn.XLOOKUP(A12,monthly_work_hours!A:A,monthly_work_hours!E:E) -> FL생산기술팀 | D12: =_xlfn.XLOOKUP(A12,monthly_work_hours!A:A,monthly_work_hours!F:F) -> 책임 | E12: =SUMIFS(monthly_work_hours!$M:$M,monthly_work_hours!$A:$A,'FTE 계산'!$A12,monthly_work_hours!$H:$H,'FTE 계산'!E$2) -> 172.1 | F12: =SUMIFS(monthly_work_hours!$M:$M,monthly_work_hours!$A:$A,'FTE 계산'!$A12,monthly_work_hours!$H:$H,'FTE 계산'!F$2) -> 174 | G12: =SUMIFS(monthly_work_hours!$M:$M,monthly_work_hours!$A:$A,'FTE 계산'!$A12,monthly_work_hours!$H:$H,'FTE 계산'!G$2) -> 146.6 | H12: =(SUMIFS(monthly_work_hours!$I:$I,monthly_work_hours!$A:$A,'FTE 계산'!$A12,monthly_work_hours!$H:$H,'FTE 계산'!H$2)) - (SUMIFS(monthly_work_hours!$L:$L,monthly_work_hours!$A:$A,'FTE 계산'!$A12,monthly_work_hours!$H:$H,'FTE 계산'!H$2)) -> 18 | I12: =(SUMIFS(monthly_work_hours!$I:$I,monthly_work_hours!$A:$A,'FTE 계산'!$A12,monthly_work_hours!$H:$H,'FTE 계산'!I$2)) - (SUMIFS(monthly_work_hours!$L:$L,monthly_work_hours!$A:$A,'FTE 계산'!$A12,monthly_work_hours!$H:$H,'FTE 계산'!I$2)) -> 18 | J12: =(SUMIFS(monthly_work_hours!$I:$I,monthly_work_hours!$A:$A,'FTE 계산'!$A12,monthly_work_hours!$H:$H,'FTE 계산'!J$2)) - (SUMIFS(monthly_work_hours!$L:$L,monthly_work_hours!$A:$A,'FTE 계산'!$A12,monthly_work_hours!$H:$H,'FTE 계산'!J$2)) -> 16 | N12: 품질경영팀 | O12: =SUMIFS($E$3:$E$253,$C$3:$C$253,$N12) -> 1175.7 | P12: =SUMIFS($E$3:$E$253,$C$3:$C$253,$N12,$D$3:$D$253,P$2) -> 332.1 | Q12: =SUMIFS($E$3:$E$253,$C$3:$C$253,$N12,$D$3:$D$253,Q$2) -> 675.1 | R12: =SUMIFS($E$3:$E$253,$C$3:$C$253,$N12,$D$3:$D$253,R$2) -> 168.5 | S12: =AVERAGEIFS($H$3:$H$253,$C$3:$C$253,$N12) -> 18.428571 | T12: =AVERAGEIFS($H$3:$H$253,$C$3:$C$253,$N12,$D$3:$D$253,P$2) -> 18.5 | U12: =AVERAGEIFS($H$3:$H$253,$C$3:$C$253,$N12,$D$3:$D$253,Q$2) -> 18.5 | V12: =AVERAGEIFS($H$3:$H$253,$C$3:$C$253,$N12,$D$3:$D$253,R$2) -> 18 | W12: =IFERROR(O12/(S12*$L$2),"-") -> 7.9747093 | X12: =IFERROR(P12/(T12*$L$2),"-") -> 2.2439189 | Y12: =IFERROR(Q12/(U12*$L$2),"-") -> 4.5614865 | Z12: =IFERROR(R12/(V12*$L$2),"-") -> 1.1701389 | AA12: =SUMIFS($F$3:$F$253,$C$3:$C$253,$N12) -> 1141.8 | AB12: =SUMIFS($F$3:$F$253,$C$3:$C$253,$N12,$D$3:$D$253,P$2) -> 337.1 | AC12: =SUMIFS($F$3:$F$253,$C$3:$C$253,$N12,$D$3:$D$253,Q$2) -> 649 | AD12: =SUMIFS($F$3:$F$253,$C$3:$C$253,$N12,$D$3:$D$253,R$2) -> 155.7 | AE12: =AVERAGEIFS($I$3:$I$253,$C$3:$C$253,$N12) -> 17.857143 | AF12: =AVERAGEIFS($I$3:$I$253,$C$3:$C$253,$N12,$D$3:$D$253,P$2) -> 18 | AG12: =AVERAGEIFS($I$3:$I$253,$C$3:$C$253,$N12,$D$3:$D$253,Q$2) -> 18 | AH12: =AVERAGEIFS($I$3:$I$253,$C$3:$C$253,$N12,$D$3:$D$253,R$2) -> 17 | AI12: =IFERROR(AA12/(AE12*$L$2),"-") -> 7.9926 | AJ12: =IFERROR(AB12/(AF12*$L$2),"-") -> 2.3409722 | AK12: =IFERROR(AC12/(AG12*$L$2),"-") -> 4.5069444 | AL12: =IFERROR(AD12/(AH12*$L$2),"-") -> 1.1448529 | AM12: =SUMIFS($G$3:$G$253,$C$3:$C$253,$N12) -> 973 | AN12: =SUMIFS($G$3:$G$253,$C$3:$C$253,$N12,$D$3:$D$253,P$2) -> 282.1 | AO12: =SUMIFS($G$3:$G$253,$C$3:$C$253,$N12,$D$3:$D$253,Q$2) -> 551.3 | AP12: =SUMIFS($G$3:$G$253,$C$3:$C$253,$N12,$D$3:$D$253,R$2) -> 139.6 | AQ12: =AVERAGEIFS($J$3:$J$253,$C$3:$C$253,$N12) -> 15.857143 | AR12: =AVERAGEIFS($J$3:$J$253,$C$3:$C$253,$N12,$D$3:$D$253,P$2) -> 15.5 | AS12: =AVERAGEIFS($J$3:$J$253,$C$3:$C$253,$N12,$D$3:$D$253,Q$2) -> 16 | AT12: =AVERAGEIFS($J$3:$J$253,$C$3:$C$253,$N12,$D$3:$D$253,R$2) -> 16 | AU12: =IFERROR(AM12/(AQ12*$L$2),"-") -> 7.670045 | AV12: =IFERROR(AN12/(AR12*$L$2),"-") -> 2.275 | AW12: =IFERROR(AO12/(AS12*$L$2),"-") -> 4.3070312 | AX12: =IFERROR(AP12/(AT12*$L$2),"-") -> 1.090625
A13: 1205081 | B13: =_xlfn.XLOOKUP(A13,monthly_work_hours!A:A,monthly_work_hours!B:B) -> 이호진 | C13: =_xlfn.XLOOKUP(A13,monthly_work_hours!A:A,monthly_work_hours!E:E) -> #N/A | D13: =_xlfn.XLOOKUP(A13,monthly_work_hours!A:A,monthly_work_hours!F:F) -> 기능주임 | E13: =SUMIFS(monthly_work_hours!$M:$M,monthly_work_hours!$A:$A,'FTE 계산'!$A13,monthly_work_hours!$H:$H,'FTE 계산'!E$2) -> 0 | F13: =SUMIFS(monthly_work_hours!$M:$M,monthly_work_hours!$A:$A,'FTE 계산'!$A13,monthly_work_hours!$H:$H,'FTE 계산'!F$2) -> 0 | G13: =SUMIFS(monthly_work_hours!$M:$M,monthly_work_hours!$A:$A,'FTE 계산'!$A13,monthly_work_hours!$H:$H,'FTE 계산'!G$2) -> 0 | H13: =(SUMIFS(monthly_work_hours!$I:$I,monthly_work_hours!$A:$A,'FTE 계산'!$A13,monthly_work_hours!$H:$H,'FTE 계산'!H$2)) - (SUMIFS(monthly_work_hours!$L:$L,monthly_work_hours!$A:$A,'FTE 계산'!$A13,monthly_work_hours!$H:$H,'FTE 계산'!H$2)) -> 0 | I13: =(SUMIFS(monthly_work_hours!$I:$I,monthly_work_hours!$A:$A,'FTE 계산'!$A13,monthly_work_hours!$H:$H,'FTE 계산'!I$2)) - (SUMIFS(monthly_work_hours!$L:$L,monthly_work_hours!$A:$A,'FTE 계산'!$A13,monthly_work_hours!$H:$H,'FTE 계산'!I$2)) -> 1 | J13: =(SUMIFS(monthly_work_hours!$I:$I,monthly_work_hours!$A:$A,'FTE 계산'!$A13,monthly_work_hours!$H:$H,'FTE 계산'!J$2)) - (SUMIFS(monthly_work_hours!$L:$L,monthly_work_hours!$A:$A,'FTE 계산'!$A13,monthly_work_hours!$H:$H,'FTE 계산'!J$2)) -> 0 | N13: B/H사업팀 | O13: =SUMIFS($E$3:$E$253,$C$3:$C$253,$N13) -> 1191.8 | P13: =SUMIFS($E$3:$E$253,$C$3:$C$253,$N13,$D$3:$D$253,P$2) -> 329.2 | Q13: =SUMIFS($E$3:$E$253,$C$3:$C$253,$N13,$D$3:$D$253,Q$2) -> 678.7 | R13: =SUMIFS($E$3:$E$253,$C$3:$C$253,$N13,$D$3:$D$253,R$2) -> 183.9 | S13: =AVERAGEIFS($H$3:$H$253,$C$3:$C$253,$N13) -> 17.857143 | T13: =AVERAGEIFS($H$3:$H$253,$C$3:$C$253,$N13,$D$3:$D$253,P$2) -> 16.5 | U13: =AVERAGEIFS($H$3:$H$253,$C$3:$C$253,$N13,$D$3:$D$253,Q$2) -> 18.25 | V13: =AVERAGEIFS($H$3:$H$253,$C$3:$C$253,$N13,$D$3:$D$253,R$2) -> 19 | W13: =IFERROR(O13/(S13*$L$2),"-") -> 8.3426 | X13: =IFERROR(P13/(T13*$L$2),"-") -> 2.4939394 | Y13: =IFERROR(Q13/(U13*$L$2),"-") -> 4.6486301 | Z13: =IFERROR(R13/(V13*$L$2),"-") -> 1.2098684 | AA13: =SUMIFS($F$3:$F$253,$C$3:$C$253,$N13) -> 1211.4 | AB13: =SUMIFS($F$3:$F$253,$C$3:$C$253,$N13,$D$3:$D$253,P$2) -> 362 | AC13: =SUMIFS($F$3:$F$253,$C$3:$C$253,$N13,$D$3:$D$253,Q$2) -> 672.1 | AD13: =SUMIFS($F$3:$F$253,$C$3:$C$253,$N13,$D$3:$D$253,R$2) -> 177.3 | AE13: =AVERAGEIFS($I$3:$I$253,$C$3:$C$253,$N13) -> 18.142857 | AF13: =AVERAGEIFS($I$3:$I$253,$C$3:$C$253,$N13,$D$3:$D$253,P$2) -> 19 | AG13: =AVERAGEIFS($I$3:$I$253,$C$3:$C$253,$N13,$D$3:$D$253,Q$2) -> 17.5 | AH13: =AVERAGEIFS($I$3:$I$253,$C$3:$C$253,$N13,$D$3:$D$253,R$2) -> 19 | AI13: =IFERROR(AA13/(AE13*$L$2),"-") -> 8.3462598 | AJ13: =IFERROR(AB13/(AF13*$L$2),"-") -> 2.3815789 | AK13: =IFERROR(AC13/(AG13*$L$2),"-") -> 4.8007143 | AL13: =IFERROR(AD13/(AH13*$L$2),"-") -> 1.1664474 | AM13: =SUMIFS($G$3:$G$253,$C$3:$C$253,$N13) -> 1029.1 | AN13: =SUMIFS($G$3:$G$253,$C$3:$C$253,$N13,$D$3:$D$253,P$2) -> 303.4 | AO13: =SUMIFS($G$3:$G$253,$C$3:$C$253,$N13,$D$3:$D$253,Q$2) -> 579 | AP13: =SUMIFS($G$3:$G$253,$C$3:$C$253,$N13,$D$3:$D$253,R$2) -> 146.7 | AQ13: =AVERAGEIFS($J$3:$J$253,$C$3:$C$253,$N13) -> 15.571429 | AR13: =AVERAGEIFS($J$3:$J$253,$C$3:$C$253,$N13,$D$3:$D$253,P$2) -> 16 | AS13: =AVERAGEIFS($J$3:$J$253,$C$3:$C$253,$N13,$D$3:$D$253,Q$2) -> 15.25 | AT13: =AVERAGEIFS($J$3:$J$253,$C$3:$C$253,$N13,$D$3:$D$253,R$2) -> 16 | AU13: =IFERROR(AM13/(AQ13*$L$2),"-") -> 8.2611239 | AV13: =IFERROR(AN13/(AR13*$L$2),"-") -> 2.3703125 | AW13: =IFERROR(AO13/(AS13*$L$2),"-") -> 4.7459016 | AX13: =IFERROR(AP13/(AT13*$L$2),"-") -> 1.1460937
A14: 1205094 | B14: =_xlfn.XLOOKUP(A14,monthly_work_hours!A:A,monthly_work_hours!B:B) -> 강동현 | C14: =_xlfn.XLOOKUP(A14,monthly_work_hours!A:A,monthly_work_hours!E:E) -> FL개발팀 | D14: =_xlfn.XLOOKUP(A14,monthly_work_hours!A:A,monthly_work_hours!F:F) -> 책임 | E14: =SUMIFS(monthly_work_hours!$M:$M,monthly_work_hours!$A:$A,'FTE 계산'!$A14,monthly_work_hours!$H:$H,'FTE 계산'!E$2) -> 283.6 | F14: =SUMIFS(monthly_work_hours!$M:$M,monthly_work_hours!$A:$A,'FTE 계산'!$A14,monthly_work_hours!$H:$H,'FTE 계산'!F$2) -> 165.9 | G14: =SUMIFS(monthly_work_hours!$M:$M,monthly_work_hours!$A:$A,'FTE 계산'!$A14,monthly_work_hours!$H:$H,'FTE 계산'!G$2) -> 151.8 | H14: =(SUMIFS(monthly_work_hours!$I:$I,monthly_work_hours!$A:$A,'FTE 계산'!$A14,monthly_work_hours!$H:$H,'FTE 계산'!H$2)) - (SUMIFS(monthly_work_hours!$L:$L,monthly_work_hours!$A:$A,'FTE 계산'!$A14,monthly_work_hours!$H:$H,'FTE 계산'!H$2)) -> 19 | I14: =(SUMIFS(monthly_work_hours!$I:$I,monthly_work_hours!$A:$A,'FTE 계산'!$A14,monthly_work_hours!$H:$H,'FTE 계산'!I$2)) - (SUMIFS(monthly_work_hours!$L:$L,monthly_work_hours!$A:$A,'FTE 계산'!$A14,monthly_work_hours!$H:$H,'FTE 계산'!I$2)) -> 16 | J14: =(SUMIFS(monthly_work_hours!$I:$I,monthly_work_hours!$A:$A,'FTE 계산'!$A14,monthly_work_hours!$H:$H,'FTE 계산'!J$2)) - (SUMIFS(monthly_work_hours!$L:$L,monthly_work_hours!$A:$A,'FTE 계산'!$A14,monthly_work_hours!$H:$H,'FTE 계산'!J$2)) -> 16 | N14: 관체사업팀 | O14: =SUMIFS($E$3:$E$253,$C$3:$C$253,$N14) -> 2093.3 | P14: =SUMIFS($E$3:$E$253,$C$3:$C$253,$N14,$D$3:$D$253,P$2) -> 779.5 | Q14: =SUMIFS($E$3:$E$253,$C$3:$C$253,$N14,$D$3:$D$253,Q$2) -> 1152.5 | R14: =SUMIFS($E$3:$E$253,$C$3:$C$253,$N14,$D$3:$D$253,R$2) -> 161.3 | S14: =AVERAGEIFS($H$3:$H$253,$C$3:$C$253,$N14) -> 17.909091 | T14: =AVERAGEIFS($H$3:$H$253,$C$3:$C$253,$N14,$D$3:$D$253,P$2) -> 18.5 | U14: =AVERAGEIFS($H$3:$H$253,$C$3:$C$253,$N14,$D$3:$D$253,Q$2) -> 17.333333 | V14: =AVERAGEIFS($H$3:$H$253,$C$3:$C$253,$N14,$D$3:$D$253,R$2) -> 19 | W14: =IFERROR(O14/(S14*$L$2),"-") -> 14.610596 | X14: =IFERROR(P14/(T14*$L$2),"-") -> 5.2668919 | Y14: =IFERROR(Q14/(U14*$L$2),"-") -> 8.3112981 | Z14: =IFERROR(R14/(V14*$L$2),"-") -> 1.0611842 | AA14: =SUMIFS($F$3:$F$253,$C$3:$C$253,$N14) -> 2411.9 | AB14: =SUMIFS($F$3:$F$253,$C$3:$C$253,$N14,$D$3:$D$253,P$2) -> 773.6 | AC14: =SUMIFS($F$3:$F$253,$C$3:$C$253,$N14,$D$3:$D$253,Q$2) -> 1478.1 | AD14: =SUMIFS($F$3:$F$253,$C$3:$C$253,$N14,$D$3:$D$253,R$2) -> 160.2 | AE14: =AVERAGEIFS($I$3:$I$253,$C$3:$C$253,$N14) -> 18 | AF14: =AVERAGEIFS($I$3:$I$253,$C$3:$C$253,$N14,$D$3:$D$253,P$2) -> 18.25 | AG14: =AVERAGEIFS($I$3:$I$253,$C$3:$C$253,$N14,$D$3:$D$253,Q$2) -> 17.833333 | AH14: =AVERAGEIFS($I$3:$I$253,$C$3:$C$253,$N14,$D$3:$D$253,R$2) -> 18 | AI14: =IFERROR(AA14/(AE14*$L$2),"-") -> 16.749306 | AJ14: =IFERROR(AB14/(AF14*$L$2),"-") -> 5.2986301 | AK14: =IFERROR(AC14/(AG14*$L$2),"-") -> 10.360514 | AL14: =IFERROR(AD14/(AH14*$L$2),"-") -> 1.1125 | AM14: =SUMIFS($G$3:$G$253,$C$3:$C$253,$N14) -> 1948.9 | AN14: =SUMIFS($G$3:$G$253,$C$3:$C$253,$N14,$D$3:$D$253,P$2) -> 632 | AO14: =SUMIFS($G$3:$G$253,$C$3:$C$253,$N14,$D$3:$D$253,Q$2) -> 1191.1 | AP14: =SUMIFS($G$3:$G$253,$C$3:$C$253,$N14,$D$3:$D$253,R$2) -> 125.8 | AQ14: =AVERAGEIFS($J$3:$J$253,$C$3:$C$253,$N14) -> 15.545455 | AR14: =AVERAGEIFS($J$3:$J$253,$C$3:$C$253,$N14,$D$3:$D$253,P$2) -> 15.75 | AS14: =AVERAGEIFS($J$3:$J$253,$C$3:$C$253,$N14,$D$3:$D$253,Q$2) -> 15.833333 | AT14: =AVERAGEIFS($J$3:$J$253,$C$3:$C$253,$N14,$D$3:$D$253,R$2) -> 13 | AU14: =IFERROR(AM14/(AQ14*$L$2),"-") -> 15.67098 | AV14: =IFERROR(AN14/(AR14*$L$2),"-") -> 5.015873 | AW14: =IFERROR(AO14/(AS14*$L$2),"-") -> 9.4034211 | AX14: =IFERROR(AP14/(AT14*$L$2),"-") -> 1.2096154
